[32mINFO    [0m integration.ha_tests.test_upgrade:test_upgrade.py:116 starting continuous writes to the database
[32mINFO    [0m integration.ha_tests.test_upgrade:test_upgrade.py:120 checking whether writes are increasing
[32mINFO    [0m integration.ha_tests.helpers:helpers.py:103 Initial writes {'testing.postgresql-0': 4, 'testing.postgresql-1': 4, 'testing.postgresql-2': 4}
[32mINFO    [0m integration.ha_tests.helpers:helpers.py:113 Retry writes {'testing.postgresql-0': 6, 'testing.postgresql-1': 6, 'testing.postgresql-2': 6}
[32mINFO    [0m integration.ha_tests.test_upgrade:test_upgrade.py:123 Get leader unit
[32mINFO    [0m integration.ha_tests.test_upgrade:test_upgrade.py:127 Run pre-upgrade-check action
[32mINFO    [0m integration.ha_tests.test_upgrade:test_upgrade.py:135 Inject dependency fault
[32mINFO    [0m integration.ha_tests.test_upgrade:test_upgrade.py:140 Refresh the charm
[32mINFO    [0m integration.ha_tests.test_upgrade:test_upgrade.py:143 Wait for upgrade to fail
[32mINFO    [0m integration.ha_tests.test_upgrade:test_upgrade.py:150 Ensure continuous_writes while in failure state on remaining units
[32mINFO    [0m integration.ha_tests.helpers:helpers.py:103 Initial writes {'testing.postgresql-0': 57, 'testing.postgresql-1': 57, 'testing.postgresql-2': 57}
[32mINFO    [0m integration.ha_tests.helpers:helpers.py:113 Retry writes {'testing.postgresql-0': 61, 'testing.postgresql-1': 61, 'testing.postgresql-2': 61}
[32mINFO    [0m integration.ha_tests.test_upgrade:test_upgrade.py:153 Re-run pre-upgrade-check action
[32mINFO    [0m integration.ha_tests.test_upgrade:test_upgrade.py:157 Re-refresh the charm
[32mINFO    [0m integration.ha_tests.test_upgrade:test_upgrade.py:160 Wait for upgrade to start
[32mINFO    [0m integration.ha_tests.test_upgrade:test_upgrade.py:166 Wait for application to recover
[32mINFO    [0m juju.model:__init__.py:3254 Waiting for model:
  postgresql/0 [idle] blocked: ready to rollback application
  postgresql/1 [idle] waiting: other units upgrading first...
  postgresql/2 [idle] waiting: other units upgrading first...
[32mINFO    [0m juju.model:__init__.py:3254 Waiting for model:
  postgresql/0 [idle] waiting: other units upgrading first...
  postgresql/1 [idle] waiting: other units upgrading first...
  postgresql/2 [executing] waiting: waiting for database initialisation
[32mINFO    [0m juju.model:__init__.py:3254 Waiting for model:
  postgresql/0 [executing] waiting: waiting for database initialisation
  postgresql/1 [idle] waiting: other units upgrading first...
  postgresql/2 [idle] maintenance: upgrade completed
[32mINFO    [0m juju.model:__init__.py:3254 Waiting for model:
  postgresql/0 [idle] maintenance: upgrade completed
  postgresql/1 [executing] waiting: waiting for database initialisation
  postgresql/2 [idle] maintenance: upgrade completed
[32mINFO    [0m juju.model:__init__.py:3254 Waiting for model:
  postgresql/0 [executing] active: 
  postgresql/1 [executing] active: 
  postgresql/2 [executing] active: 
[32mINFO    [0m integration.ha_tests.test_upgrade:test_upgrade.py:172 Ensure continuous_writes after rollback procedure
[32mINFO    [0m integration.ha_tests.helpers:helpers.py:103 Initial writes {'testing.postgresql-0': 361, 'testing.postgresql-1': 361, 'testing.postgresql-2': 361}
[32mINFO    [0m integration.ha_tests.helpers:helpers.py:113 Retry writes {'testing.postgresql-0': 363, 'testing.postgresql-1': 363, 'testing.postgresql-2': 363}
[32mINFO    [0m integration.ha_tests.test_upgrade:test_upgrade.py:177 Checking whether no writes were lost
[32mINFO    [0m pytest_operator.plugin:plugin.py:951 Model status:

Model    Controller     Cloud/Region         Version  SLA          Timestamp
testing  concierge-lxd  localhost/localhost  3.6.9    unsupported  01:50:17Z

App                  Version  Status  Scale  Charm                Channel      Rev  Exposed  Message
postgresql           14.18    active      3  postgresql                          2  no       
postgresql-test-app           active      1  postgresql-test-app  latest/edge  402  no       received database credentials of the first database

Unit                    Workload  Agent  Machine  Public address  Ports     Message
postgresql-test-app/0*  active    idle   3        10.130.52.101             received database credentials of the first database
postgresql/0*           active    idle   0        10.130.52.120   5432/tcp  
postgresql/1            active    idle   1        10.130.52.183   5432/tcp  Primary
postgresql/2            active    idle   2        10.130.52.185   5432/tcp  

Machine  State    Address        Inst id        Base          AZ               Message
0        started  10.130.52.120  juju-289afd-0  ubuntu@22.04  pkrvmubgrv54qmi  Running
1        started  10.130.52.183  juju-289afd-1  ubuntu@22.04  pkrvmubgrv54qmi  Running
2        started  10.130.52.185  juju-289afd-2  ubuntu@22.04  pkrvmubgrv54qmi  Running
3        started  10.130.52.101  juju-289afd-3  ubuntu@22.04  pkrvmubgrv54qmi  Running

[32mINFO    [0m pytest_operator.plugin:plugin.py:957 Juju error logs:

machine-0: 01:33:17 ERROR juju.worker.dependency "kvm-container-provisioner" manifold worker returned unexpected error: container types not yet available
machine-0: 01:33:17 ERROR juju.worker.dependency "lxd-container-provisioner" manifold worker returned unexpected error: container types not yet available
unit-postgresql-0: 01:33:17 ERROR juju.worker.meterstatus error running "meter-status-changed": charm missing from disk
unit-postgresql-0: 01:34:51 ERROR unit.postgresql/0.juju-log Unable to get the state of the cluster
Traceback (most recent call last):
  File "/var/lib/juju/agents/unit-postgresql-0/charm/venv/lib/python3.10/site-packages/urllib3/connection.py", line 198, in _new_conn
    sock = connection.create_connection(
  File "/var/lib/juju/agents/unit-postgresql-0/charm/venv/lib/python3.10/site-packages/urllib3/util/connection.py", line 85, in create_connection
    raise err
  File "/var/lib/juju/agents/unit-postgresql-0/charm/venv/lib/python3.10/site-packages/urllib3/util/connection.py", line 73, in create_connection
    sock.connect(sa)
ConnectionRefusedError: [Errno 111] Connection refused

The above exception was the direct cause of the following exception:

Traceback (most recent call last):
  File "/var/lib/juju/agents/unit-postgresql-0/charm/venv/lib/python3.10/site-packages/urllib3/connectionpool.py", line 787, in urlopen
    response = self._make_request(
  File "/var/lib/juju/agents/unit-postgresql-0/charm/venv/lib/python3.10/site-packages/urllib3/connectionpool.py", line 493, in _make_request
    conn.request(
  File "/var/lib/juju/agents/unit-postgresql-0/charm/venv/lib/python3.10/site-packages/urllib3/connection.py", line 494, in request
    self.endheaders()
  File "/usr/lib/python3.10/http/client.py", line 1278, in endheaders
    self._send_output(message_body, encode_chunked=encode_chunked)
  File "/usr/lib/python3.10/http/client.py", line 1038, in _send_output
    self.send(msg)
  File "/usr/lib/python3.10/http/client.py", line 976, in send
    self.connect()
  File "/var/lib/juju/agents/unit-postgresql-0/charm/venv/lib/python3.10/site-packages/urllib3/connection.py", line 325, in connect
    self.sock = self._new_conn()
  File "/var/lib/juju/agents/unit-postgresql-0/charm/venv/lib/python3.10/site-packages/urllib3/connection.py", line 213, in _new_conn
    raise NewConnectionError(
urllib3.exceptions.NewConnectionError: <urllib3.connection.HTTPConnection object at 0x7fedfb7ee8f0>: Failed to establish a new connection: [Errno 111] Connection refused

The above exception was the direct cause of the following exception:

Traceback (most recent call last):
  File "/var/lib/juju/agents/unit-postgresql-0/charm/venv/lib/python3.10/site-packages/requests/adapters.py", line 667, in send
    resp = conn.urlopen(
  File "/var/lib/juju/agents/unit-postgresql-0/charm/venv/lib/python3.10/site-packages/urllib3/connectionpool.py", line 841, in urlopen
    retries = retries.increment(
  File "/var/lib/juju/agents/unit-postgresql-0/charm/venv/lib/python3.10/site-packages/urllib3/util/retry.py", line 519, in increment
    raise MaxRetryError(_pool, url, reason) from reason  # type: ignore[arg-type]
urllib3.exceptions.MaxRetryError: HTTPConnectionPool(host='10.130.52.120', port=8008): Max retries exceeded with url: /cluster (Caused by NewConnectionError('<urllib3.connection.HTTPConnection object at 0x7fedfb7ee8f0>: Failed to establish a new connection: [Errno 111] Connection refused'))

During handling of the above exception, another exception occurred:

Traceback (most recent call last):
  File "/var/lib/juju/agents/unit-postgresql-0/charm/src/cluster.py", line 571, in are_replicas_up
    response = requests.get(
  File "/var/lib/juju/agents/unit-postgresql-0/charm/venv/lib/python3.10/site-packages/requests/api.py", line 73, in get
    return request("get", url, params=params, **kwargs)
  File "/var/lib/juju/agents/unit-postgresql-0/charm/venv/lib/python3.10/site-packages/requests/api.py", line 59, in request
    return session.request(method=method, url=url, **kwargs)
  File "/var/lib/juju/agents/unit-postgresql-0/charm/venv/lib/python3.10/site-packages/requests/sessions.py", line 589, in request
    resp = self.send(prep, **send_kwargs)
  File "/var/lib/juju/agents/unit-postgresql-0/charm/venv/lib/python3.10/site-packages/requests/sessions.py", line 703, in send
    r = adapter.send(request, **kwargs)
  File "/var/lib/juju/agents/unit-postgresql-0/charm/venv/lib/python3.10/site-packages/requests/adapters.py", line 700, in send
    raise ConnectionError(e, request=request)
requests.exceptions.ConnectionError: HTTPConnectionPool(host='10.130.52.120', port=8008): Max retries exceeded with url: /cluster (Caused by NewConnectionError('<urllib3.connection.HTTPConnection object at 0x7fedfb7ee8f0>: Failed to establish a new connection: [Errno 111] Connection refused'))
unit-postgresql-0: 01:35:14 ERROR unit.postgresql/0.juju-log Failed to list PostgreSQL database users: could not translate host name "None" to address: Temporary failure in name resolution

machine-2: 01:35:14 ERROR juju.worker.dependency "lxd-container-provisioner" manifold worker returned unexpected error: container types not yet available
machine-2: 01:35:14 ERROR juju.worker.dependency "kvm-container-provisioner" manifold worker returned unexpected error: container types not yet available
unit-postgresql-2: 01:35:14 ERROR juju.worker.meterstatus error running "meter-status-changed": charm missing from disk
machine-3: 01:35:26 ERROR juju.worker.dependency "kvm-container-provisioner" manifold worker returned unexpected error: container types not yet available
machine-3: 01:35:26 ERROR juju.worker.dependency "lxd-container-provisioner" manifold worker returned unexpected error: container types not yet available
unit-postgresql-test-app-0: 01:35:27 ERROR juju.worker.meterstatus error running "meter-status-changed": charm missing from disk
machine-1: 01:35:42 ERROR juju.worker.dependency "kvm-container-provisioner" manifold worker returned unexpected error: container types not yet available
machine-1: 01:35:42 ERROR juju.worker.dependency "lxd-container-provisioner" manifold worker returned unexpected error: container types not yet available
unit-postgresql-1: 01:35:42 ERROR juju.worker.meterstatus error running "meter-status-changed": charm missing from disk
unit-postgresql-1: 01:39:47 ERROR unit.postgresql/1.juju-log Failed to list PostgreSQL database users: connection to server at "10.130.52.183", port 5432 failed: Connection refused
	Is the server running on that host and accepting TCP/IP connections?

unit-postgresql-0: 01:47:24 ERROR unit.postgresql/0.juju-log charms.data_platform_libs.v0.upgrade.VersionError - {'message': 'Versions incompatible, snap 14.12 can not be upgraded to 15.0', 'cause': 'Upgrades only supported for specific versions, snap versions satisfying requirement ^15', 'resolution': ''}

[32mINFO    [0m pytest_operator.plugin:plugin.py:1039 Forgetting model main...