[32mINFO    [0m integration.ha_tests.test_self_healing:test_self_healing.py:486 checking whether the connectivity to the database is working
[32mINFO    [0m integration.ha_tests.test_self_healing:test_self_healing.py:491 Cutting network for postgresql/2
[32mINFO    [0m integration.ha_tests.test_self_healing:test_self_healing.py:499 checking for no connectivity between postgresql/2 and postgresql/0
[32mINFO    [0m integration.ha_tests.test_self_healing:test_self_healing.py:499 checking for no connectivity between postgresql/2 and postgresql/0
[32mINFO    [0m integration.ha_tests.test_self_healing:test_self_healing.py:499 checking for no connectivity between postgresql/2 and postgresql/3
[32mINFO    [0m integration.ha_tests.test_self_healing:test_self_healing.py:506 checking for no connectivity between postgresql/2 and the controller
[32mINFO    [0m integration.ha_tests.test_self_healing:test_self_healing.py:513 checking whether the connectivity to the database is not working
[32mINFO    [0m integration.ha_tests.test_self_healing:test_self_healing.py:519 checking whether writes are increasing
[32mINFO    [0m integration.ha_tests.helpers:helpers.py:103 Initial writes {'testing.postgresql-0': 192, 'testing.postgresql-3': 192}
[32mINFO    [0m integration.ha_tests.helpers:helpers.py:113 Retry writes {'testing.postgresql-0': 192, 'testing.postgresql-3': 192}
[32mINFO    [0m integration.ha_tests.helpers:helpers.py:113 Retry writes {'testing.postgresql-0': 192, 'testing.postgresql-3': 192}
[32mINFO    [0m integration.ha_tests.helpers:helpers.py:113 Retry writes {'testing.postgresql-0': 192, 'testing.postgresql-3': 192}
[32mINFO    [0m integration.ha_tests.helpers:helpers.py:113 Retry writes {'testing.postgresql-0': 192, 'testing.postgresql-3': 192}
[32mINFO    [0m integration.ha_tests.helpers:helpers.py:113 Retry writes {'testing.postgresql-0': 192, 'testing.postgresql-3': 192}
[32mINFO    [0m integration.ha_tests.helpers:helpers.py:113 Retry writes {'testing.postgresql-0': 192, 'testing.postgresql-3': 192}
[32mINFO    [0m integration.ha_tests.helpers:helpers.py:113 Retry writes {'testing.postgresql-0': 192, 'testing.postgresql-3': 192}
[32mINFO    [0m integration.ha_tests.helpers:helpers.py:113 Retry writes {'testing.postgresql-0': 192, 'testing.postgresql-3': 192}
[32mINFO    [0m integration.ha_tests.helpers:helpers.py:113 Retry writes {'testing.postgresql-0': 192, 'testing.postgresql-3': 192}
[32mINFO    [0m integration.ha_tests.helpers:helpers.py:113 Retry writes {'testing.postgresql-0': 192, 'testing.postgresql-3': 192}
[32mINFO    [0m integration.ha_tests.helpers:helpers.py:113 Retry writes {'testing.postgresql-0': 192, 'testing.postgresql-3': 192}
[32mINFO    [0m integration.ha_tests.helpers:helpers.py:113 Retry writes {'testing.postgresql-0': 192, 'testing.postgresql-3': 192}
[32mINFO    [0m integration.ha_tests.helpers:helpers.py:113 Retry writes {'testing.postgresql-0': 192, 'testing.postgresql-3': 192}
[32mINFO    [0m integration.ha_tests.helpers:helpers.py:113 Retry writes {'testing.postgresql-0': 192, 'testing.postgresql-3': 192}
[32mINFO    [0m integration.ha_tests.helpers:helpers.py:113 Retry writes {'testing.postgresql-0': 192, 'testing.postgresql-3': 192}
[32mINFO    [0m integration.ha_tests.helpers:helpers.py:113 Retry writes {'testing.postgresql-0': 192, 'testing.postgresql-3': 192}
[32mINFO    [0m integration.ha_tests.helpers:helpers.py:113 Retry writes {'testing.postgresql-0': 192, 'testing.postgresql-3': 192}
[32mINFO    [0m integration.ha_tests.helpers:helpers.py:113 Retry writes {'testing.postgresql-0': 192, 'testing.postgresql-3': 192}
[32mINFO    [0m integration.ha_tests.helpers:helpers.py:113 Retry writes {'testing.postgresql-0': 192, 'testing.postgresql-3': 192}
[32mINFO    [0m integration.ha_tests.helpers:helpers.py:113 Retry writes {'testing.postgresql-0': 192, 'testing.postgresql-3': 192}
[32mINFO    [0m integration.ha_tests.helpers:helpers.py:113 Retry writes {'testing.postgresql-0': 192, 'testing.postgresql-3': 192}
[32mINFO    [0m integration.ha_tests.helpers:helpers.py:113 Retry writes {'testing.postgresql-0': 192, 'testing.postgresql-3': 192}
[32mINFO    [0m integration.ha_tests.helpers:helpers.py:113 Retry writes {'testing.postgresql-0': 192, 'testing.postgresql-3': 192}
[32mINFO    [0m integration.ha_tests.helpers:helpers.py:113 Retry writes {'testing.postgresql-0': 192, 'testing.postgresql-3': 192}
[32mINFO    [0m integration.ha_tests.helpers:helpers.py:113 Retry writes {'testing.postgresql-0': 192, 'testing.postgresql-3': 192}
[32mINFO    [0m integration.ha_tests.helpers:helpers.py:113 Retry writes {'testing.postgresql-0': 192, 'testing.postgresql-3': 192}
[32mINFO    [0m integration.ha_tests.helpers:helpers.py:113 Retry writes {'testing.postgresql-0': 192, 'testing.postgresql-3': 192}
[32mINFO    [0m integration.ha_tests.helpers:helpers.py:113 Retry writes {'testing.postgresql-0': 192, 'testing.postgresql-3': 192}
[32mINFO    [0m integration.ha_tests.helpers:helpers.py:113 Retry writes {'testing.postgresql-0': 192, 'testing.postgresql-3': 192}
[32mINFO    [0m integration.ha_tests.helpers:helpers.py:113 Retry writes {'testing.postgresql-0': 192, 'testing.postgresql-3': 192}
[32mINFO    [0m integration.ha_tests.helpers:helpers.py:113 Retry writes {'testing.postgresql-0': 192, 'testing.postgresql-3': 192}
[32mINFO    [0m integration.ha_tests.helpers:helpers.py:113 Retry writes {'testing.postgresql-0': 192, 'testing.postgresql-3': 192}
[32mINFO    [0m integration.ha_tests.helpers:helpers.py:113 Retry writes {'testing.postgresql-0': 192, 'testing.postgresql-3': 192}
[32mINFO    [0m pytest_operator.plugin:plugin.py:929 Model status:

Model    Controller     Cloud/Region         Version  SLA          Timestamp
testing  concierge-lxd  localhost/localhost  3.6.2    unsupported  02:32:25Z

App                  Version  Status  Scale  Charm                Channel      Rev  Exposed  Message
postgresql           14.15    active    2/3  postgresql                          0  no       
postgresql-test-app           active      1  postgresql-test-app  latest/edge  360  no       received database credentials of the first database

Unit                    Workload  Agent  Machine  Public address  Ports     Message
postgresql-test-app/0*  active    idle   3        10.244.155.162            received database credentials of the first database
postgresql/0            active    idle   0        10.244.155.82   5432/tcp  
postgresql/2            unknown   lost   2        10.244.155.96   5432/tcp  agent lost, see 'juju show-status-log postgresql/2'
postgresql/3*           active    idle   4        10.244.155.11   5432/tcp  

Machine  State    Address         Inst id        Base          AZ  Message
0        started  10.244.155.82   juju-2ea7b6-0  ubuntu@22.04      Running
2        down     10.244.155.96   juju-2ea7b6-2  ubuntu@22.04      Running
3        started  10.244.155.162  juju-2ea7b6-3  ubuntu@22.04      Running
4        started  10.244.155.11   juju-2ea7b6-4  ubuntu@22.04      Running

[32mINFO    [0m pytest_operator.plugin:plugin.py:935 Juju error logs:

machine-0: 01:41:03 ERROR juju.worker.dependency "lxd-container-provisioner" manifold worker returned unexpected error: container types not yet available
machine-0: 01:41:03 ERROR juju.worker.dependency "kvm-container-provisioner" manifold worker returned unexpected error: container types not yet available
unit-postgresql-0: 01:41:03 ERROR juju.worker.meterstatus error running "meter-status-changed": charm missing from disk
unit-postgresql-0: 01:42:29 ERROR unit.postgresql/0.juju-log Unable to get the state of the cluster
Traceback (most recent call last):
  File "/var/lib/juju/agents/unit-postgresql-0/charm/venv/lib/python3.10/site-packages/urllib3/connection.py", line 198, in _new_conn
    sock = connection.create_connection(
  File "/var/lib/juju/agents/unit-postgresql-0/charm/venv/lib/python3.10/site-packages/urllib3/util/connection.py", line 85, in create_connection
    raise err
  File "/var/lib/juju/agents/unit-postgresql-0/charm/venv/lib/python3.10/site-packages/urllib3/util/connection.py", line 73, in create_connection
    sock.connect(sa)
ConnectionRefusedError: [Errno 111] Connection refused

The above exception was the direct cause of the following exception:

Traceback (most recent call last):
  File "/var/lib/juju/agents/unit-postgresql-0/charm/venv/lib/python3.10/site-packages/urllib3/connectionpool.py", line 787, in urlopen
    response = self._make_request(
  File "/var/lib/juju/agents/unit-postgresql-0/charm/venv/lib/python3.10/site-packages/urllib3/connectionpool.py", line 493, in _make_request
    conn.request(
  File "/var/lib/juju/agents/unit-postgresql-0/charm/venv/lib/python3.10/site-packages/urllib3/connection.py", line 445, in request
    self.endheaders()
  File "/usr/lib/python3.10/http/client.py", line 1278, in endheaders
    self._send_output(message_body, encode_chunked=encode_chunked)
  File "/usr/lib/python3.10/http/client.py", line 1038, in _send_output
    self.send(msg)
  File "/usr/lib/python3.10/http/client.py", line 976, in send
    self.connect()
  File "/var/lib/juju/agents/unit-postgresql-0/charm/venv/lib/python3.10/site-packages/urllib3/connection.py", line 276, in connect
    self.sock = self._new_conn()
  File "/var/lib/juju/agents/unit-postgresql-0/charm/venv/lib/python3.10/site-packages/urllib3/connection.py", line 213, in _new_conn
    raise NewConnectionError(
urllib3.exceptions.NewConnectionError: <urllib3.connection.HTTPConnection object at 0x7efef65ebe20>: Failed to establish a new connection: [Errno 111] Connection refused

The above exception was the direct cause of the following exception:

Traceback (most recent call last):
  File "/var/lib/juju/agents/unit-postgresql-0/charm/venv/lib/python3.10/site-packages/requests/adapters.py", line 667, in send
    resp = conn.urlopen(
  File "/var/lib/juju/agents/unit-postgresql-0/charm/venv/lib/python3.10/site-packages/urllib3/connectionpool.py", line 841, in urlopen
    retries = retries.increment(
  File "/var/lib/juju/agents/unit-postgresql-0/charm/venv/lib/python3.10/site-packages/urllib3/util/retry.py", line 519, in increment
    raise MaxRetryError(_pool, url, reason) from reason  # type: ignore[arg-type]
urllib3.exceptions.MaxRetryError: HTTPConnectionPool(host='10.244.155.64', port=8008): Max retries exceeded with url: /cluster (Caused by NewConnectionError('<urllib3.connection.HTTPConnection object at 0x7efef65ebe20>: Failed to establish a new connection: [Errno 111] Connection refused'))

During handling of the above exception, another exception occurred:

Traceback (most recent call last):
  File "/var/lib/juju/agents/unit-postgresql-0/charm/src/cluster.py", line 552, in are_replicas_up
    response = requests.get(
  File "/var/lib/juju/agents/unit-postgresql-0/charm/venv/lib/python3.10/site-packages/requests/api.py", line 73, in get
    return request("get", url, params=params, **kwargs)
  File "/var/lib/juju/agents/unit-postgresql-0/charm/venv/lib/python3.10/site-packages/requests/api.py", line 59, in request
    return session.request(method=method, url=url, **kwargs)
  File "/var/lib/juju/agents/unit-postgresql-0/charm/venv/lib/python3.10/site-packages/requests/sessions.py", line 589, in request
    resp = self.send(prep, **send_kwargs)
  File "/var/lib/juju/agents/unit-postgresql-0/charm/venv/lib/python3.10/site-packages/requests/sessions.py", line 703, in send
    r = adapter.send(request, **kwargs)
  File "/var/lib/juju/agents/unit-postgresql-0/charm/venv/lib/python3.10/site-packages/requests/adapters.py", line 700, in send
    raise ConnectionError(e, request=request)
requests.exceptions.ConnectionError: HTTPConnectionPool(host='10.244.155.64', port=8008): Max retries exceeded with url: /cluster (Caused by NewConnectionError('<urllib3.connection.HTTPConnection object at 0x7efef65ebe20>: Failed to establish a new connection: [Errno 111] Connection refused'))
machine-2: 01:43:08 ERROR juju.worker.dependency "kvm-container-provisioner" manifold worker returned unexpected error: container types not yet available
machine-2: 01:43:08 ERROR juju.worker.dependency "lxd-container-provisioner" manifold worker returned unexpected error: container types not yet available
unit-postgresql-2: 01:43:08 ERROR juju.worker.meterstatus error running "meter-status-changed": charm missing from disk
machine-3: 01:43:14 ERROR juju.worker.dependency "kvm-container-provisioner" manifold worker returned unexpected error: container types not yet available
machine-3: 01:43:14 ERROR juju.worker.dependency "lxd-container-provisioner" manifold worker returned unexpected error: container types not yet available
unit-postgresql-test-app-0: 01:43:15 ERROR juju.worker.meterstatus error running "meter-status-changed": charm missing from disk
machine-1: 01:43:15 ERROR juju.worker.dependency "kvm-container-provisioner" manifold worker returned unexpected error: container types not yet available
machine-1: 01:43:15 ERROR juju.worker.dependency "lxd-container-provisioner" manifold worker returned unexpected error: container types not yet available
unit-postgresql-1: 01:43:15 ERROR juju.worker.meterstatus error running "meter-status-changed": charm missing from disk
machine-4: 01:55:44 ERROR juju.worker.dependency "lxd-container-provisioner" manifold worker returned unexpected error: container types not yet available
machine-4: 01:55:44 ERROR juju.worker.dependency "kvm-container-provisioner" manifold worker returned unexpected error: container types not yet available
unit-postgresql-3: 01:55:44 ERROR juju.worker.meterstatus error running "meter-status-changed": charm missing from disk
machine-0: 02:18:32 ERROR juju.worker.dependency "api-caller" manifold worker returned unexpected error: api connection broken unexpectedly
machine-0: 02:18:36 ERROR juju.worker.dependency "api-caller" manifold worker returned unexpected error: [91d009] "machine-0" cannot open api: unable to connect to API: dial tcp 10.244.155.196:17070: connect: network is unreachable
machine-0: 02:18:39 ERROR juju.worker.dependency "api-caller" manifold worker returned unexpected error: [91d009] "machine-0" cannot open api: unable to connect to API: dial tcp 10.244.155.196:17070: connect: network is unreachable
machine-0: 02:18:44 ERROR juju.worker.dependency "api-caller" manifold worker returned unexpected error: [91d009] "machine-0" cannot open api: unable to connect to API: dial tcp 10.244.155.196:17070: connect: network is unreachable
machine-0: 02:18:50 ERROR juju.worker.dependency "api-caller" manifold worker returned unexpected error: [91d009] "machine-0" cannot open api: unable to connect to API: dial tcp 10.244.155.196:17070: connect: network is unreachable
machine-0: 02:18:56 ERROR juju.worker.dependency "api-caller" manifold worker returned unexpected error: [91d009] "machine-0" cannot open api: unable to connect to API: dial tcp 10.244.155.196:17070: connect: network is unreachable
machine-0: 02:19:03 ERROR juju.worker.dependency "api-caller" manifold worker returned unexpected error: [91d009] "machine-0" cannot open api: unable to connect to API: dial tcp 10.244.155.196:17070: connect: network is unreachable
unit-postgresql-3: 02:24:16 ERROR unit.postgresql/3.juju-log Failed to list PostgreSQL database users: connection to server at "10.244.155.96", port 5432 failed: timeout expired

unit-postgresql-3: 02:24:24 ERROR unit.postgresql/3.juju-log Failed to list PostgreSQL database users: connection to server at "10.244.155.96", port 5432 failed: timeout expired

unit-postgresql-3: 02:24:36 ERROR unit.postgresql/3.juju-log Failed to list PostgreSQL database users: connection to server at "10.244.155.96", port 5432 failed: timeout expired

unit-postgresql-3: 02:24:45 ERROR unit.postgresql/3.juju-log Failed to list PostgreSQL database users: connection to server at "10.244.155.96", port 5432 failed: timeout expired

unit-postgresql-3: 02:24:53 ERROR unit.postgresql/3.juju-log Failed to list PostgreSQL database users: connection to server at "10.244.155.96", port 5432 failed: timeout expired

unit-postgresql-3: 02:25:04 ERROR unit.postgresql/3.juju-log Failed to list PostgreSQL database users: connection to server at "10.244.155.96", port 5432 failed: timeout expired

unit-postgresql-3: 02:25:13 ERROR unit.postgresql/3.juju-log Failed to list PostgreSQL database users: connection to server at "10.244.155.96", port 5432 failed: timeout expired

unit-postgresql-3: 02:25:25 ERROR unit.postgresql/3.juju-log Failed to list PostgreSQL database users: connection to server at "10.244.155.96", port 5432 failed: timeout expired

unit-postgresql-3: 02:25:35 ERROR unit.postgresql/3.juju-log Failed to list PostgreSQL database users: connection to server at "10.244.155.96", port 5432 failed: timeout expired

unit-postgresql-3: 02:25:46 ERROR unit.postgresql/3.juju-log Failed to list PostgreSQL database users: connection to server at "10.244.155.96", port 5432 failed: timeout expired

unit-postgresql-3: 02:25:55 ERROR unit.postgresql/3.juju-log Failed to list PostgreSQL database users: connection to server at "10.244.155.96", port 5432 failed: timeout expired

unit-postgresql-3: 02:26:06 ERROR unit.postgresql/3.juju-log Failed to list PostgreSQL database users: connection to server at "10.244.155.96", port 5432 failed: timeout expired

unit-postgresql-3: 02:26:17 ERROR unit.postgresql/3.juju-log Failed to list PostgreSQL database users: connection to server at "10.244.155.96", port 5432 failed: timeout expired

unit-postgresql-3: 02:26:25 ERROR unit.postgresql/3.juju-log Failed to list PostgreSQL database users: connection to server at "10.244.155.96", port 5432 failed: timeout expired

unit-postgresql-3: 02:26:34 ERROR unit.postgresql/3.juju-log Failed to list PostgreSQL database users: connection to server at "10.244.155.96", port 5432 failed: timeout expired

unit-postgresql-3: 02:26:45 ERROR unit.postgresql/3.juju-log Failed to list PostgreSQL database users: connection to server at "10.244.155.96", port 5432 failed: timeout expired

unit-postgresql-3: 02:26:54 ERROR unit.postgresql/3.juju-log Failed to list PostgreSQL database users: connection to server at "10.244.155.96", port 5432 failed: timeout expired

unit-postgresql-3: 02:27:05 ERROR unit.postgresql/3.juju-log Failed to list PostgreSQL database users: connection to server at "10.244.155.96", port 5432 failed: timeout expired

unit-postgresql-test-app-0: 02:27:12 ERROR unit.postgresql-test-app/0.juju-log Unable to drop table
Traceback (most recent call last):
  File "/var/lib/juju/agents/unit-postgresql-test-app-0/charm/src/charm.py", line 318, in _on_clear_continuous_writes_action
    psycopg2.connect(self._connection_string) as connection,
  File "/var/lib/juju/agents/unit-postgresql-test-app-0/charm/venv/lib/python3.10/site-packages/psycopg2/__init__.py", line 122, in connect
    conn = _connect(dsn, connection_factory=connection_factory, **kwasync)
psycopg2.OperationalError: connection to server at "10.244.155.96", port 5432 failed: Connection timed out
	Is the server running on that host and accepting TCP/IP connections?

unit-postgresql-test-app-0: 02:27:12 ERROR unit.postgresql-test-app/0.juju-log Uncaught exception while in charm code:
Traceback (most recent call last):
  File "/var/lib/juju/agents/unit-postgresql-test-app-0/charm/src/charm.py", line 560, in <module>
    main(ApplicationCharm)
  File "/var/lib/juju/agents/unit-postgresql-test-app-0/charm/venv/lib/python3.10/site-packages/ops/__init__.py", line 343, in __call__
    return _main.main(charm_class=charm_class, use_juju_for_storage=use_juju_for_storage)
  File "/var/lib/juju/agents/unit-postgresql-test-app-0/charm/venv/lib/python3.10/site-packages/ops/_main.py", line 558, in main
    manager.run()
  File "/var/lib/juju/agents/unit-postgresql-test-app-0/charm/venv/lib/python3.10/site-packages/ops/_main.py", line 543, in run
    self._emit()
  File "/var/lib/juju/agents/unit-postgresql-test-app-0/charm/venv/lib/python3.10/site-packages/ops/_main.py", line 502, in _emit
    self._emit_charm_event(self.dispatcher.event_name)
  File "/var/lib/juju/agents/unit-postgresql-test-app-0/charm/venv/lib/python3.10/site-packages/ops/_main.py", line 530, in _emit_charm_event
    event_to_emit.emit(*args, **kwargs)
  File "/var/lib/juju/agents/unit-postgresql-test-app-0/charm/venv/lib/python3.10/site-packages/ops/framework.py", line 347, in emit
    framework._emit(event)
  File "/var/lib/juju/agents/unit-postgresql-test-app-0/charm/venv/lib/python3.10/site-packages/ops/framework.py", line 906, in _emit
    self._reemit(event_path)
  File "/var/lib/juju/agents/unit-postgresql-test-app-0/charm/venv/lib/python3.10/site-packages/ops/framework.py", line 996, in _reemit
    custom_handler(event)
  File "/var/lib/juju/agents/unit-postgresql-test-app-0/charm/src/charm.py", line 327, in _on_clear_continuous_writes_action
    connection.close()
UnboundLocalError: local variable 'connection' referenced before assignment
unit-postgresql-3: 02:27:15 ERROR unit.postgresql/3.juju-log Failed to list PostgreSQL database users: connection to server at "10.244.155.96", port 5432 failed: timeout expired

unit-postgresql-3: 02:27:27 ERROR unit.postgresql/3.juju-log Failed to list PostgreSQL database users: connection to server at "10.244.155.96", port 5432 failed: timeout expired

unit-postgresql-3: 02:27:36 ERROR unit.postgresql/3.juju-log Failed to list PostgreSQL database users: connection to server at "10.244.155.96", port 5432 failed: timeout expired

unit-postgresql-3: 02:27:46 ERROR unit.postgresql/3.juju-log Failed to list PostgreSQL database users: connection to server at "10.244.155.96", port 5432 failed: timeout expired

unit-postgresql-3: 02:27:55 ERROR unit.postgresql/3.juju-log Failed to list PostgreSQL database users: connection to server at "10.244.155.96", port 5432 failed: timeout expired

unit-postgresql-3: 02:28:04 ERROR unit.postgresql/3.juju-log Failed to list PostgreSQL database users: connection to server at "10.244.155.96", port 5432 failed: timeout expired

unit-postgresql-3: 02:28:14 ERROR unit.postgresql/3.juju-log Failed to list PostgreSQL database users: connection to server at "10.244.155.96", port 5432 failed: timeout expired

unit-postgresql-test-app-0: 02:28:16 ERROR unit.postgresql-test-app/0.juju-log Unable to read result
Traceback (most recent call last):
  File "/var/lib/juju/agents/unit-postgresql-test-app-0/charm/src/charm.py", line 429, in _stop_continuous_writes
    with attempt, open(LAST_WRITTEN_FILE) as fd:
FileNotFoundError: [Errno 2] No such file or directory: '/tmp/last_written_value'

The above exception was the direct cause of the following exception:

Traceback (most recent call last):
  File "/var/lib/juju/agents/unit-postgresql-test-app-0/charm/src/charm.py", line 428, in _stop_continuous_writes
    for attempt in Retrying(stop=stop_after_delay(60), wait=wait_fixed(5)):
  File "/var/lib/juju/agents/unit-postgresql-test-app-0/charm/venv/lib/python3.10/site-packages/tenacity/__init__.py", line 443, in __iter__
    do = self.iter(retry_state=retry_state)
  File "/var/lib/juju/agents/unit-postgresql-test-app-0/charm/venv/lib/python3.10/site-packages/tenacity/__init__.py", line 376, in iter
    result = action(retry_state)
  File "/var/lib/juju/agents/unit-postgresql-test-app-0/charm/venv/lib/python3.10/site-packages/tenacity/__init__.py", line 419, in exc_check
    raise retry_exc from fut.exception()
tenacity.RetryError: RetryError[<Future at 0x7fccd66f4af0 state=finished raised FileNotFoundError>]
unit-postgresql-test-app-0: 02:28:17 ERROR unit.postgresql-test-app/0.juju-log Unable to drop table
Traceback (most recent call last):
  File "/var/lib/juju/agents/unit-postgresql-test-app-0/charm/src/charm.py", line 318, in _on_clear_continuous_writes_action
    psycopg2.connect(self._connection_string) as connection,
  File "/var/lib/juju/agents/unit-postgresql-test-app-0/charm/venv/lib/python3.10/site-packages/psycopg2/__init__.py", line 122, in connect
    conn = _connect(dsn, connection_factory=connection_factory, **kwasync)
psycopg2.OperationalError: connection to server at "10.244.155.96", port 5432 failed: Connection timed out
	Is the server running on that host and accepting TCP/IP connections?

unit-postgresql-test-app-0: 02:28:17 ERROR unit.postgresql-test-app/0.juju-log Uncaught exception while in charm code:
Traceback (most recent call last):
  File "/var/lib/juju/agents/unit-postgresql-test-app-0/charm/src/charm.py", line 560, in <module>
    main(ApplicationCharm)
  File "/var/lib/juju/agents/unit-postgresql-test-app-0/charm/venv/lib/python3.10/site-packages/ops/__init__.py", line 343, in __call__
    return _main.main(charm_class=charm_class, use_juju_for_storage=use_juju_for_storage)
  File "/var/lib/juju/agents/unit-postgresql-test-app-0/charm/venv/lib/python3.10/site-packages/ops/_main.py", line 558, in main
    manager.run()
  File "/var/lib/juju/agents/unit-postgresql-test-app-0/charm/venv/lib/python3.10/site-packages/ops/_main.py", line 543, in run
    self._emit()
  File "/var/lib/juju/agents/unit-postgresql-test-app-0/charm/venv/lib/python3.10/site-packages/ops/_main.py", line 502, in _emit
    self._emit_charm_event(self.dispatcher.event_name)
  File "/var/lib/juju/agents/unit-postgresql-test-app-0/charm/venv/lib/python3.10/site-packages/ops/_main.py", line 530, in _emit_charm_event
    event_to_emit.emit(*args, **kwargs)
  File "/var/lib/juju/agents/unit-postgresql-test-app-0/charm/venv/lib/python3.10/site-packages/ops/framework.py", line 347, in emit
    framework._emit(event)
  File "/var/lib/juju/agents/unit-postgresql-test-app-0/charm/venv/lib/python3.10/site-packages/ops/framework.py", line 906, in _emit
    self._reemit(event_path)
  File "/var/lib/juju/agents/unit-postgresql-test-app-0/charm/venv/lib/python3.10/site-packages/ops/framework.py", line 996, in _reemit
    custom_handler(event)
  File "/var/lib/juju/agents/unit-postgresql-test-app-0/charm/src/charm.py", line 327, in _on_clear_continuous_writes_action
    connection.close()
UnboundLocalError: local variable 'connection' referenced before assignment
unit-postgresql-test-app-0: 02:28:22 ERROR unit.postgresql-test-app/0.juju-log Unable to drop table
Traceback (most recent call last):
  File "/var/lib/juju/agents/unit-postgresql-test-app-0/charm/src/charm.py", line 318, in _on_clear_continuous_writes_action
    psycopg2.connect(self._connection_string) as connection,
  File "/var/lib/juju/agents/unit-postgresql-test-app-0/charm/venv/lib/python3.10/site-packages/psycopg2/__init__.py", line 122, in connect
    conn = _connect(dsn, connection_factory=connection_factory, **kwasync)
psycopg2.OperationalError: connection to server at "10.244.155.96", port 5432 failed: Connection timed out
	Is the server running on that host and accepting TCP/IP connections?

unit-postgresql-test-app-0: 02:28:22 ERROR unit.postgresql-test-app/0.juju-log Uncaught exception while in charm code:
Traceback (most recent call last):
  File "/var/lib/juju/agents/unit-postgresql-test-app-0/charm/src/charm.py", line 560, in <module>
    main(ApplicationCharm)
  File "/var/lib/juju/agents/unit-postgresql-test-app-0/charm/venv/lib/python3.10/site-packages/ops/__init__.py", line 343, in __call__
    return _main.main(charm_class=charm_class, use_juju_for_storage=use_juju_for_storage)
  File "/var/lib/juju/agents/unit-postgresql-test-app-0/charm/venv/lib/python3.10/site-packages/ops/_main.py", line 558, in main
    manager.run()
  File "/var/lib/juju/agents/unit-postgresql-test-app-0/charm/venv/lib/python3.10/site-packages/ops/_main.py", line 543, in run
    self._emit()
  File "/var/lib/juju/agents/unit-postgresql-test-app-0/charm/venv/lib/python3.10/site-packages/ops/_main.py", line 502, in _emit
    self._emit_charm_event(self.dispatcher.event_name)
  File "/var/lib/juju/agents/unit-postgresql-test-app-0/charm/venv/lib/python3.10/site-packages/ops/_main.py", line 530, in _emit_charm_event
    event_to_emit.emit(*args, **kwargs)
  File "/var/lib/juju/agents/unit-postgresql-test-app-0/charm/venv/lib/python3.10/site-packages/ops/framework.py", line 347, in emit
    framework._emit(event)
  File "/var/lib/juju/agents/unit-postgresql-test-app-0/charm/venv/lib/python3.10/site-packages/ops/framework.py", line 906, in _emit
    self._reemit(event_path)
  File "/var/lib/juju/agents/unit-postgresql-test-app-0/charm/venv/lib/python3.10/site-packages/ops/framework.py", line 996, in _reemit
    custom_handler(event)
  File "/var/lib/juju/agents/unit-postgresql-test-app-0/charm/src/charm.py", line 327, in _on_clear_continuous_writes_action
    connection.close()
UnboundLocalError: local variable 'connection' referenced before assignment
unit-postgresql-3: 02:28:24 ERROR unit.postgresql/3.juju-log Failed to list PostgreSQL database users: connection to server at "10.244.155.96", port 5432 failed: timeout expired

unit-postgresql-test-app-0: 02:28:27 ERROR unit.postgresql-test-app/0.juju-log Unable to drop table
Traceback (most recent call last):
  File "/var/lib/juju/agents/unit-postgresql-test-app-0/charm/src/charm.py", line 318, in _on_clear_continuous_writes_action
    psycopg2.connect(self._connection_string) as connection,
  File "/var/lib/juju/agents/unit-postgresql-test-app-0/charm/venv/lib/python3.10/site-packages/psycopg2/__init__.py", line 122, in connect
    conn = _connect(dsn, connection_factory=connection_factory, **kwasync)
psycopg2.OperationalError: connection to server at "10.244.155.96", port 5432 failed: Connection timed out
	Is the server running on that host and accepting TCP/IP connections?

unit-postgresql-test-app-0: 02:28:27 ERROR unit.postgresql-test-app/0.juju-log Uncaught exception while in charm code:
Traceback (most recent call last):
  File "/var/lib/juju/agents/unit-postgresql-test-app-0/charm/src/charm.py", line 560, in <module>
    main(ApplicationCharm)
  File "/var/lib/juju/agents/unit-postgresql-test-app-0/charm/venv/lib/python3.10/site-packages/ops/__init__.py", line 343, in __call__
    return _main.main(charm_class=charm_class, use_juju_for_storage=use_juju_for_storage)
  File "/var/lib/juju/agents/unit-postgresql-test-app-0/charm/venv/lib/python3.10/site-packages/ops/_main.py", line 558, in main
    manager.run()
  File "/var/lib/juju/agents/unit-postgresql-test-app-0/charm/venv/lib/python3.10/site-packages/ops/_main.py", line 543, in run
    self._emit()
  File "/var/lib/juju/agents/unit-postgresql-test-app-0/charm/venv/lib/python3.10/site-packages/ops/_main.py", line 502, in _emit
    self._emit_charm_event(self.dispatcher.event_name)
  File "/var/lib/juju/agents/unit-postgresql-test-app-0/charm/venv/lib/python3.10/site-packages/ops/_main.py", line 530, in _emit_charm_event
    event_to_emit.emit(*args, **kwargs)
  File "/var/lib/juju/agents/unit-postgresql-test-app-0/charm/venv/lib/python3.10/site-packages/ops/framework.py", line 347, in emit
    framework._emit(event)
  File "/var/lib/juju/agents/unit-postgresql-test-app-0/charm/venv/lib/python3.10/site-packages/ops/framework.py", line 906, in _emit
    self._reemit(event_path)
  File "/var/lib/juju/agents/unit-postgresql-test-app-0/charm/venv/lib/python3.10/site-packages/ops/framework.py", line 996, in _reemit
    custom_handler(event)
  File "/var/lib/juju/agents/unit-postgresql-test-app-0/charm/src/charm.py", line 327, in _on_clear_continuous_writes_action
    connection.close()
UnboundLocalError: local variable 'connection' referenced before assignment
unit-postgresql-test-app-0: 02:28:32 ERROR unit.postgresql-test-app/0.juju-log Unable to drop table
Traceback (most recent call last):
  File "/var/lib/juju/agents/unit-postgresql-test-app-0/charm/src/charm.py", line 318, in _on_clear_continuous_writes_action
    psycopg2.connect(self._connection_string) as connection,
  File "/var/lib/juju/agents/unit-postgresql-test-app-0/charm/venv/lib/python3.10/site-packages/psycopg2/__init__.py", line 122, in connect
    conn = _connect(dsn, connection_factory=connection_factory, **kwasync)
psycopg2.OperationalError: connection to server at "10.244.155.96", port 5432 failed: Connection timed out
	Is the server running on that host and accepting TCP/IP connections?

unit-postgresql-test-app-0: 02:28:32 ERROR unit.postgresql-test-app/0.juju-log Uncaught exception while in charm code:
Traceback (most recent call last):
  File "/var/lib/juju/agents/unit-postgresql-test-app-0/charm/src/charm.py", line 560, in <module>
    main(ApplicationCharm)
  File "/var/lib/juju/agents/unit-postgresql-test-app-0/charm/venv/lib/python3.10/site-packages/ops/__init__.py", line 343, in __call__
    return _main.main(charm_class=charm_class, use_juju_for_storage=use_juju_for_storage)
  File "/var/lib/juju/agents/unit-postgresql-test-app-0/charm/venv/lib/python3.10/site-packages/ops/_main.py", line 558, in main
    manager.run()
  File "/var/lib/juju/agents/unit-postgresql-test-app-0/charm/venv/lib/python3.10/site-packages/ops/_main.py", line 543, in run
    self._emit()
  File "/var/lib/juju/agents/unit-postgresql-test-app-0/charm/venv/lib/python3.10/site-packages/ops/_main.py", line 502, in _emit
    self._emit_charm_event(self.dispatcher.event_name)
  File "/var/lib/juju/agents/unit-postgresql-test-app-0/charm/venv/lib/python3.10/site-packages/ops/_main.py", line 530, in _emit_charm_event
    event_to_emit.emit(*args, **kwargs)
  File "/var/lib/juju/agents/unit-postgresql-test-app-0/charm/venv/lib/python3.10/site-packages/ops/framework.py", line 347, in emit
    framework._emit(event)
  File "/var/lib/juju/agents/unit-postgresql-test-app-0/charm/venv/lib/python3.10/site-packages/ops/framework.py", line 906, in _emit
    self._reemit(event_path)
  File "/var/lib/juju/agents/unit-postgresql-test-app-0/charm/venv/lib/python3.10/site-packages/ops/framework.py", line 996, in _reemit
    custom_handler(event)
  File "/var/lib/juju/agents/unit-postgresql-test-app-0/charm/src/charm.py", line 327, in _on_clear_continuous_writes_action
    connection.close()
UnboundLocalError: local variable 'connection' referenced before assignment
unit-postgresql-3: 02:28:32 ERROR unit.postgresql/3.juju-log Failed to list PostgreSQL database users: connection to server at "10.244.155.96", port 5432 failed: timeout expired

unit-postgresql-test-app-0: 02:28:37 ERROR unit.postgresql-test-app/0.juju-log Unable to drop table
Traceback (most recent call last):
  File "/var/lib/juju/agents/unit-postgresql-test-app-0/charm/src/charm.py", line 318, in _on_clear_continuous_writes_action
    psycopg2.connect(self._connection_string) as connection,
  File "/var/lib/juju/agents/unit-postgresql-test-app-0/charm/venv/lib/python3.10/site-packages/psycopg2/__init__.py", line 122, in connect
    conn = _connect(dsn, connection_factory=connection_factory, **kwasync)
psycopg2.OperationalError: connection to server at "10.244.155.96", port 5432 failed: Connection timed out
	Is the server running on that host and accepting TCP/IP connections?

unit-postgresql-test-app-0: 02:28:37 ERROR unit.postgresql-test-app/0.juju-log Uncaught exception while in charm code:
Traceback (most recent call last):
  File "/var/lib/juju/agents/unit-postgresql-test-app-0/charm/src/charm.py", line 560, in <module>
    main(ApplicationCharm)
  File "/var/lib/juju/agents/unit-postgresql-test-app-0/charm/venv/lib/python3.10/site-packages/ops/__init__.py", line 343, in __call__
    return _main.main(charm_class=charm_class, use_juju_for_storage=use_juju_for_storage)
  File "/var/lib/juju/agents/unit-postgresql-test-app-0/charm/venv/lib/python3.10/site-packages/ops/_main.py", line 558, in main
    manager.run()
  File "/var/lib/juju/agents/unit-postgresql-test-app-0/charm/venv/lib/python3.10/site-packages/ops/_main.py", line 543, in run
    self._emit()
  File "/var/lib/juju/agents/unit-postgresql-test-app-0/charm/venv/lib/python3.10/site-packages/ops/_main.py", line 502, in _emit
    self._emit_charm_event(self.dispatcher.event_name)
  File "/var/lib/juju/agents/unit-postgresql-test-app-0/charm/venv/lib/python3.10/site-packages/ops/_main.py", line 530, in _emit_charm_event
    event_to_emit.emit(*args, **kwargs)
  File "/var/lib/juju/agents/unit-postgresql-test-app-0/charm/venv/lib/python3.10/site-packages/ops/framework.py", line 347, in emit
    framework._emit(event)
  File "/var/lib/juju/agents/unit-postgresql-test-app-0/charm/venv/lib/python3.10/site-packages/ops/framework.py", line 906, in _emit
    self._reemit(event_path)
  File "/var/lib/juju/agents/unit-postgresql-test-app-0/charm/venv/lib/python3.10/site-packages/ops/framework.py", line 996, in _reemit
    custom_handler(event)
  File "/var/lib/juju/agents/unit-postgresql-test-app-0/charm/src/charm.py", line 327, in _on_clear_continuous_writes_action
    connection.close()
UnboundLocalError: local variable 'connection' referenced before assignment
unit-postgresql-test-app-0: 02:28:42 ERROR unit.postgresql-test-app/0.juju-log Unable to drop table
Traceback (most recent call last):
  File "/var/lib/juju/agents/unit-postgresql-test-app-0/charm/src/charm.py", line 318, in _on_clear_continuous_writes_action
    psycopg2.connect(self._connection_string) as connection,
  File "/var/lib/juju/agents/unit-postgresql-test-app-0/charm/venv/lib/python3.10/site-packages/psycopg2/__init__.py", line 122, in connect
    conn = _connect(dsn, connection_factory=connection_factory, **kwasync)
psycopg2.OperationalError: connection to server at "10.244.155.96", port 5432 failed: Connection timed out
	Is the server running on that host and accepting TCP/IP connections?

unit-postgresql-test-app-0: 02:28:42 ERROR unit.postgresql-test-app/0.juju-log Uncaught exception while in charm code:
Traceback (most recent call last):
  File "/var/lib/juju/agents/unit-postgresql-test-app-0/charm/src/charm.py", line 560, in <module>
    main(ApplicationCharm)
  File "/var/lib/juju/agents/unit-postgresql-test-app-0/charm/venv/lib/python3.10/site-packages/ops/__init__.py", line 343, in __call__
    return _main.main(charm_class=charm_class, use_juju_for_storage=use_juju_for_storage)
  File "/var/lib/juju/agents/unit-postgresql-test-app-0/charm/venv/lib/python3.10/site-packages/ops/_main.py", line 558, in main
    manager.run()
  File "/var/lib/juju/agents/unit-postgresql-test-app-0/charm/venv/lib/python3.10/site-packages/ops/_main.py", line 543, in run
    self._emit()
  File "/var/lib/juju/agents/unit-postgresql-test-app-0/charm/venv/lib/python3.10/site-packages/ops/_main.py", line 502, in _emit
    self._emit_charm_event(self.dispatcher.event_name)
  File "/var/lib/juju/agents/unit-postgresql-test-app-0/charm/venv/lib/python3.10/site-packages/ops/_main.py", line 530, in _emit_charm_event
    event_to_emit.emit(*args, **kwargs)
  File "/var/lib/juju/agents/unit-postgresql-test-app-0/charm/venv/lib/python3.10/site-packages/ops/framework.py", line 347, in emit
    framework._emit(event)
  File "/var/lib/juju/agents/unit-postgresql-test-app-0/charm/venv/lib/python3.10/site-packages/ops/framework.py", line 906, in _emit
    self._reemit(event_path)
  File "/var/lib/juju/agents/unit-postgresql-test-app-0/charm/venv/lib/python3.10/site-packages/ops/framework.py", line 996, in _reemit
    custom_handler(event)
  File "/var/lib/juju/agents/unit-postgresql-test-app-0/charm/src/charm.py", line 327, in _on_clear_continuous_writes_action
    connection.close()
UnboundLocalError: local variable 'connection' referenced before assignment
unit-postgresql-3: 02:28:43 ERROR unit.postgresql/3.juju-log Failed to list PostgreSQL database users: connection to server at "10.244.155.96", port 5432 failed: timeout expired

unit-postgresql-test-app-0: 02:28:47 ERROR unit.postgresql-test-app/0.juju-log Unable to drop table
Traceback (most recent call last):
  File "/var/lib/juju/agents/unit-postgresql-test-app-0/charm/src/charm.py", line 318, in _on_clear_continuous_writes_action
    psycopg2.connect(self._connection_string) as connection,
  File "/var/lib/juju/agents/unit-postgresql-test-app-0/charm/venv/lib/python3.10/site-packages/psycopg2/__init__.py", line 122, in connect
    conn = _connect(dsn, connection_factory=connection_factory, **kwasync)
psycopg2.OperationalError: connection to server at "10.244.155.96", port 5432 failed: Connection timed out
	Is the server running on that host and accepting TCP/IP connections?

unit-postgresql-test-app-0: 02:28:47 ERROR unit.postgresql-test-app/0.juju-log Uncaught exception while in charm code:
Traceback (most recent call last):
  File "/var/lib/juju/agents/unit-postgresql-test-app-0/charm/src/charm.py", line 560, in <module>
    main(ApplicationCharm)
  File "/var/lib/juju/agents/unit-postgresql-test-app-0/charm/venv/lib/python3.10/site-packages/ops/__init__.py", line 343, in __call__
    return _main.main(charm_class=charm_class, use_juju_for_storage=use_juju_for_storage)
  File "/var/lib/juju/agents/unit-postgresql-test-app-0/charm/venv/lib/python3.10/site-packages/ops/_main.py", line 558, in main
    manager.run()
  File "/var/lib/juju/agents/unit-postgresql-test-app-0/charm/venv/lib/python3.10/site-packages/ops/_main.py", line 543, in run
    self._emit()
  File "/var/lib/juju/agents/unit-postgresql-test-app-0/charm/venv/lib/python3.10/site-packages/ops/_main.py", line 502, in _emit
    self._emit_charm_event(self.dispatcher.event_name)
  File "/var/lib/juju/agents/unit-postgresql-test-app-0/charm/venv/lib/python3.10/site-packages/ops/_main.py", line 530, in _emit_charm_event
    event_to_emit.emit(*args, **kwargs)
  File "/var/lib/juju/agents/unit-postgresql-test-app-0/charm/venv/lib/python3.10/site-packages/ops/framework.py", line 347, in emit
    framework._emit(event)
  File "/var/lib/juju/agents/unit-postgresql-test-app-0/charm/venv/lib/python3.10/site-packages/ops/framework.py", line 906, in _emit
    self._reemit(event_path)
  File "/var/lib/juju/agents/unit-postgresql-test-app-0/charm/venv/lib/python3.10/site-packages/ops/framework.py", line 996, in _reemit
    custom_handler(event)
  File "/var/lib/juju/agents/unit-postgresql-test-app-0/charm/src/charm.py", line 327, in _on_clear_continuous_writes_action
    connection.close()
UnboundLocalError: local variable 'connection' referenced before assignment
unit-postgresql-3: 02:28:52 ERROR unit.postgresql/3.juju-log Failed to list PostgreSQL database users: connection to server at "10.244.155.96", port 5432 failed: timeout expired

unit-postgresql-test-app-0: 02:28:52 ERROR unit.postgresql-test-app/0.juju-log Unable to drop table
Traceback (most recent call last):
  File "/var/lib/juju/agents/unit-postgresql-test-app-0/charm/src/charm.py", line 318, in _on_clear_continuous_writes_action
    psycopg2.connect(self._connection_string) as connection,
  File "/var/lib/juju/agents/unit-postgresql-test-app-0/charm/venv/lib/python3.10/site-packages/psycopg2/__init__.py", line 122, in connect
    conn = _connect(dsn, connection_factory=connection_factory, **kwasync)
psycopg2.OperationalError: connection to server at "10.244.155.96", port 5432 failed: Connection timed out
	Is the server running on that host and accepting TCP/IP connections?

unit-postgresql-test-app-0: 02:28:52 ERROR unit.postgresql-test-app/0.juju-log Uncaught exception while in charm code:
Traceback (most recent call last):
  File "/var/lib/juju/agents/unit-postgresql-test-app-0/charm/src/charm.py", line 560, in <module>
    main(ApplicationCharm)
  File "/var/lib/juju/agents/unit-postgresql-test-app-0/charm/venv/lib/python3.10/site-packages/ops/__init__.py", line 343, in __call__
    return _main.main(charm_class=charm_class, use_juju_for_storage=use_juju_for_storage)
  File "/var/lib/juju/agents/unit-postgresql-test-app-0/charm/venv/lib/python3.10/site-packages/ops/_main.py", line 558, in main
    manager.run()
  File "/var/lib/juju/agents/unit-postgresql-test-app-0/charm/venv/lib/python3.10/site-packages/ops/_main.py", line 543, in run
    self._emit()
  File "/var/lib/juju/agents/unit-postgresql-test-app-0/charm/venv/lib/python3.10/site-packages/ops/_main.py", line 502, in _emit
    self._emit_charm_event(self.dispatcher.event_name)
  File "/var/lib/juju/agents/unit-postgresql-test-app-0/charm/venv/lib/python3.10/site-packages/ops/_main.py", line 530, in _emit_charm_event
    event_to_emit.emit(*args, **kwargs)
  File "/var/lib/juju/agents/unit-postgresql-test-app-0/charm/venv/lib/python3.10/site-packages/ops/framework.py", line 347, in emit
    framework._emit(event)
  File "/var/lib/juju/agents/unit-postgresql-test-app-0/charm/venv/lib/python3.10/site-packages/ops/framework.py", line 906, in _emit
    self._reemit(event_path)
  File "/var/lib/juju/agents/unit-postgresql-test-app-0/charm/venv/lib/python3.10/site-packages/ops/framework.py", line 996, in _reemit
    custom_handler(event)
  File "/var/lib/juju/agents/unit-postgresql-test-app-0/charm/src/charm.py", line 327, in _on_clear_continuous_writes_action
    connection.close()
UnboundLocalError: local variable 'connection' referenced before assignment
unit-postgresql-test-app-0: 02:28:57 ERROR unit.postgresql-test-app/0.juju-log Unable to drop table
Traceback (most recent call last):
  File "/var/lib/juju/agents/unit-postgresql-test-app-0/charm/src/charm.py", line 318, in _on_clear_continuous_writes_action
    psycopg2.connect(self._connection_string) as connection,
  File "/var/lib/juju/agents/unit-postgresql-test-app-0/charm/venv/lib/python3.10/site-packages/psycopg2/__init__.py", line 122, in connect
    conn = _connect(dsn, connection_factory=connection_factory, **kwasync)
psycopg2.OperationalError: connection to server at "10.244.155.96", port 5432 failed: Connection timed out
	Is the server running on that host and accepting TCP/IP connections?

unit-postgresql-test-app-0: 02:28:57 ERROR unit.postgresql-test-app/0.juju-log Uncaught exception while in charm code:
Traceback (most recent call last):
  File "/var/lib/juju/agents/unit-postgresql-test-app-0/charm/src/charm.py", line 560, in <module>
    main(ApplicationCharm)
  File "/var/lib/juju/agents/unit-postgresql-test-app-0/charm/venv/lib/python3.10/site-packages/ops/__init__.py", line 343, in __call__
    return _main.main(charm_class=charm_class, use_juju_for_storage=use_juju_for_storage)
  File "/var/lib/juju/agents/unit-postgresql-test-app-0/charm/venv/lib/python3.10/site-packages/ops/_main.py", line 558, in main
    manager.run()
  File "/var/lib/juju/agents/unit-postgresql-test-app-0/charm/venv/lib/python3.10/site-packages/ops/_main.py", line 543, in run
    self._emit()
  File "/var/lib/juju/agents/unit-postgresql-test-app-0/charm/venv/lib/python3.10/site-packages/ops/_main.py", line 502, in _emit
    self._emit_charm_event(self.dispatcher.event_name)
  File "/var/lib/juju/agents/unit-postgresql-test-app-0/charm/venv/lib/python3.10/site-packages/ops/_main.py", line 530, in _emit_charm_event
    event_to_emit.emit(*args, **kwargs)
  File "/var/lib/juju/agents/unit-postgresql-test-app-0/charm/venv/lib/python3.10/site-packages/ops/framework.py", line 347, in emit
    framework._emit(event)
  File "/var/lib/juju/agents/unit-postgresql-test-app-0/charm/venv/lib/python3.10/site-packages/ops/framework.py", line 906, in _emit
    self._reemit(event_path)
  File "/var/lib/juju/agents/unit-postgresql-test-app-0/charm/venv/lib/python3.10/site-packages/ops/framework.py", line 996, in _reemit
    custom_handler(event)
  File "/var/lib/juju/agents/unit-postgresql-test-app-0/charm/src/charm.py", line 327, in _on_clear_continuous_writes_action
    connection.close()
UnboundLocalError: local variable 'connection' referenced before assignment
unit-postgresql-test-app-0: 02:29:02 ERROR unit.postgresql-test-app/0.juju-log Unable to drop table
Traceback (most recent call last):
  File "/var/lib/juju/agents/unit-postgresql-test-app-0/charm/src/charm.py", line 318, in _on_clear_continuous_writes_action
    psycopg2.connect(self._connection_string) as connection,
  File "/var/lib/juju/agents/unit-postgresql-test-app-0/charm/venv/lib/python3.10/site-packages/psycopg2/__init__.py", line 122, in connect
    conn = _connect(dsn, connection_factory=connection_factory, **kwasync)
psycopg2.OperationalError: connection to server at "10.244.155.96", port 5432 failed: Connection timed out
	Is the server running on that host and accepting TCP/IP connections?

unit-postgresql-test-app-0: 02:29:02 ERROR unit.postgresql-test-app/0.juju-log Uncaught exception while in charm code:
Traceback (most recent call last):
  File "/var/lib/juju/agents/unit-postgresql-test-app-0/charm/src/charm.py", line 560, in <module>
    main(ApplicationCharm)
  File "/var/lib/juju/agents/unit-postgresql-test-app-0/charm/venv/lib/python3.10/site-packages/ops/__init__.py", line 343, in __call__
    return _main.main(charm_class=charm_class, use_juju_for_storage=use_juju_for_storage)
  File "/var/lib/juju/agents/unit-postgresql-test-app-0/charm/venv/lib/python3.10/site-packages/ops/_main.py", line 558, in main
    manager.run()
  File "/var/lib/juju/agents/unit-postgresql-test-app-0/charm/venv/lib/python3.10/site-packages/ops/_main.py", line 543, in run
    self._emit()
  File "/var/lib/juju/agents/unit-postgresql-test-app-0/charm/venv/lib/python3.10/site-packages/ops/_main.py", line 502, in _emit
    self._emit_charm_event(self.dispatcher.event_name)
  File "/var/lib/juju/agents/unit-postgresql-test-app-0/charm/venv/lib/python3.10/site-packages/ops/_main.py", line 530, in _emit_charm_event
    event_to_emit.emit(*args, **kwargs)
  File "/var/lib/juju/agents/unit-postgresql-test-app-0/charm/venv/lib/python3.10/site-packages/ops/framework.py", line 347, in emit
    framework._emit(event)
  File "/var/lib/juju/agents/unit-postgresql-test-app-0/charm/venv/lib/python3.10/site-packages/ops/framework.py", line 906, in _emit
    self._reemit(event_path)
  File "/var/lib/juju/agents/unit-postgresql-test-app-0/charm/venv/lib/python3.10/site-packages/ops/framework.py", line 996, in _reemit
    custom_handler(event)
  File "/var/lib/juju/agents/unit-postgresql-test-app-0/charm/src/charm.py", line 327, in _on_clear_continuous_writes_action
    connection.close()
UnboundLocalError: local variable 'connection' referenced before assignment
unit-postgresql-3: 02:29:04 ERROR unit.postgresql/3.juju-log Failed to list PostgreSQL database users: connection to server at "10.244.155.96", port 5432 failed: timeout expired

unit-postgresql-test-app-0: 02:29:07 ERROR unit.postgresql-test-app/0.juju-log Unable to drop table
Traceback (most recent call last):
  File "/var/lib/juju/agents/unit-postgresql-test-app-0/charm/src/charm.py", line 318, in _on_clear_continuous_writes_action
    psycopg2.connect(self._connection_string) as connection,
  File "/var/lib/juju/agents/unit-postgresql-test-app-0/charm/venv/lib/python3.10/site-packages/psycopg2/__init__.py", line 122, in connect
    conn = _connect(dsn, connection_factory=connection_factory, **kwasync)
psycopg2.OperationalError: connection to server at "10.244.155.96", port 5432 failed: Connection timed out
	Is the server running on that host and accepting TCP/IP connections?

unit-postgresql-test-app-0: 02:29:07 ERROR unit.postgresql-test-app/0.juju-log Uncaught exception while in charm code:
Traceback (most recent call last):
  File "/var/lib/juju/agents/unit-postgresql-test-app-0/charm/src/charm.py", line 560, in <module>
    main(ApplicationCharm)
  File "/var/lib/juju/agents/unit-postgresql-test-app-0/charm/venv/lib/python3.10/site-packages/ops/__init__.py", line 343, in __call__
    return _main.main(charm_class=charm_class, use_juju_for_storage=use_juju_for_storage)
  File "/var/lib/juju/agents/unit-postgresql-test-app-0/charm/venv/lib/python3.10/site-packages/ops/_main.py", line 558, in main
    manager.run()
  File "/var/lib/juju/agents/unit-postgresql-test-app-0/charm/venv/lib/python3.10/site-packages/ops/_main.py", line 543, in run
    self._emit()
  File "/var/lib/juju/agents/unit-postgresql-test-app-0/charm/venv/lib/python3.10/site-packages/ops/_main.py", line 502, in _emit
    self._emit_charm_event(self.dispatcher.event_name)
  File "/var/lib/juju/agents/unit-postgresql-test-app-0/charm/venv/lib/python3.10/site-packages/ops/_main.py", line 530, in _emit_charm_event
    event_to_emit.emit(*args, **kwargs)
  File "/var/lib/juju/agents/unit-postgresql-test-app-0/charm/venv/lib/python3.10/site-packages/ops/framework.py", line 347, in emit
    framework._emit(event)
  File "/var/lib/juju/agents/unit-postgresql-test-app-0/charm/venv/lib/python3.10/site-packages/ops/framework.py", line 906, in _emit
    self._reemit(event_path)
  File "/var/lib/juju/agents/unit-postgresql-test-app-0/charm/venv/lib/python3.10/site-packages/ops/framework.py", line 996, in _reemit
    custom_handler(event)
  File "/var/lib/juju/agents/unit-postgresql-test-app-0/charm/src/charm.py", line 327, in _on_clear_continuous_writes_action
    connection.close()
UnboundLocalError: local variable 'connection' referenced before assignment
unit-postgresql-test-app-0: 02:29:13 ERROR unit.postgresql-test-app/0.juju-log Unable to drop table
Traceback (most recent call last):
  File "/var/lib/juju/agents/unit-postgresql-test-app-0/charm/src/charm.py", line 318, in _on_clear_continuous_writes_action
    psycopg2.connect(self._connection_string) as connection,
  File "/var/lib/juju/agents/unit-postgresql-test-app-0/charm/venv/lib/python3.10/site-packages/psycopg2/__init__.py", line 122, in connect
    conn = _connect(dsn, connection_factory=connection_factory, **kwasync)
psycopg2.OperationalError: connection to server at "10.244.155.96", port 5432 failed: Connection timed out
	Is the server running on that host and accepting TCP/IP connections?

unit-postgresql-test-app-0: 02:29:13 ERROR unit.postgresql-test-app/0.juju-log Uncaught exception while in charm code:
Traceback (most recent call last):
  File "/var/lib/juju/agents/unit-postgresql-test-app-0/charm/src/charm.py", line 560, in <module>
    main(ApplicationCharm)
  File "/var/lib/juju/agents/unit-postgresql-test-app-0/charm/venv/lib/python3.10/site-packages/ops/__init__.py", line 343, in __call__
    return _main.main(charm_class=charm_class, use_juju_for_storage=use_juju_for_storage)
  File "/var/lib/juju/agents/unit-postgresql-test-app-0/charm/venv/lib/python3.10/site-packages/ops/_main.py", line 558, in main
    manager.run()
  File "/var/lib/juju/agents/unit-postgresql-test-app-0/charm/venv/lib/python3.10/site-packages/ops/_main.py", line 543, in run
    self._emit()
  File "/var/lib/juju/agents/unit-postgresql-test-app-0/charm/venv/lib/python3.10/site-packages/ops/_main.py", line 502, in _emit
    self._emit_charm_event(self.dispatcher.event_name)
  File "/var/lib/juju/agents/unit-postgresql-test-app-0/charm/venv/lib/python3.10/site-packages/ops/_main.py", line 530, in _emit_charm_event
    event_to_emit.emit(*args, **kwargs)
  File "/var/lib/juju/agents/unit-postgresql-test-app-0/charm/venv/lib/python3.10/site-packages/ops/framework.py", line 347, in emit
    framework._emit(event)
  File "/var/lib/juju/agents/unit-postgresql-test-app-0/charm/venv/lib/python3.10/site-packages/ops/framework.py", line 906, in _emit
    self._reemit(event_path)
  File "/var/lib/juju/agents/unit-postgresql-test-app-0/charm/venv/lib/python3.10/site-packages/ops/framework.py", line 996, in _reemit
    custom_handler(event)
  File "/var/lib/juju/agents/unit-postgresql-test-app-0/charm/src/charm.py", line 327, in _on_clear_continuous_writes_action
    connection.close()
UnboundLocalError: local variable 'connection' referenced before assignment
unit-postgresql-3: 02:29:15 ERROR unit.postgresql/3.juju-log Failed to list PostgreSQL database users: connection to server at "10.244.155.96", port 5432 failed: timeout expired

unit-postgresql-test-app-0: 02:29:17 ERROR unit.postgresql-test-app/0.juju-log Unable to drop table
Traceback (most recent call last):
  File "/var/lib/juju/agents/unit-postgresql-test-app-0/charm/src/charm.py", line 318, in _on_clear_continuous_writes_action
    psycopg2.connect(self._connection_string) as connection,
  File "/var/lib/juju/agents/unit-postgresql-test-app-0/charm/venv/lib/python3.10/site-packages/psycopg2/__init__.py", line 122, in connect
    conn = _connect(dsn, connection_factory=connection_factory, **kwasync)
psycopg2.OperationalError: connection to server at "10.244.155.96", port 5432 failed: Connection timed out
	Is the server running on that host and accepting TCP/IP connections?

unit-postgresql-test-app-0: 02:29:17 ERROR unit.postgresql-test-app/0.juju-log Uncaught exception while in charm code:
Traceback (most recent call last):
  File "/var/lib/juju/agents/unit-postgresql-test-app-0/charm/src/charm.py", line 560, in <module>
    main(ApplicationCharm)
  File "/var/lib/juju/agents/unit-postgresql-test-app-0/charm/venv/lib/python3.10/site-packages/ops/__init__.py", line 343, in __call__
    return _main.main(charm_class=charm_class, use_juju_for_storage=use_juju_for_storage)
  File "/var/lib/juju/agents/unit-postgresql-test-app-0/charm/venv/lib/python3.10/site-packages/ops/_main.py", line 558, in main
    manager.run()
  File "/var/lib/juju/agents/unit-postgresql-test-app-0/charm/venv/lib/python3.10/site-packages/ops/_main.py", line 543, in run
    self._emit()
  File "/var/lib/juju/agents/unit-postgresql-test-app-0/charm/venv/lib/python3.10/site-packages/ops/_main.py", line 502, in _emit
    self._emit_charm_event(self.dispatcher.event_name)
  File "/var/lib/juju/agents/unit-postgresql-test-app-0/charm/venv/lib/python3.10/site-packages/ops/_main.py", line 530, in _emit_charm_event
    event_to_emit.emit(*args, **kwargs)
  File "/var/lib/juju/agents/unit-postgresql-test-app-0/charm/venv/lib/python3.10/site-packages/ops/framework.py", line 347, in emit
    framework._emit(event)
  File "/var/lib/juju/agents/unit-postgresql-test-app-0/charm/venv/lib/python3.10/site-packages/ops/framework.py", line 906, in _emit
    self._reemit(event_path)
  File "/var/lib/juju/agents/unit-postgresql-test-app-0/charm/venv/lib/python3.10/site-packages/ops/framework.py", line 996, in _reemit
    custom_handler(event)
  File "/var/lib/juju/agents/unit-postgresql-test-app-0/charm/src/charm.py", line 327, in _on_clear_continuous_writes_action
    connection.close()
UnboundLocalError: local variable 'connection' referenced before assignment
unit-postgresql-test-app-0: 02:29:22 ERROR unit.postgresql-test-app/0.juju-log Unable to drop table
Traceback (most recent call last):
  File "/var/lib/juju/agents/unit-postgresql-test-app-0/charm/src/charm.py", line 318, in _on_clear_continuous_writes_action
    psycopg2.connect(self._connection_string) as connection,
  File "/var/lib/juju/agents/unit-postgresql-test-app-0/charm/venv/lib/python3.10/site-packages/psycopg2/__init__.py", line 122, in connect
    conn = _connect(dsn, connection_factory=connection_factory, **kwasync)
psycopg2.OperationalError: connection to server at "10.244.155.96", port 5432 failed: Connection timed out
	Is the server running on that host and accepting TCP/IP connections?

unit-postgresql-test-app-0: 02:29:22 ERROR unit.postgresql-test-app/0.juju-log Uncaught exception while in charm code:
Traceback (most recent call last):
  File "/var/lib/juju/agents/unit-postgresql-test-app-0/charm/src/charm.py", line 560, in <module>
    main(ApplicationCharm)
  File "/var/lib/juju/agents/unit-postgresql-test-app-0/charm/venv/lib/python3.10/site-packages/ops/__init__.py", line 343, in __call__
    return _main.main(charm_class=charm_class, use_juju_for_storage=use_juju_for_storage)
  File "/var/lib/juju/agents/unit-postgresql-test-app-0/charm/venv/lib/python3.10/site-packages/ops/_main.py", line 558, in main
    manager.run()
  File "/var/lib/juju/agents/unit-postgresql-test-app-0/charm/venv/lib/python3.10/site-packages/ops/_main.py", line 543, in run
    self._emit()
  File "/var/lib/juju/agents/unit-postgresql-test-app-0/charm/venv/lib/python3.10/site-packages/ops/_main.py", line 502, in _emit
    self._emit_charm_event(self.dispatcher.event_name)
  File "/var/lib/juju/agents/unit-postgresql-test-app-0/charm/venv/lib/python3.10/site-packages/ops/_main.py", line 530, in _emit_charm_event
    event_to_emit.emit(*args, **kwargs)
  File "/var/lib/juju/agents/unit-postgresql-test-app-0/charm/venv/lib/python3.10/site-packages/ops/framework.py", line 347, in emit
    framework._emit(event)
  File "/var/lib/juju/agents/unit-postgresql-test-app-0/charm/venv/lib/python3.10/site-packages/ops/framework.py", line 906, in _emit
    self._reemit(event_path)
  File "/var/lib/juju/agents/unit-postgresql-test-app-0/charm/venv/lib/python3.10/site-packages/ops/framework.py", line 996, in _reemit
    custom_handler(event)
  File "/var/lib/juju/agents/unit-postgresql-test-app-0/charm/src/charm.py", line 327, in _on_clear_continuous_writes_action
    connection.close()
UnboundLocalError: local variable 'connection' referenced before assignment
unit-postgresql-3: 02:29:25 ERROR unit.postgresql/3.juju-log Failed to list PostgreSQL database users: connection to server at "10.244.155.96", port 5432 failed: timeout expired

unit-postgresql-test-app-0: 02:29:27 ERROR unit.postgresql-test-app/0.juju-log Unable to drop table
Traceback (most recent call last):
  File "/var/lib/juju/agents/unit-postgresql-test-app-0/charm/src/charm.py", line 318, in _on_clear_continuous_writes_action
    psycopg2.connect(self._connection_string) as connection,
  File "/var/lib/juju/agents/unit-postgresql-test-app-0/charm/venv/lib/python3.10/site-packages/psycopg2/__init__.py", line 122, in connect
    conn = _connect(dsn, connection_factory=connection_factory, **kwasync)
psycopg2.OperationalError: connection to server at "10.244.155.96", port 5432 failed: Connection timed out
	Is the server running on that host and accepting TCP/IP connections?

unit-postgresql-test-app-0: 02:29:27 ERROR unit.postgresql-test-app/0.juju-log Uncaught exception while in charm code:
Traceback (most recent call last):
  File "/var/lib/juju/agents/unit-postgresql-test-app-0/charm/src/charm.py", line 560, in <module>
    main(ApplicationCharm)
  File "/var/lib/juju/agents/unit-postgresql-test-app-0/charm/venv/lib/python3.10/site-packages/ops/__init__.py", line 343, in __call__
    return _main.main(charm_class=charm_class, use_juju_for_storage=use_juju_for_storage)
  File "/var/lib/juju/agents/unit-postgresql-test-app-0/charm/venv/lib/python3.10/site-packages/ops/_main.py", line 558, in main
    manager.run()
  File "/var/lib/juju/agents/unit-postgresql-test-app-0/charm/venv/lib/python3.10/site-packages/ops/_main.py", line 543, in run
    self._emit()
  File "/var/lib/juju/agents/unit-postgresql-test-app-0/charm/venv/lib/python3.10/site-packages/ops/_main.py", line 502, in _emit
    self._emit_charm_event(self.dispatcher.event_name)
  File "/var/lib/juju/agents/unit-postgresql-test-app-0/charm/venv/lib/python3.10/site-packages/ops/_main.py", line 530, in _emit_charm_event
    event_to_emit.emit(*args, **kwargs)
  File "/var/lib/juju/agents/unit-postgresql-test-app-0/charm/venv/lib/python3.10/site-packages/ops/framework.py", line 347, in emit
    framework._emit(event)
  File "/var/lib/juju/agents/unit-postgresql-test-app-0/charm/venv/lib/python3.10/site-packages/ops/framework.py", line 906, in _emit
    self._reemit(event_path)
  File "/var/lib/juju/agents/unit-postgresql-test-app-0/charm/venv/lib/python3.10/site-packages/ops/framework.py", line 996, in _reemit
    custom_handler(event)
  File "/var/lib/juju/agents/unit-postgresql-test-app-0/charm/src/charm.py", line 327, in _on_clear_continuous_writes_action
    connection.close()
UnboundLocalError: local variable 'connection' referenced before assignment
unit-postgresql-test-app-0: 02:29:32 ERROR unit.postgresql-test-app/0.juju-log Unable to drop table
Traceback (most recent call last):
  File "/var/lib/juju/agents/unit-postgresql-test-app-0/charm/src/charm.py", line 318, in _on_clear_continuous_writes_action
    psycopg2.connect(self._connection_string) as connection,
  File "/var/lib/juju/agents/unit-postgresql-test-app-0/charm/venv/lib/python3.10/site-packages/psycopg2/__init__.py", line 122, in connect
    conn = _connect(dsn, connection_factory=connection_factory, **kwasync)
psycopg2.OperationalError: connection to server at "10.244.155.96", port 5432 failed: Connection timed out
	Is the server running on that host and accepting TCP/IP connections?

unit-postgresql-test-app-0: 02:29:32 ERROR unit.postgresql-test-app/0.juju-log Uncaught exception while in charm code:
Traceback (most recent call last):
  File "/var/lib/juju/agents/unit-postgresql-test-app-0/charm/src/charm.py", line 560, in <module>
    main(ApplicationCharm)
  File "/var/lib/juju/agents/unit-postgresql-test-app-0/charm/venv/lib/python3.10/site-packages/ops/__init__.py", line 343, in __call__
    return _main.main(charm_class=charm_class, use_juju_for_storage=use_juju_for_storage)
  File "/var/lib/juju/agents/unit-postgresql-test-app-0/charm/venv/lib/python3.10/site-packages/ops/_main.py", line 558, in main
    manager.run()
  File "/var/lib/juju/agents/unit-postgresql-test-app-0/charm/venv/lib/python3.10/site-packages/ops/_main.py", line 543, in run
    self._emit()
  File "/var/lib/juju/agents/unit-postgresql-test-app-0/charm/venv/lib/python3.10/site-packages/ops/_main.py", line 502, in _emit
    self._emit_charm_event(self.dispatcher.event_name)
  File "/var/lib/juju/agents/unit-postgresql-test-app-0/charm/venv/lib/python3.10/site-packages/ops/_main.py", line 530, in _emit_charm_event
    event_to_emit.emit(*args, **kwargs)
  File "/var/lib/juju/agents/unit-postgresql-test-app-0/charm/venv/lib/python3.10/site-packages/ops/framework.py", line 347, in emit
    framework._emit(event)
  File "/var/lib/juju/agents/unit-postgresql-test-app-0/charm/venv/lib/python3.10/site-packages/ops/framework.py", line 906, in _emit
    self._reemit(event_path)
  File "/var/lib/juju/agents/unit-postgresql-test-app-0/charm/venv/lib/python3.10/site-packages/ops/framework.py", line 996, in _reemit
    custom_handler(event)
  File "/var/lib/juju/agents/unit-postgresql-test-app-0/charm/src/charm.py", line 327, in _on_clear_continuous_writes_action
    connection.close()
UnboundLocalError: local variable 'connection' referenced before assignment
unit-postgresql-3: 02:29:34 ERROR unit.postgresql/3.juju-log Failed to list PostgreSQL database users: connection to server at "10.244.155.96", port 5432 failed: timeout expired

unit-postgresql-test-app-0: 02:29:37 ERROR unit.postgresql-test-app/0.juju-log Unable to drop table
Traceback (most recent call last):
  File "/var/lib/juju/agents/unit-postgresql-test-app-0/charm/src/charm.py", line 318, in _on_clear_continuous_writes_action
    psycopg2.connect(self._connection_string) as connection,
  File "/var/lib/juju/agents/unit-postgresql-test-app-0/charm/venv/lib/python3.10/site-packages/psycopg2/__init__.py", line 122, in connect
    conn = _connect(dsn, connection_factory=connection_factory, **kwasync)
psycopg2.OperationalError: connection to server at "10.244.155.96", port 5432 failed: Connection timed out
	Is the server running on that host and accepting TCP/IP connections?

unit-postgresql-test-app-0: 02:29:37 ERROR unit.postgresql-test-app/0.juju-log Uncaught exception while in charm code:
Traceback (most recent call last):
  File "/var/lib/juju/agents/unit-postgresql-test-app-0/charm/src/charm.py", line 560, in <module>
    main(ApplicationCharm)
  File "/var/lib/juju/agents/unit-postgresql-test-app-0/charm/venv/lib/python3.10/site-packages/ops/__init__.py", line 343, in __call__
    return _main.main(charm_class=charm_class, use_juju_for_storage=use_juju_for_storage)
  File "/var/lib/juju/agents/unit-postgresql-test-app-0/charm/venv/lib/python3.10/site-packages/ops/_main.py", line 558, in main
    manager.run()
  File "/var/lib/juju/agents/unit-postgresql-test-app-0/charm/venv/lib/python3.10/site-packages/ops/_main.py", line 543, in run
    self._emit()
  File "/var/lib/juju/agents/unit-postgresql-test-app-0/charm/venv/lib/python3.10/site-packages/ops/_main.py", line 502, in _emit
    self._emit_charm_event(self.dispatcher.event_name)
  File "/var/lib/juju/agents/unit-postgresql-test-app-0/charm/venv/lib/python3.10/site-packages/ops/_main.py", line 530, in _emit_charm_event
    event_to_emit.emit(*args, **kwargs)
  File "/var/lib/juju/agents/unit-postgresql-test-app-0/charm/venv/lib/python3.10/site-packages/ops/framework.py", line 347, in emit
    framework._emit(event)
  File "/var/lib/juju/agents/unit-postgresql-test-app-0/charm/venv/lib/python3.10/site-packages/ops/framework.py", line 906, in _emit
    self._reemit(event_path)
  File "/var/lib/juju/agents/unit-postgresql-test-app-0/charm/venv/lib/python3.10/site-packages/ops/framework.py", line 996, in _reemit
    custom_handler(event)
  File "/var/lib/juju/agents/unit-postgresql-test-app-0/charm/src/charm.py", line 327, in _on_clear_continuous_writes_action
    connection.close()
UnboundLocalError: local variable 'connection' referenced before assignment
unit-postgresql-test-app-0: 02:29:42 ERROR unit.postgresql-test-app/0.juju-log Unable to drop table
Traceback (most recent call last):
  File "/var/lib/juju/agents/unit-postgresql-test-app-0/charm/src/charm.py", line 318, in _on_clear_continuous_writes_action
    psycopg2.connect(self._connection_string) as connection,
  File "/var/lib/juju/agents/unit-postgresql-test-app-0/charm/venv/lib/python3.10/site-packages/psycopg2/__init__.py", line 122, in connect
    conn = _connect(dsn, connection_factory=connection_factory, **kwasync)
psycopg2.OperationalError: connection to server at "10.244.155.96", port 5432 failed: Connection timed out
	Is the server running on that host and accepting TCP/IP connections?

unit-postgresql-test-app-0: 02:29:42 ERROR unit.postgresql-test-app/0.juju-log Uncaught exception while in charm code:
Traceback (most recent call last):
  File "/var/lib/juju/agents/unit-postgresql-test-app-0/charm/src/charm.py", line 560, in <module>
    main(ApplicationCharm)
  File "/var/lib/juju/agents/unit-postgresql-test-app-0/charm/venv/lib/python3.10/site-packages/ops/__init__.py", line 343, in __call__
    return _main.main(charm_class=charm_class, use_juju_for_storage=use_juju_for_storage)
  File "/var/lib/juju/agents/unit-postgresql-test-app-0/charm/venv/lib/python3.10/site-packages/ops/_main.py", line 558, in main
    manager.run()
  File "/var/lib/juju/agents/unit-postgresql-test-app-0/charm/venv/lib/python3.10/site-packages/ops/_main.py", line 543, in run
    self._emit()
  File "/var/lib/juju/agents/unit-postgresql-test-app-0/charm/venv/lib/python3.10/site-packages/ops/_main.py", line 502, in _emit
    self._emit_charm_event(self.dispatcher.event_name)
  File "/var/lib/juju/agents/unit-postgresql-test-app-0/charm/venv/lib/python3.10/site-packages/ops/_main.py", line 530, in _emit_charm_event
    event_to_emit.emit(*args, **kwargs)
  File "/var/lib/juju/agents/unit-postgresql-test-app-0/charm/venv/lib/python3.10/site-packages/ops/framework.py", line 347, in emit
    framework._emit(event)
  File "/var/lib/juju/agents/unit-postgresql-test-app-0/charm/venv/lib/python3.10/site-packages/ops/framework.py", line 906, in _emit
    self._reemit(event_path)
  File "/var/lib/juju/agents/unit-postgresql-test-app-0/charm/venv/lib/python3.10/site-packages/ops/framework.py", line 996, in _reemit
    custom_handler(event)
  File "/var/lib/juju/agents/unit-postgresql-test-app-0/charm/src/charm.py", line 327, in _on_clear_continuous_writes_action
    connection.close()
UnboundLocalError: local variable 'connection' referenced before assignment
unit-postgresql-3: 02:29:44 ERROR unit.postgresql/3.juju-log Failed to list PostgreSQL database users: connection to server at "10.244.155.96", port 5432 failed: timeout expired

unit-postgresql-test-app-0: 02:29:47 ERROR unit.postgresql-test-app/0.juju-log Unable to drop table
Traceback (most recent call last):
  File "/var/lib/juju/agents/unit-postgresql-test-app-0/charm/src/charm.py", line 318, in _on_clear_continuous_writes_action
    psycopg2.connect(self._connection_string) as connection,
  File "/var/lib/juju/agents/unit-postgresql-test-app-0/charm/venv/lib/python3.10/site-packages/psycopg2/__init__.py", line 122, in connect
    conn = _connect(dsn, connection_factory=connection_factory, **kwasync)
psycopg2.OperationalError: connection to server at "10.244.155.96", port 5432 failed: Connection timed out
	Is the server running on that host and accepting TCP/IP connections?

unit-postgresql-test-app-0: 02:29:47 ERROR unit.postgresql-test-app/0.juju-log Uncaught exception while in charm code:
Traceback (most recent call last):
  File "/var/lib/juju/agents/unit-postgresql-test-app-0/charm/src/charm.py", line 560, in <module>
    main(ApplicationCharm)
  File "/var/lib/juju/agents/unit-postgresql-test-app-0/charm/venv/lib/python3.10/site-packages/ops/__init__.py", line 343, in __call__
    return _main.main(charm_class=charm_class, use_juju_for_storage=use_juju_for_storage)
  File "/var/lib/juju/agents/unit-postgresql-test-app-0/charm/venv/lib/python3.10/site-packages/ops/_main.py", line 558, in main
    manager.run()
  File "/var/lib/juju/agents/unit-postgresql-test-app-0/charm/venv/lib/python3.10/site-packages/ops/_main.py", line 543, in run
    self._emit()
  File "/var/lib/juju/agents/unit-postgresql-test-app-0/charm/venv/lib/python3.10/site-packages/ops/_main.py", line 502, in _emit
    self._emit_charm_event(self.dispatcher.event_name)
  File "/var/lib/juju/agents/unit-postgresql-test-app-0/charm/venv/lib/python3.10/site-packages/ops/_main.py", line 530, in _emit_charm_event
    event_to_emit.emit(*args, **kwargs)
  File "/var/lib/juju/agents/unit-postgresql-test-app-0/charm/venv/lib/python3.10/site-packages/ops/framework.py", line 347, in emit
    framework._emit(event)
  File "/var/lib/juju/agents/unit-postgresql-test-app-0/charm/venv/lib/python3.10/site-packages/ops/framework.py", line 906, in _emit
    self._reemit(event_path)
  File "/var/lib/juju/agents/unit-postgresql-test-app-0/charm/venv/lib/python3.10/site-packages/ops/framework.py", line 996, in _reemit
    custom_handler(event)
  File "/var/lib/juju/agents/unit-postgresql-test-app-0/charm/src/charm.py", line 327, in _on_clear_continuous_writes_action
    connection.close()
UnboundLocalError: local variable 'connection' referenced before assignment
unit-postgresql-test-app-0: 02:29:52 ERROR unit.postgresql-test-app/0.juju-log Unable to drop table
Traceback (most recent call last):
  File "/var/lib/juju/agents/unit-postgresql-test-app-0/charm/src/charm.py", line 318, in _on_clear_continuous_writes_action
    psycopg2.connect(self._connection_string) as connection,
  File "/var/lib/juju/agents/unit-postgresql-test-app-0/charm/venv/lib/python3.10/site-packages/psycopg2/__init__.py", line 122, in connect
    conn = _connect(dsn, connection_factory=connection_factory, **kwasync)
psycopg2.OperationalError: connection to server at "10.244.155.96", port 5432 failed: Connection timed out
	Is the server running on that host and accepting TCP/IP connections?

unit-postgresql-test-app-0: 02:29:52 ERROR unit.postgresql-test-app/0.juju-log Uncaught exception while in charm code:
Traceback (most recent call last):
  File "/var/lib/juju/agents/unit-postgresql-test-app-0/charm/src/charm.py", line 560, in <module>
    main(ApplicationCharm)
  File "/var/lib/juju/agents/unit-postgresql-test-app-0/charm/venv/lib/python3.10/site-packages/ops/__init__.py", line 343, in __call__
    return _main.main(charm_class=charm_class, use_juju_for_storage=use_juju_for_storage)
  File "/var/lib/juju/agents/unit-postgresql-test-app-0/charm/venv/lib/python3.10/site-packages/ops/_main.py", line 558, in main
    manager.run()
  File "/var/lib/juju/agents/unit-postgresql-test-app-0/charm/venv/lib/python3.10/site-packages/ops/_main.py", line 543, in run
    self._emit()
  File "/var/lib/juju/agents/unit-postgresql-test-app-0/charm/venv/lib/python3.10/site-packages/ops/_main.py", line 502, in _emit
    self._emit_charm_event(self.dispatcher.event_name)
  File "/var/lib/juju/agents/unit-postgresql-test-app-0/charm/venv/lib/python3.10/site-packages/ops/_main.py", line 530, in _emit_charm_event
    event_to_emit.emit(*args, **kwargs)
  File "/var/lib/juju/agents/unit-postgresql-test-app-0/charm/venv/lib/python3.10/site-packages/ops/framework.py", line 347, in emit
    framework._emit(event)
  File "/var/lib/juju/agents/unit-postgresql-test-app-0/charm/venv/lib/python3.10/site-packages/ops/framework.py", line 906, in _emit
    self._reemit(event_path)
  File "/var/lib/juju/agents/unit-postgresql-test-app-0/charm/venv/lib/python3.10/site-packages/ops/framework.py", line 996, in _reemit
    custom_handler(event)
  File "/var/lib/juju/agents/unit-postgresql-test-app-0/charm/src/charm.py", line 327, in _on_clear_continuous_writes_action
    connection.close()
UnboundLocalError: local variable 'connection' referenced before assignment
unit-postgresql-3: 02:29:54 ERROR unit.postgresql/3.juju-log Failed to list PostgreSQL database users: connection to server at "10.244.155.96", port 5432 failed: timeout expired

unit-postgresql-test-app-0: 02:29:57 ERROR unit.postgresql-test-app/0.juju-log Unable to drop table
Traceback (most recent call last):
  File "/var/lib/juju/agents/unit-postgresql-test-app-0/charm/src/charm.py", line 318, in _on_clear_continuous_writes_action
    psycopg2.connect(self._connection_string) as connection,
  File "/var/lib/juju/agents/unit-postgresql-test-app-0/charm/venv/lib/python3.10/site-packages/psycopg2/__init__.py", line 122, in connect
    conn = _connect(dsn, connection_factory=connection_factory, **kwasync)
psycopg2.OperationalError: connection to server at "10.244.155.96", port 5432 failed: Connection timed out
	Is the server running on that host and accepting TCP/IP connections?

unit-postgresql-test-app-0: 02:29:57 ERROR unit.postgresql-test-app/0.juju-log Uncaught exception while in charm code:
Traceback (most recent call last):
  File "/var/lib/juju/agents/unit-postgresql-test-app-0/charm/src/charm.py", line 560, in <module>
    main(ApplicationCharm)
  File "/var/lib/juju/agents/unit-postgresql-test-app-0/charm/venv/lib/python3.10/site-packages/ops/__init__.py", line 343, in __call__
    return _main.main(charm_class=charm_class, use_juju_for_storage=use_juju_for_storage)
  File "/var/lib/juju/agents/unit-postgresql-test-app-0/charm/venv/lib/python3.10/site-packages/ops/_main.py", line 558, in main
    manager.run()
  File "/var/lib/juju/agents/unit-postgresql-test-app-0/charm/venv/lib/python3.10/site-packages/ops/_main.py", line 543, in run
    self._emit()
  File "/var/lib/juju/agents/unit-postgresql-test-app-0/charm/venv/lib/python3.10/site-packages/ops/_main.py", line 502, in _emit
    self._emit_charm_event(self.dispatcher.event_name)
  File "/var/lib/juju/agents/unit-postgresql-test-app-0/charm/venv/lib/python3.10/site-packages/ops/_main.py", line 530, in _emit_charm_event
    event_to_emit.emit(*args, **kwargs)
  File "/var/lib/juju/agents/unit-postgresql-test-app-0/charm/venv/lib/python3.10/site-packages/ops/framework.py", line 347, in emit
    framework._emit(event)
  File "/var/lib/juju/agents/unit-postgresql-test-app-0/charm/venv/lib/python3.10/site-packages/ops/framework.py", line 906, in _emit
    self._reemit(event_path)
  File "/var/lib/juju/agents/unit-postgresql-test-app-0/charm/venv/lib/python3.10/site-packages/ops/framework.py", line 996, in _reemit
    custom_handler(event)
  File "/var/lib/juju/agents/unit-postgresql-test-app-0/charm/src/charm.py", line 327, in _on_clear_continuous_writes_action
    connection.close()
UnboundLocalError: local variable 'connection' referenced before assignment
unit-postgresql-test-app-0: 02:30:02 ERROR unit.postgresql-test-app/0.juju-log Unable to drop table
Traceback (most recent call last):
  File "/var/lib/juju/agents/unit-postgresql-test-app-0/charm/src/charm.py", line 318, in _on_clear_continuous_writes_action
    psycopg2.connect(self._connection_string) as connection,
  File "/var/lib/juju/agents/unit-postgresql-test-app-0/charm/venv/lib/python3.10/site-packages/psycopg2/__init__.py", line 122, in connect
    conn = _connect(dsn, connection_factory=connection_factory, **kwasync)
psycopg2.OperationalError: connection to server at "10.244.155.96", port 5432 failed: Connection timed out
	Is the server running on that host and accepting TCP/IP connections?

unit-postgresql-test-app-0: 02:30:02 ERROR unit.postgresql-test-app/0.juju-log Uncaught exception while in charm code:
Traceback (most recent call last):
  File "/var/lib/juju/agents/unit-postgresql-test-app-0/charm/src/charm.py", line 560, in <module>
    main(ApplicationCharm)
  File "/var/lib/juju/agents/unit-postgresql-test-app-0/charm/venv/lib/python3.10/site-packages/ops/__init__.py", line 343, in __call__
    return _main.main(charm_class=charm_class, use_juju_for_storage=use_juju_for_storage)
  File "/var/lib/juju/agents/unit-postgresql-test-app-0/charm/venv/lib/python3.10/site-packages/ops/_main.py", line 558, in main
    manager.run()
  File "/var/lib/juju/agents/unit-postgresql-test-app-0/charm/venv/lib/python3.10/site-packages/ops/_main.py", line 543, in run
    self._emit()
  File "/var/lib/juju/agents/unit-postgresql-test-app-0/charm/venv/lib/python3.10/site-packages/ops/_main.py", line 502, in _emit
    self._emit_charm_event(self.dispatcher.event_name)
  File "/var/lib/juju/agents/unit-postgresql-test-app-0/charm/venv/lib/python3.10/site-packages/ops/_main.py", line 530, in _emit_charm_event
    event_to_emit.emit(*args, **kwargs)
  File "/var/lib/juju/agents/unit-postgresql-test-app-0/charm/venv/lib/python3.10/site-packages/ops/framework.py", line 347, in emit
    framework._emit(event)
  File "/var/lib/juju/agents/unit-postgresql-test-app-0/charm/venv/lib/python3.10/site-packages/ops/framework.py", line 906, in _emit
    self._reemit(event_path)
  File "/var/lib/juju/agents/unit-postgresql-test-app-0/charm/venv/lib/python3.10/site-packages/ops/framework.py", line 996, in _reemit
    custom_handler(event)
  File "/var/lib/juju/agents/unit-postgresql-test-app-0/charm/src/charm.py", line 327, in _on_clear_continuous_writes_action
    connection.close()
UnboundLocalError: local variable 'connection' referenced before assignment
unit-postgresql-3: 02:30:06 ERROR unit.postgresql/3.juju-log Failed to list PostgreSQL database users: connection to server at "10.244.155.96", port 5432 failed: timeout expired

unit-postgresql-test-app-0: 02:30:07 ERROR unit.postgresql-test-app/0.juju-log Unable to drop table
Traceback (most recent call last):
  File "/var/lib/juju/agents/unit-postgresql-test-app-0/charm/src/charm.py", line 318, in _on_clear_continuous_writes_action
    psycopg2.connect(self._connection_string) as connection,
  File "/var/lib/juju/agents/unit-postgresql-test-app-0/charm/venv/lib/python3.10/site-packages/psycopg2/__init__.py", line 122, in connect
    conn = _connect(dsn, connection_factory=connection_factory, **kwasync)
psycopg2.OperationalError: connection to server at "10.244.155.96", port 5432 failed: Connection timed out
	Is the server running on that host and accepting TCP/IP connections?

unit-postgresql-test-app-0: 02:30:07 ERROR unit.postgresql-test-app/0.juju-log Uncaught exception while in charm code:
Traceback (most recent call last):
  File "/var/lib/juju/agents/unit-postgresql-test-app-0/charm/src/charm.py", line 560, in <module>
    main(ApplicationCharm)
  File "/var/lib/juju/agents/unit-postgresql-test-app-0/charm/venv/lib/python3.10/site-packages/ops/__init__.py", line 343, in __call__
    return _main.main(charm_class=charm_class, use_juju_for_storage=use_juju_for_storage)
  File "/var/lib/juju/agents/unit-postgresql-test-app-0/charm/venv/lib/python3.10/site-packages/ops/_main.py", line 558, in main
    manager.run()
  File "/var/lib/juju/agents/unit-postgresql-test-app-0/charm/venv/lib/python3.10/site-packages/ops/_main.py", line 543, in run
    self._emit()
  File "/var/lib/juju/agents/unit-postgresql-test-app-0/charm/venv/lib/python3.10/site-packages/ops/_main.py", line 502, in _emit
    self._emit_charm_event(self.dispatcher.event_name)
  File "/var/lib/juju/agents/unit-postgresql-test-app-0/charm/venv/lib/python3.10/site-packages/ops/_main.py", line 530, in _emit_charm_event
    event_to_emit.emit(*args, **kwargs)
  File "/var/lib/juju/agents/unit-postgresql-test-app-0/charm/venv/lib/python3.10/site-packages/ops/framework.py", line 347, in emit
    framework._emit(event)
  File "/var/lib/juju/agents/unit-postgresql-test-app-0/charm/venv/lib/python3.10/site-packages/ops/framework.py", line 906, in _emit
    self._reemit(event_path)
  File "/var/lib/juju/agents/unit-postgresql-test-app-0/charm/venv/lib/python3.10/site-packages/ops/framework.py", line 996, in _reemit
    custom_handler(event)
  File "/var/lib/juju/agents/unit-postgresql-test-app-0/charm/src/charm.py", line 327, in _on_clear_continuous_writes_action
    connection.close()
UnboundLocalError: local variable 'connection' referenced before assignment
unit-postgresql-test-app-0: 02:30:12 ERROR unit.postgresql-test-app/0.juju-log Unable to drop table
Traceback (most recent call last):
  File "/var/lib/juju/agents/unit-postgresql-test-app-0/charm/src/charm.py", line 318, in _on_clear_continuous_writes_action
    psycopg2.connect(self._connection_string) as connection,
  File "/var/lib/juju/agents/unit-postgresql-test-app-0/charm/venv/lib/python3.10/site-packages/psycopg2/__init__.py", line 122, in connect
    conn = _connect(dsn, connection_factory=connection_factory, **kwasync)
psycopg2.OperationalError: connection to server at "10.244.155.96", port 5432 failed: Connection timed out
	Is the server running on that host and accepting TCP/IP connections?

unit-postgresql-test-app-0: 02:30:12 ERROR unit.postgresql-test-app/0.juju-log Uncaught exception while in charm code:
Traceback (most recent call last):
  File "/var/lib/juju/agents/unit-postgresql-test-app-0/charm/src/charm.py", line 560, in <module>
    main(ApplicationCharm)
  File "/var/lib/juju/agents/unit-postgresql-test-app-0/charm/venv/lib/python3.10/site-packages/ops/__init__.py", line 343, in __call__
    return _main.main(charm_class=charm_class, use_juju_for_storage=use_juju_for_storage)
  File "/var/lib/juju/agents/unit-postgresql-test-app-0/charm/venv/lib/python3.10/site-packages/ops/_main.py", line 558, in main
    manager.run()
  File "/var/lib/juju/agents/unit-postgresql-test-app-0/charm/venv/lib/python3.10/site-packages/ops/_main.py", line 543, in run
    self._emit()
  File "/var/lib/juju/agents/unit-postgresql-test-app-0/charm/venv/lib/python3.10/site-packages/ops/_main.py", line 502, in _emit
    self._emit_charm_event(self.dispatcher.event_name)
  File "/var/lib/juju/agents/unit-postgresql-test-app-0/charm/venv/lib/python3.10/site-packages/ops/_main.py", line 530, in _emit_charm_event
    event_to_emit.emit(*args, **kwargs)
  File "/var/lib/juju/agents/unit-postgresql-test-app-0/charm/venv/lib/python3.10/site-packages/ops/framework.py", line 347, in emit
    framework._emit(event)
  File "/var/lib/juju/agents/unit-postgresql-test-app-0/charm/venv/lib/python3.10/site-packages/ops/framework.py", line 906, in _emit
    self._reemit(event_path)
  File "/var/lib/juju/agents/unit-postgresql-test-app-0/charm/venv/lib/python3.10/site-packages/ops/framework.py", line 996, in _reemit
    custom_handler(event)
  File "/var/lib/juju/agents/unit-postgresql-test-app-0/charm/src/charm.py", line 327, in _on_clear_continuous_writes_action
    connection.close()
UnboundLocalError: local variable 'connection' referenced before assignment
unit-postgresql-3: 02:30:15 ERROR unit.postgresql/3.juju-log Failed to list PostgreSQL database users: connection to server at "10.244.155.96", port 5432 failed: timeout expired

unit-postgresql-test-app-0: 02:30:18 ERROR unit.postgresql-test-app/0.juju-log Unable to drop table
Traceback (most recent call last):
  File "/var/lib/juju/agents/unit-postgresql-test-app-0/charm/src/charm.py", line 318, in _on_clear_continuous_writes_action
    psycopg2.connect(self._connection_string) as connection,
  File "/var/lib/juju/agents/unit-postgresql-test-app-0/charm/venv/lib/python3.10/site-packages/psycopg2/__init__.py", line 122, in connect
    conn = _connect(dsn, connection_factory=connection_factory, **kwasync)
psycopg2.OperationalError: connection to server at "10.244.155.96", port 5432 failed: Connection timed out
	Is the server running on that host and accepting TCP/IP connections?

unit-postgresql-test-app-0: 02:30:18 ERROR unit.postgresql-test-app/0.juju-log Uncaught exception while in charm code:
Traceback (most recent call last):
  File "/var/lib/juju/agents/unit-postgresql-test-app-0/charm/src/charm.py", line 560, in <module>
    main(ApplicationCharm)
  File "/var/lib/juju/agents/unit-postgresql-test-app-0/charm/venv/lib/python3.10/site-packages/ops/__init__.py", line 343, in __call__
    return _main.main(charm_class=charm_class, use_juju_for_storage=use_juju_for_storage)
  File "/var/lib/juju/agents/unit-postgresql-test-app-0/charm/venv/lib/python3.10/site-packages/ops/_main.py", line 558, in main
    manager.run()
  File "/var/lib/juju/agents/unit-postgresql-test-app-0/charm/venv/lib/python3.10/site-packages/ops/_main.py", line 543, in run
    self._emit()
  File "/var/lib/juju/agents/unit-postgresql-test-app-0/charm/venv/lib/python3.10/site-packages/ops/_main.py", line 502, in _emit
    self._emit_charm_event(self.dispatcher.event_name)
  File "/var/lib/juju/agents/unit-postgresql-test-app-0/charm/venv/lib/python3.10/site-packages/ops/_main.py", line 530, in _emit_charm_event
    event_to_emit.emit(*args, **kwargs)
  File "/var/lib/juju/agents/unit-postgresql-test-app-0/charm/venv/lib/python3.10/site-packages/ops/framework.py", line 347, in emit
    framework._emit(event)
  File "/var/lib/juju/agents/unit-postgresql-test-app-0/charm/venv/lib/python3.10/site-packages/ops/framework.py", line 906, in _emit
    self._reemit(event_path)
  File "/var/lib/juju/agents/unit-postgresql-test-app-0/charm/venv/lib/python3.10/site-packages/ops/framework.py", line 996, in _reemit
    custom_handler(event)
  File "/var/lib/juju/agents/unit-postgresql-test-app-0/charm/src/charm.py", line 327, in _on_clear_continuous_writes_action
    connection.close()
UnboundLocalError: local variable 'connection' referenced before assignment
unit-postgresql-test-app-0: 02:30:23 ERROR unit.postgresql-test-app/0.juju-log Unable to drop table
Traceback (most recent call last):
  File "/var/lib/juju/agents/unit-postgresql-test-app-0/charm/src/charm.py", line 318, in _on_clear_continuous_writes_action
    psycopg2.connect(self._connection_string) as connection,
  File "/var/lib/juju/agents/unit-postgresql-test-app-0/charm/venv/lib/python3.10/site-packages/psycopg2/__init__.py", line 122, in connect
    conn = _connect(dsn, connection_factory=connection_factory, **kwasync)
psycopg2.OperationalError: connection to server at "10.244.155.96", port 5432 failed: Connection timed out
	Is the server running on that host and accepting TCP/IP connections?

unit-postgresql-test-app-0: 02:30:23 ERROR unit.postgresql-test-app/0.juju-log Uncaught exception while in charm code:
Traceback (most recent call last):
  File "/var/lib/juju/agents/unit-postgresql-test-app-0/charm/src/charm.py", line 560, in <module>
    main(ApplicationCharm)
  File "/var/lib/juju/agents/unit-postgresql-test-app-0/charm/venv/lib/python3.10/site-packages/ops/__init__.py", line 343, in __call__
    return _main.main(charm_class=charm_class, use_juju_for_storage=use_juju_for_storage)
  File "/var/lib/juju/agents/unit-postgresql-test-app-0/charm/venv/lib/python3.10/site-packages/ops/_main.py", line 558, in main
    manager.run()
  File "/var/lib/juju/agents/unit-postgresql-test-app-0/charm/venv/lib/python3.10/site-packages/ops/_main.py", line 543, in run
    self._emit()
  File "/var/lib/juju/agents/unit-postgresql-test-app-0/charm/venv/lib/python3.10/site-packages/ops/_main.py", line 502, in _emit
    self._emit_charm_event(self.dispatcher.event_name)
  File "/var/lib/juju/agents/unit-postgresql-test-app-0/charm/venv/lib/python3.10/site-packages/ops/_main.py", line 530, in _emit_charm_event
    event_to_emit.emit(*args, **kwargs)
  File "/var/lib/juju/agents/unit-postgresql-test-app-0/charm/venv/lib/python3.10/site-packages/ops/framework.py", line 347, in emit
    framework._emit(event)
  File "/var/lib/juju/agents/unit-postgresql-test-app-0/charm/venv/lib/python3.10/site-packages/ops/framework.py", line 906, in _emit
    self._reemit(event_path)
  File "/var/lib/juju/agents/unit-postgresql-test-app-0/charm/venv/lib/python3.10/site-packages/ops/framework.py", line 996, in _reemit
    custom_handler(event)
  File "/var/lib/juju/agents/unit-postgresql-test-app-0/charm/src/charm.py", line 327, in _on_clear_continuous_writes_action
    connection.close()
UnboundLocalError: local variable 'connection' referenced before assignment
unit-postgresql-3: 02:30:23 ERROR unit.postgresql/3.juju-log Failed to list PostgreSQL database users: connection to server at "10.244.155.96", port 5432 failed: timeout expired

unit-postgresql-test-app-0: 02:30:28 ERROR unit.postgresql-test-app/0.juju-log Unable to drop table
Traceback (most recent call last):
  File "/var/lib/juju/agents/unit-postgresql-test-app-0/charm/src/charm.py", line 318, in _on_clear_continuous_writes_action
    psycopg2.connect(self._connection_string) as connection,
  File "/var/lib/juju/agents/unit-postgresql-test-app-0/charm/venv/lib/python3.10/site-packages/psycopg2/__init__.py", line 122, in connect
    conn = _connect(dsn, connection_factory=connection_factory, **kwasync)
psycopg2.OperationalError: connection to server at "10.244.155.96", port 5432 failed: Connection timed out
	Is the server running on that host and accepting TCP/IP connections?

unit-postgresql-test-app-0: 02:30:28 ERROR unit.postgresql-test-app/0.juju-log Uncaught exception while in charm code:
Traceback (most recent call last):
  File "/var/lib/juju/agents/unit-postgresql-test-app-0/charm/src/charm.py", line 560, in <module>
    main(ApplicationCharm)
  File "/var/lib/juju/agents/unit-postgresql-test-app-0/charm/venv/lib/python3.10/site-packages/ops/__init__.py", line 343, in __call__
    return _main.main(charm_class=charm_class, use_juju_for_storage=use_juju_for_storage)
  File "/var/lib/juju/agents/unit-postgresql-test-app-0/charm/venv/lib/python3.10/site-packages/ops/_main.py", line 558, in main
    manager.run()
  File "/var/lib/juju/agents/unit-postgresql-test-app-0/charm/venv/lib/python3.10/site-packages/ops/_main.py", line 543, in run
    self._emit()
  File "/var/lib/juju/agents/unit-postgresql-test-app-0/charm/venv/lib/python3.10/site-packages/ops/_main.py", line 502, in _emit
    self._emit_charm_event(self.dispatcher.event_name)
  File "/var/lib/juju/agents/unit-postgresql-test-app-0/charm/venv/lib/python3.10/site-packages/ops/_main.py", line 530, in _emit_charm_event
    event_to_emit.emit(*args, **kwargs)
  File "/var/lib/juju/agents/unit-postgresql-test-app-0/charm/venv/lib/python3.10/site-packages/ops/framework.py", line 347, in emit
    framework._emit(event)
  File "/var/lib/juju/agents/unit-postgresql-test-app-0/charm/venv/lib/python3.10/site-packages/ops/framework.py", line 906, in _emit
    self._reemit(event_path)
  File "/var/lib/juju/agents/unit-postgresql-test-app-0/charm/venv/lib/python3.10/site-packages/ops/framework.py", line 996, in _reemit
    custom_handler(event)
  File "/var/lib/juju/agents/unit-postgresql-test-app-0/charm/src/charm.py", line 327, in _on_clear_continuous_writes_action
    connection.close()
UnboundLocalError: local variable 'connection' referenced before assignment
unit-postgresql-3: 02:30:32 ERROR unit.postgresql/3.juju-log Failed to list PostgreSQL database users: connection to server at "10.244.155.96", port 5432 failed: timeout expired

unit-postgresql-test-app-0: 02:30:33 ERROR unit.postgresql-test-app/0.juju-log Unable to drop table
Traceback (most recent call last):
  File "/var/lib/juju/agents/unit-postgresql-test-app-0/charm/src/charm.py", line 318, in _on_clear_continuous_writes_action
    psycopg2.connect(self._connection_string) as connection,
  File "/var/lib/juju/agents/unit-postgresql-test-app-0/charm/venv/lib/python3.10/site-packages/psycopg2/__init__.py", line 122, in connect
    conn = _connect(dsn, connection_factory=connection_factory, **kwasync)
psycopg2.OperationalError: connection to server at "10.244.155.96", port 5432 failed: Connection timed out
	Is the server running on that host and accepting TCP/IP connections?

unit-postgresql-test-app-0: 02:30:33 ERROR unit.postgresql-test-app/0.juju-log Uncaught exception while in charm code:
Traceback (most recent call last):
  File "/var/lib/juju/agents/unit-postgresql-test-app-0/charm/src/charm.py", line 560, in <module>
    main(ApplicationCharm)
  File "/var/lib/juju/agents/unit-postgresql-test-app-0/charm/venv/lib/python3.10/site-packages/ops/__init__.py", line 343, in __call__
    return _main.main(charm_class=charm_class, use_juju_for_storage=use_juju_for_storage)
  File "/var/lib/juju/agents/unit-postgresql-test-app-0/charm/venv/lib/python3.10/site-packages/ops/_main.py", line 558, in main
    manager.run()
  File "/var/lib/juju/agents/unit-postgresql-test-app-0/charm/venv/lib/python3.10/site-packages/ops/_main.py", line 543, in run
    self._emit()
  File "/var/lib/juju/agents/unit-postgresql-test-app-0/charm/venv/lib/python3.10/site-packages/ops/_main.py", line 502, in _emit
    self._emit_charm_event(self.dispatcher.event_name)
  File "/var/lib/juju/agents/unit-postgresql-test-app-0/charm/venv/lib/python3.10/site-packages/ops/_main.py", line 530, in _emit_charm_event
    event_to_emit.emit(*args, **kwargs)
  File "/var/lib/juju/agents/unit-postgresql-test-app-0/charm/venv/lib/python3.10/site-packages/ops/framework.py", line 347, in emit
    framework._emit(event)
  File "/var/lib/juju/agents/unit-postgresql-test-app-0/charm/venv/lib/python3.10/site-packages/ops/framework.py", line 906, in _emit
    self._reemit(event_path)
  File "/var/lib/juju/agents/unit-postgresql-test-app-0/charm/venv/lib/python3.10/site-packages/ops/framework.py", line 996, in _reemit
    custom_handler(event)
  File "/var/lib/juju/agents/unit-postgresql-test-app-0/charm/src/charm.py", line 327, in _on_clear_continuous_writes_action
    connection.close()
UnboundLocalError: local variable 'connection' referenced before assignment
unit-postgresql-test-app-0: 02:30:38 ERROR unit.postgresql-test-app/0.juju-log Unable to drop table
Traceback (most recent call last):
  File "/var/lib/juju/agents/unit-postgresql-test-app-0/charm/src/charm.py", line 318, in _on_clear_continuous_writes_action
    psycopg2.connect(self._connection_string) as connection,
  File "/var/lib/juju/agents/unit-postgresql-test-app-0/charm/venv/lib/python3.10/site-packages/psycopg2/__init__.py", line 122, in connect
    conn = _connect(dsn, connection_factory=connection_factory, **kwasync)
psycopg2.OperationalError: connection to server at "10.244.155.96", port 5432 failed: Connection timed out
	Is the server running on that host and accepting TCP/IP connections?

unit-postgresql-test-app-0: 02:30:38 ERROR unit.postgresql-test-app/0.juju-log Uncaught exception while in charm code:
Traceback (most recent call last):
  File "/var/lib/juju/agents/unit-postgresql-test-app-0/charm/src/charm.py", line 560, in <module>
    main(ApplicationCharm)
  File "/var/lib/juju/agents/unit-postgresql-test-app-0/charm/venv/lib/python3.10/site-packages/ops/__init__.py", line 343, in __call__
    return _main.main(charm_class=charm_class, use_juju_for_storage=use_juju_for_storage)
  File "/var/lib/juju/agents/unit-postgresql-test-app-0/charm/venv/lib/python3.10/site-packages/ops/_main.py", line 558, in main
    manager.run()
  File "/var/lib/juju/agents/unit-postgresql-test-app-0/charm/venv/lib/python3.10/site-packages/ops/_main.py", line 543, in run
    self._emit()
  File "/var/lib/juju/agents/unit-postgresql-test-app-0/charm/venv/lib/python3.10/site-packages/ops/_main.py", line 502, in _emit
    self._emit_charm_event(self.dispatcher.event_name)
  File "/var/lib/juju/agents/unit-postgresql-test-app-0/charm/venv/lib/python3.10/site-packages/ops/_main.py", line 530, in _emit_charm_event
    event_to_emit.emit(*args, **kwargs)
  File "/var/lib/juju/agents/unit-postgresql-test-app-0/charm/venv/lib/python3.10/site-packages/ops/framework.py", line 347, in emit
    framework._emit(event)
  File "/var/lib/juju/agents/unit-postgresql-test-app-0/charm/venv/lib/python3.10/site-packages/ops/framework.py", line 906, in _emit
    self._reemit(event_path)
  File "/var/lib/juju/agents/unit-postgresql-test-app-0/charm/venv/lib/python3.10/site-packages/ops/framework.py", line 996, in _reemit
    custom_handler(event)
  File "/var/lib/juju/agents/unit-postgresql-test-app-0/charm/src/charm.py", line 327, in _on_clear_continuous_writes_action
    connection.close()
UnboundLocalError: local variable 'connection' referenced before assignment
unit-postgresql-test-app-0: 02:30:43 ERROR unit.postgresql-test-app/0.juju-log Unable to drop table
Traceback (most recent call last):
  File "/var/lib/juju/agents/unit-postgresql-test-app-0/charm/src/charm.py", line 318, in _on_clear_continuous_writes_action
    psycopg2.connect(self._connection_string) as connection,
  File "/var/lib/juju/agents/unit-postgresql-test-app-0/charm/venv/lib/python3.10/site-packages/psycopg2/__init__.py", line 122, in connect
    conn = _connect(dsn, connection_factory=connection_factory, **kwasync)
psycopg2.OperationalError: connection to server at "10.244.155.96", port 5432 failed: Connection timed out
	Is the server running on that host and accepting TCP/IP connections?

unit-postgresql-test-app-0: 02:30:43 ERROR unit.postgresql-test-app/0.juju-log Uncaught exception while in charm code:
Traceback (most recent call last):
  File "/var/lib/juju/agents/unit-postgresql-test-app-0/charm/src/charm.py", line 560, in <module>
    main(ApplicationCharm)
  File "/var/lib/juju/agents/unit-postgresql-test-app-0/charm/venv/lib/python3.10/site-packages/ops/__init__.py", line 343, in __call__
    return _main.main(charm_class=charm_class, use_juju_for_storage=use_juju_for_storage)
  File "/var/lib/juju/agents/unit-postgresql-test-app-0/charm/venv/lib/python3.10/site-packages/ops/_main.py", line 558, in main
    manager.run()
  File "/var/lib/juju/agents/unit-postgresql-test-app-0/charm/venv/lib/python3.10/site-packages/ops/_main.py", line 543, in run
    self._emit()
  File "/var/lib/juju/agents/unit-postgresql-test-app-0/charm/venv/lib/python3.10/site-packages/ops/_main.py", line 502, in _emit
    self._emit_charm_event(self.dispatcher.event_name)
  File "/var/lib/juju/agents/unit-postgresql-test-app-0/charm/venv/lib/python3.10/site-packages/ops/_main.py", line 530, in _emit_charm_event
    event_to_emit.emit(*args, **kwargs)
  File "/var/lib/juju/agents/unit-postgresql-test-app-0/charm/venv/lib/python3.10/site-packages/ops/framework.py", line 347, in emit
    framework._emit(event)
  File "/var/lib/juju/agents/unit-postgresql-test-app-0/charm/venv/lib/python3.10/site-packages/ops/framework.py", line 906, in _emit
    self._reemit(event_path)
  File "/var/lib/juju/agents/unit-postgresql-test-app-0/charm/venv/lib/python3.10/site-packages/ops/framework.py", line 996, in _reemit
    custom_handler(event)
  File "/var/lib/juju/agents/unit-postgresql-test-app-0/charm/src/charm.py", line 327, in _on_clear_continuous_writes_action
    connection.close()
UnboundLocalError: local variable 'connection' referenced before assignment
unit-postgresql-3: 02:30:43 ERROR unit.postgresql/3.juju-log Failed to list PostgreSQL database users: connection to server at "10.244.155.96", port 5432 failed: timeout expired

unit-postgresql-test-app-0: 02:30:48 ERROR unit.postgresql-test-app/0.juju-log Unable to drop table
Traceback (most recent call last):
  File "/var/lib/juju/agents/unit-postgresql-test-app-0/charm/src/charm.py", line 318, in _on_clear_continuous_writes_action
    psycopg2.connect(self._connection_string) as connection,
  File "/var/lib/juju/agents/unit-postgresql-test-app-0/charm/venv/lib/python3.10/site-packages/psycopg2/__init__.py", line 122, in connect
    conn = _connect(dsn, connection_factory=connection_factory, **kwasync)
psycopg2.OperationalError: connection to server at "10.244.155.96", port 5432 failed: Connection timed out
	Is the server running on that host and accepting TCP/IP connections?

unit-postgresql-test-app-0: 02:30:48 ERROR unit.postgresql-test-app/0.juju-log Uncaught exception while in charm code:
Traceback (most recent call last):
  File "/var/lib/juju/agents/unit-postgresql-test-app-0/charm/src/charm.py", line 560, in <module>
    main(ApplicationCharm)
  File "/var/lib/juju/agents/unit-postgresql-test-app-0/charm/venv/lib/python3.10/site-packages/ops/__init__.py", line 343, in __call__
    return _main.main(charm_class=charm_class, use_juju_for_storage=use_juju_for_storage)
  File "/var/lib/juju/agents/unit-postgresql-test-app-0/charm/venv/lib/python3.10/site-packages/ops/_main.py", line 558, in main
    manager.run()
  File "/var/lib/juju/agents/unit-postgresql-test-app-0/charm/venv/lib/python3.10/site-packages/ops/_main.py", line 543, in run
    self._emit()
  File "/var/lib/juju/agents/unit-postgresql-test-app-0/charm/venv/lib/python3.10/site-packages/ops/_main.py", line 502, in _emit
    self._emit_charm_event(self.dispatcher.event_name)
  File "/var/lib/juju/agents/unit-postgresql-test-app-0/charm/venv/lib/python3.10/site-packages/ops/_main.py", line 530, in _emit_charm_event
    event_to_emit.emit(*args, **kwargs)
  File "/var/lib/juju/agents/unit-postgresql-test-app-0/charm/venv/lib/python3.10/site-packages/ops/framework.py", line 347, in emit
    framework._emit(event)
  File "/var/lib/juju/agents/unit-postgresql-test-app-0/charm/venv/lib/python3.10/site-packages/ops/framework.py", line 906, in _emit
    self._reemit(event_path)
  File "/var/lib/juju/agents/unit-postgresql-test-app-0/charm/venv/lib/python3.10/site-packages/ops/framework.py", line 996, in _reemit
    custom_handler(event)
  File "/var/lib/juju/agents/unit-postgresql-test-app-0/charm/src/charm.py", line 327, in _on_clear_continuous_writes_action
    connection.close()
UnboundLocalError: local variable 'connection' referenced before assignment
unit-postgresql-test-app-0: 02:30:53 ERROR unit.postgresql-test-app/0.juju-log Unable to drop table
Traceback (most recent call last):
  File "/var/lib/juju/agents/unit-postgresql-test-app-0/charm/src/charm.py", line 318, in _on_clear_continuous_writes_action
    psycopg2.connect(self._connection_string) as connection,
  File "/var/lib/juju/agents/unit-postgresql-test-app-0/charm/venv/lib/python3.10/site-packages/psycopg2/__init__.py", line 122, in connect
    conn = _connect(dsn, connection_factory=connection_factory, **kwasync)
psycopg2.OperationalError: connection to server at "10.244.155.96", port 5432 failed: Connection timed out
	Is the server running on that host and accepting TCP/IP connections?

unit-postgresql-test-app-0: 02:30:53 ERROR unit.postgresql-test-app/0.juju-log Uncaught exception while in charm code:
Traceback (most recent call last):
  File "/var/lib/juju/agents/unit-postgresql-test-app-0/charm/src/charm.py", line 560, in <module>
    main(ApplicationCharm)
  File "/var/lib/juju/agents/unit-postgresql-test-app-0/charm/venv/lib/python3.10/site-packages/ops/__init__.py", line 343, in __call__
    return _main.main(charm_class=charm_class, use_juju_for_storage=use_juju_for_storage)
  File "/var/lib/juju/agents/unit-postgresql-test-app-0/charm/venv/lib/python3.10/site-packages/ops/_main.py", line 558, in main
    manager.run()
  File "/var/lib/juju/agents/unit-postgresql-test-app-0/charm/venv/lib/python3.10/site-packages/ops/_main.py", line 543, in run
    self._emit()
  File "/var/lib/juju/agents/unit-postgresql-test-app-0/charm/venv/lib/python3.10/site-packages/ops/_main.py", line 502, in _emit
    self._emit_charm_event(self.dispatcher.event_name)
  File "/var/lib/juju/agents/unit-postgresql-test-app-0/charm/venv/lib/python3.10/site-packages/ops/_main.py", line 530, in _emit_charm_event
    event_to_emit.emit(*args, **kwargs)
  File "/var/lib/juju/agents/unit-postgresql-test-app-0/charm/venv/lib/python3.10/site-packages/ops/framework.py", line 347, in emit
    framework._emit(event)
  File "/var/lib/juju/agents/unit-postgresql-test-app-0/charm/venv/lib/python3.10/site-packages/ops/framework.py", line 906, in _emit
    self._reemit(event_path)
  File "/var/lib/juju/agents/unit-postgresql-test-app-0/charm/venv/lib/python3.10/site-packages/ops/framework.py", line 996, in _reemit
    custom_handler(event)
  File "/var/lib/juju/agents/unit-postgresql-test-app-0/charm/src/charm.py", line 327, in _on_clear_continuous_writes_action
    connection.close()
UnboundLocalError: local variable 'connection' referenced before assignment
unit-postgresql-3: 02:30:53 ERROR unit.postgresql/3.juju-log Failed to list PostgreSQL database users: connection to server at "10.244.155.96", port 5432 failed: timeout expired

unit-postgresql-test-app-0: 02:30:58 ERROR unit.postgresql-test-app/0.juju-log Unable to drop table
Traceback (most recent call last):
  File "/var/lib/juju/agents/unit-postgresql-test-app-0/charm/src/charm.py", line 318, in _on_clear_continuous_writes_action
    psycopg2.connect(self._connection_string) as connection,
  File "/var/lib/juju/agents/unit-postgresql-test-app-0/charm/venv/lib/python3.10/site-packages/psycopg2/__init__.py", line 122, in connect
    conn = _connect(dsn, connection_factory=connection_factory, **kwasync)
psycopg2.OperationalError: connection to server at "10.244.155.96", port 5432 failed: Connection timed out
	Is the server running on that host and accepting TCP/IP connections?

unit-postgresql-test-app-0: 02:30:58 ERROR unit.postgresql-test-app/0.juju-log Uncaught exception while in charm code:
Traceback (most recent call last):
  File "/var/lib/juju/agents/unit-postgresql-test-app-0/charm/src/charm.py", line 560, in <module>
    main(ApplicationCharm)
  File "/var/lib/juju/agents/unit-postgresql-test-app-0/charm/venv/lib/python3.10/site-packages/ops/__init__.py", line 343, in __call__
    return _main.main(charm_class=charm_class, use_juju_for_storage=use_juju_for_storage)
  File "/var/lib/juju/agents/unit-postgresql-test-app-0/charm/venv/lib/python3.10/site-packages/ops/_main.py", line 558, in main
    manager.run()
  File "/var/lib/juju/agents/unit-postgresql-test-app-0/charm/venv/lib/python3.10/site-packages/ops/_main.py", line 543, in run
    self._emit()
  File "/var/lib/juju/agents/unit-postgresql-test-app-0/charm/venv/lib/python3.10/site-packages/ops/_main.py", line 502, in _emit
    self._emit_charm_event(self.dispatcher.event_name)
  File "/var/lib/juju/agents/unit-postgresql-test-app-0/charm/venv/lib/python3.10/site-packages/ops/_main.py", line 530, in _emit_charm_event
    event_to_emit.emit(*args, **kwargs)
  File "/var/lib/juju/agents/unit-postgresql-test-app-0/charm/venv/lib/python3.10/site-packages/ops/framework.py", line 347, in emit
    framework._emit(event)
  File "/var/lib/juju/agents/unit-postgresql-test-app-0/charm/venv/lib/python3.10/site-packages/ops/framework.py", line 906, in _emit
    self._reemit(event_path)
  File "/var/lib/juju/agents/unit-postgresql-test-app-0/charm/venv/lib/python3.10/site-packages/ops/framework.py", line 996, in _reemit
    custom_handler(event)
  File "/var/lib/juju/agents/unit-postgresql-test-app-0/charm/src/charm.py", line 327, in _on_clear_continuous_writes_action
    connection.close()
UnboundLocalError: local variable 'connection' referenced before assignment
unit-postgresql-test-app-0: 02:31:03 ERROR unit.postgresql-test-app/0.juju-log Unable to drop table
Traceback (most recent call last):
  File "/var/lib/juju/agents/unit-postgresql-test-app-0/charm/src/charm.py", line 318, in _on_clear_continuous_writes_action
    psycopg2.connect(self._connection_string) as connection,
  File "/var/lib/juju/agents/unit-postgresql-test-app-0/charm/venv/lib/python3.10/site-packages/psycopg2/__init__.py", line 122, in connect
    conn = _connect(dsn, connection_factory=connection_factory, **kwasync)
psycopg2.OperationalError: connection to server at "10.244.155.96", port 5432 failed: Connection timed out
	Is the server running on that host and accepting TCP/IP connections?

unit-postgresql-test-app-0: 02:31:03 ERROR unit.postgresql-test-app/0.juju-log Uncaught exception while in charm code:
Traceback (most recent call last):
  File "/var/lib/juju/agents/unit-postgresql-test-app-0/charm/src/charm.py", line 560, in <module>
    main(ApplicationCharm)
  File "/var/lib/juju/agents/unit-postgresql-test-app-0/charm/venv/lib/python3.10/site-packages/ops/__init__.py", line 343, in __call__
    return _main.main(charm_class=charm_class, use_juju_for_storage=use_juju_for_storage)
  File "/var/lib/juju/agents/unit-postgresql-test-app-0/charm/venv/lib/python3.10/site-packages/ops/_main.py", line 558, in main
    manager.run()
  File "/var/lib/juju/agents/unit-postgresql-test-app-0/charm/venv/lib/python3.10/site-packages/ops/_main.py", line 543, in run
    self._emit()
  File "/var/lib/juju/agents/unit-postgresql-test-app-0/charm/venv/lib/python3.10/site-packages/ops/_main.py", line 502, in _emit
    self._emit_charm_event(self.dispatcher.event_name)
  File "/var/lib/juju/agents/unit-postgresql-test-app-0/charm/venv/lib/python3.10/site-packages/ops/_main.py", line 530, in _emit_charm_event
    event_to_emit.emit(*args, **kwargs)
  File "/var/lib/juju/agents/unit-postgresql-test-app-0/charm/venv/lib/python3.10/site-packages/ops/framework.py", line 347, in emit
    framework._emit(event)
  File "/var/lib/juju/agents/unit-postgresql-test-app-0/charm/venv/lib/python3.10/site-packages/ops/framework.py", line 906, in _emit
    self._reemit(event_path)
  File "/var/lib/juju/agents/unit-postgresql-test-app-0/charm/venv/lib/python3.10/site-packages/ops/framework.py", line 996, in _reemit
    custom_handler(event)
  File "/var/lib/juju/agents/unit-postgresql-test-app-0/charm/src/charm.py", line 327, in _on_clear_continuous_writes_action
    connection.close()
UnboundLocalError: local variable 'connection' referenced before assignment
unit-postgresql-3: 02:31:03 ERROR unit.postgresql/3.juju-log Failed to list PostgreSQL database users: connection to server at "10.244.155.96", port 5432 failed: timeout expired

unit-postgresql-test-app-0: 02:31:08 ERROR unit.postgresql-test-app/0.juju-log Unable to drop table
Traceback (most recent call last):
  File "/var/lib/juju/agents/unit-postgresql-test-app-0/charm/src/charm.py", line 318, in _on_clear_continuous_writes_action
    psycopg2.connect(self._connection_string) as connection,
  File "/var/lib/juju/agents/unit-postgresql-test-app-0/charm/venv/lib/python3.10/site-packages/psycopg2/__init__.py", line 122, in connect
    conn = _connect(dsn, connection_factory=connection_factory, **kwasync)
psycopg2.OperationalError: connection to server at "10.244.155.96", port 5432 failed: Connection timed out
	Is the server running on that host and accepting TCP/IP connections?

unit-postgresql-test-app-0: 02:31:08 ERROR unit.postgresql-test-app/0.juju-log Uncaught exception while in charm code:
Traceback (most recent call last):
  File "/var/lib/juju/agents/unit-postgresql-test-app-0/charm/src/charm.py", line 560, in <module>
    main(ApplicationCharm)
  File "/var/lib/juju/agents/unit-postgresql-test-app-0/charm/venv/lib/python3.10/site-packages/ops/__init__.py", line 343, in __call__
    return _main.main(charm_class=charm_class, use_juju_for_storage=use_juju_for_storage)
  File "/var/lib/juju/agents/unit-postgresql-test-app-0/charm/venv/lib/python3.10/site-packages/ops/_main.py", line 558, in main
    manager.run()
  File "/var/lib/juju/agents/unit-postgresql-test-app-0/charm/venv/lib/python3.10/site-packages/ops/_main.py", line 543, in run
    self._emit()
  File "/var/lib/juju/agents/unit-postgresql-test-app-0/charm/venv/lib/python3.10/site-packages/ops/_main.py", line 502, in _emit
    self._emit_charm_event(self.dispatcher.event_name)
  File "/var/lib/juju/agents/unit-postgresql-test-app-0/charm/venv/lib/python3.10/site-packages/ops/_main.py", line 530, in _emit_charm_event
    event_to_emit.emit(*args, **kwargs)
  File "/var/lib/juju/agents/unit-postgresql-test-app-0/charm/venv/lib/python3.10/site-packages/ops/framework.py", line 347, in emit
    framework._emit(event)
  File "/var/lib/juju/agents/unit-postgresql-test-app-0/charm/venv/lib/python3.10/site-packages/ops/framework.py", line 906, in _emit
    self._reemit(event_path)
  File "/var/lib/juju/agents/unit-postgresql-test-app-0/charm/venv/lib/python3.10/site-packages/ops/framework.py", line 996, in _reemit
    custom_handler(event)
  File "/var/lib/juju/agents/unit-postgresql-test-app-0/charm/src/charm.py", line 327, in _on_clear_continuous_writes_action
    connection.close()
UnboundLocalError: local variable 'connection' referenced before assignment
unit-postgresql-3: 02:31:13 ERROR unit.postgresql/3.juju-log Failed to list PostgreSQL database users: connection to server at "10.244.155.96", port 5432 failed: timeout expired

unit-postgresql-test-app-0: 02:31:13 ERROR unit.postgresql-test-app/0.juju-log Unable to drop table
Traceback (most recent call last):
  File "/var/lib/juju/agents/unit-postgresql-test-app-0/charm/src/charm.py", line 318, in _on_clear_continuous_writes_action
    psycopg2.connect(self._connection_string) as connection,
  File "/var/lib/juju/agents/unit-postgresql-test-app-0/charm/venv/lib/python3.10/site-packages/psycopg2/__init__.py", line 122, in connect
    conn = _connect(dsn, connection_factory=connection_factory, **kwasync)
psycopg2.OperationalError: connection to server at "10.244.155.96", port 5432 failed: Connection timed out
	Is the server running on that host and accepting TCP/IP connections?

unit-postgresql-test-app-0: 02:31:13 ERROR unit.postgresql-test-app/0.juju-log Uncaught exception while in charm code:
Traceback (most recent call last):
  File "/var/lib/juju/agents/unit-postgresql-test-app-0/charm/src/charm.py", line 560, in <module>
    main(ApplicationCharm)
  File "/var/lib/juju/agents/unit-postgresql-test-app-0/charm/venv/lib/python3.10/site-packages/ops/__init__.py", line 343, in __call__
    return _main.main(charm_class=charm_class, use_juju_for_storage=use_juju_for_storage)
  File "/var/lib/juju/agents/unit-postgresql-test-app-0/charm/venv/lib/python3.10/site-packages/ops/_main.py", line 558, in main
    manager.run()
  File "/var/lib/juju/agents/unit-postgresql-test-app-0/charm/venv/lib/python3.10/site-packages/ops/_main.py", line 543, in run
    self._emit()
  File "/var/lib/juju/agents/unit-postgresql-test-app-0/charm/venv/lib/python3.10/site-packages/ops/_main.py", line 502, in _emit
    self._emit_charm_event(self.dispatcher.event_name)
  File "/var/lib/juju/agents/unit-postgresql-test-app-0/charm/venv/lib/python3.10/site-packages/ops/_main.py", line 530, in _emit_charm_event
    event_to_emit.emit(*args, **kwargs)
  File "/var/lib/juju/agents/unit-postgresql-test-app-0/charm/venv/lib/python3.10/site-packages/ops/framework.py", line 347, in emit
    framework._emit(event)
  File "/var/lib/juju/agents/unit-postgresql-test-app-0/charm/venv/lib/python3.10/site-packages/ops/framework.py", line 906, in _emit
    self._reemit(event_path)
  File "/var/lib/juju/agents/unit-postgresql-test-app-0/charm/venv/lib/python3.10/site-packages/ops/framework.py", line 996, in _reemit
    custom_handler(event)
  File "/var/lib/juju/agents/unit-postgresql-test-app-0/charm/src/charm.py", line 327, in _on_clear_continuous_writes_action
    connection.close()
UnboundLocalError: local variable 'connection' referenced before assignment
unit-postgresql-test-app-0: 02:31:18 ERROR unit.postgresql-test-app/0.juju-log Unable to drop table
Traceback (most recent call last):
  File "/var/lib/juju/agents/unit-postgresql-test-app-0/charm/src/charm.py", line 318, in _on_clear_continuous_writes_action
    psycopg2.connect(self._connection_string) as connection,
  File "/var/lib/juju/agents/unit-postgresql-test-app-0/charm/venv/lib/python3.10/site-packages/psycopg2/__init__.py", line 122, in connect
    conn = _connect(dsn, connection_factory=connection_factory, **kwasync)
psycopg2.OperationalError: connection to server at "10.244.155.96", port 5432 failed: Connection timed out
	Is the server running on that host and accepting TCP/IP connections?

unit-postgresql-test-app-0: 02:31:18 ERROR unit.postgresql-test-app/0.juju-log Uncaught exception while in charm code:
Traceback (most recent call last):
  File "/var/lib/juju/agents/unit-postgresql-test-app-0/charm/src/charm.py", line 560, in <module>
    main(ApplicationCharm)
  File "/var/lib/juju/agents/unit-postgresql-test-app-0/charm/venv/lib/python3.10/site-packages/ops/__init__.py", line 343, in __call__
    return _main.main(charm_class=charm_class, use_juju_for_storage=use_juju_for_storage)
  File "/var/lib/juju/agents/unit-postgresql-test-app-0/charm/venv/lib/python3.10/site-packages/ops/_main.py", line 558, in main
    manager.run()
  File "/var/lib/juju/agents/unit-postgresql-test-app-0/charm/venv/lib/python3.10/site-packages/ops/_main.py", line 543, in run
    self._emit()
  File "/var/lib/juju/agents/unit-postgresql-test-app-0/charm/venv/lib/python3.10/site-packages/ops/_main.py", line 502, in _emit
    self._emit_charm_event(self.dispatcher.event_name)
  File "/var/lib/juju/agents/unit-postgresql-test-app-0/charm/venv/lib/python3.10/site-packages/ops/_main.py", line 530, in _emit_charm_event
    event_to_emit.emit(*args, **kwargs)
  File "/var/lib/juju/agents/unit-postgresql-test-app-0/charm/venv/lib/python3.10/site-packages/ops/framework.py", line 347, in emit
    framework._emit(event)
  File "/var/lib/juju/agents/unit-postgresql-test-app-0/charm/venv/lib/python3.10/site-packages/ops/framework.py", line 906, in _emit
    self._reemit(event_path)
  File "/var/lib/juju/agents/unit-postgresql-test-app-0/charm/venv/lib/python3.10/site-packages/ops/framework.py", line 996, in _reemit
    custom_handler(event)
  File "/var/lib/juju/agents/unit-postgresql-test-app-0/charm/src/charm.py", line 327, in _on_clear_continuous_writes_action
    connection.close()
UnboundLocalError: local variable 'connection' referenced before assignment
unit-postgresql-3: 02:31:21 ERROR unit.postgresql/3.juju-log Failed to list PostgreSQL database users: connection to server at "10.244.155.96", port 5432 failed: timeout expired

unit-postgresql-test-app-0: 02:31:23 ERROR unit.postgresql-test-app/0.juju-log Unable to drop table
Traceback (most recent call last):
  File "/var/lib/juju/agents/unit-postgresql-test-app-0/charm/src/charm.py", line 318, in _on_clear_continuous_writes_action
    psycopg2.connect(self._connection_string) as connection,
  File "/var/lib/juju/agents/unit-postgresql-test-app-0/charm/venv/lib/python3.10/site-packages/psycopg2/__init__.py", line 122, in connect
    conn = _connect(dsn, connection_factory=connection_factory, **kwasync)
psycopg2.OperationalError: connection to server at "10.244.155.96", port 5432 failed: Connection timed out
	Is the server running on that host and accepting TCP/IP connections?

unit-postgresql-test-app-0: 02:31:23 ERROR unit.postgresql-test-app/0.juju-log Uncaught exception while in charm code:
Traceback (most recent call last):
  File "/var/lib/juju/agents/unit-postgresql-test-app-0/charm/src/charm.py", line 560, in <module>
    main(ApplicationCharm)
  File "/var/lib/juju/agents/unit-postgresql-test-app-0/charm/venv/lib/python3.10/site-packages/ops/__init__.py", line 343, in __call__
    return _main.main(charm_class=charm_class, use_juju_for_storage=use_juju_for_storage)
  File "/var/lib/juju/agents/unit-postgresql-test-app-0/charm/venv/lib/python3.10/site-packages/ops/_main.py", line 558, in main
    manager.run()
  File "/var/lib/juju/agents/unit-postgresql-test-app-0/charm/venv/lib/python3.10/site-packages/ops/_main.py", line 543, in run
    self._emit()
  File "/var/lib/juju/agents/unit-postgresql-test-app-0/charm/venv/lib/python3.10/site-packages/ops/_main.py", line 502, in _emit
    self._emit_charm_event(self.dispatcher.event_name)
  File "/var/lib/juju/agents/unit-postgresql-test-app-0/charm/venv/lib/python3.10/site-packages/ops/_main.py", line 530, in _emit_charm_event
    event_to_emit.emit(*args, **kwargs)
  File "/var/lib/juju/agents/unit-postgresql-test-app-0/charm/venv/lib/python3.10/site-packages/ops/framework.py", line 347, in emit
    framework._emit(event)
  File "/var/lib/juju/agents/unit-postgresql-test-app-0/charm/venv/lib/python3.10/site-packages/ops/framework.py", line 906, in _emit
    self._reemit(event_path)
  File "/var/lib/juju/agents/unit-postgresql-test-app-0/charm/venv/lib/python3.10/site-packages/ops/framework.py", line 996, in _reemit
    custom_handler(event)
  File "/var/lib/juju/agents/unit-postgresql-test-app-0/charm/src/charm.py", line 327, in _on_clear_continuous_writes_action
    connection.close()
UnboundLocalError: local variable 'connection' referenced before assignment
unit-postgresql-test-app-0: 02:31:28 ERROR unit.postgresql-test-app/0.juju-log Unable to drop table
Traceback (most recent call last):
  File "/var/lib/juju/agents/unit-postgresql-test-app-0/charm/src/charm.py", line 318, in _on_clear_continuous_writes_action
    psycopg2.connect(self._connection_string) as connection,
  File "/var/lib/juju/agents/unit-postgresql-test-app-0/charm/venv/lib/python3.10/site-packages/psycopg2/__init__.py", line 122, in connect
    conn = _connect(dsn, connection_factory=connection_factory, **kwasync)
psycopg2.OperationalError: connection to server at "10.244.155.96", port 5432 failed: Connection timed out
	Is the server running on that host and accepting TCP/IP connections?

unit-postgresql-test-app-0: 02:31:28 ERROR unit.postgresql-test-app/0.juju-log Uncaught exception while in charm code:
Traceback (most recent call last):
  File "/var/lib/juju/agents/unit-postgresql-test-app-0/charm/src/charm.py", line 560, in <module>
    main(ApplicationCharm)
  File "/var/lib/juju/agents/unit-postgresql-test-app-0/charm/venv/lib/python3.10/site-packages/ops/__init__.py", line 343, in __call__
    return _main.main(charm_class=charm_class, use_juju_for_storage=use_juju_for_storage)
  File "/var/lib/juju/agents/unit-postgresql-test-app-0/charm/venv/lib/python3.10/site-packages/ops/_main.py", line 558, in main
    manager.run()
  File "/var/lib/juju/agents/unit-postgresql-test-app-0/charm/venv/lib/python3.10/site-packages/ops/_main.py", line 543, in run
    self._emit()
  File "/var/lib/juju/agents/unit-postgresql-test-app-0/charm/venv/lib/python3.10/site-packages/ops/_main.py", line 502, in _emit
    self._emit_charm_event(self.dispatcher.event_name)
  File "/var/lib/juju/agents/unit-postgresql-test-app-0/charm/venv/lib/python3.10/site-packages/ops/_main.py", line 530, in _emit_charm_event
    event_to_emit.emit(*args, **kwargs)
  File "/var/lib/juju/agents/unit-postgresql-test-app-0/charm/venv/lib/python3.10/site-packages/ops/framework.py", line 347, in emit
    framework._emit(event)
  File "/var/lib/juju/agents/unit-postgresql-test-app-0/charm/venv/lib/python3.10/site-packages/ops/framework.py", line 906, in _emit
    self._reemit(event_path)
  File "/var/lib/juju/agents/unit-postgresql-test-app-0/charm/venv/lib/python3.10/site-packages/ops/framework.py", line 996, in _reemit
    custom_handler(event)
  File "/var/lib/juju/agents/unit-postgresql-test-app-0/charm/src/charm.py", line 327, in _on_clear_continuous_writes_action
    connection.close()
UnboundLocalError: local variable 'connection' referenced before assignment
unit-postgresql-3: 02:31:31 ERROR unit.postgresql/3.juju-log Failed to list PostgreSQL database users: connection to server at "10.244.155.96", port 5432 failed: timeout expired

unit-postgresql-test-app-0: 02:31:33 ERROR unit.postgresql-test-app/0.juju-log Unable to drop table
Traceback (most recent call last):
  File "/var/lib/juju/agents/unit-postgresql-test-app-0/charm/src/charm.py", line 318, in _on_clear_continuous_writes_action
    psycopg2.connect(self._connection_string) as connection,
  File "/var/lib/juju/agents/unit-postgresql-test-app-0/charm/venv/lib/python3.10/site-packages/psycopg2/__init__.py", line 122, in connect
    conn = _connect(dsn, connection_factory=connection_factory, **kwasync)
psycopg2.OperationalError: connection to server at "10.244.155.96", port 5432 failed: Connection timed out
	Is the server running on that host and accepting TCP/IP connections?

unit-postgresql-test-app-0: 02:31:33 ERROR unit.postgresql-test-app/0.juju-log Uncaught exception while in charm code:
Traceback (most recent call last):
  File "/var/lib/juju/agents/unit-postgresql-test-app-0/charm/src/charm.py", line 560, in <module>
    main(ApplicationCharm)
  File "/var/lib/juju/agents/unit-postgresql-test-app-0/charm/venv/lib/python3.10/site-packages/ops/__init__.py", line 343, in __call__
    return _main.main(charm_class=charm_class, use_juju_for_storage=use_juju_for_storage)
  File "/var/lib/juju/agents/unit-postgresql-test-app-0/charm/venv/lib/python3.10/site-packages/ops/_main.py", line 558, in main
    manager.run()
  File "/var/lib/juju/agents/unit-postgresql-test-app-0/charm/venv/lib/python3.10/site-packages/ops/_main.py", line 543, in run
    self._emit()
  File "/var/lib/juju/agents/unit-postgresql-test-app-0/charm/venv/lib/python3.10/site-packages/ops/_main.py", line 502, in _emit
    self._emit_charm_event(self.dispatcher.event_name)
  File "/var/lib/juju/agents/unit-postgresql-test-app-0/charm/venv/lib/python3.10/site-packages/ops/_main.py", line 530, in _emit_charm_event
    event_to_emit.emit(*args, **kwargs)
  File "/var/lib/juju/agents/unit-postgresql-test-app-0/charm/venv/lib/python3.10/site-packages/ops/framework.py", line 347, in emit
    framework._emit(event)
  File "/var/lib/juju/agents/unit-postgresql-test-app-0/charm/venv/lib/python3.10/site-packages/ops/framework.py", line 906, in _emit
    self._reemit(event_path)
  File "/var/lib/juju/agents/unit-postgresql-test-app-0/charm/venv/lib/python3.10/site-packages/ops/framework.py", line 996, in _reemit
    custom_handler(event)
  File "/var/lib/juju/agents/unit-postgresql-test-app-0/charm/src/charm.py", line 327, in _on_clear_continuous_writes_action
    connection.close()
UnboundLocalError: local variable 'connection' referenced before assignment
unit-postgresql-test-app-0: 02:31:38 ERROR unit.postgresql-test-app/0.juju-log Unable to drop table
Traceback (most recent call last):
  File "/var/lib/juju/agents/unit-postgresql-test-app-0/charm/src/charm.py", line 318, in _on_clear_continuous_writes_action
    psycopg2.connect(self._connection_string) as connection,
  File "/var/lib/juju/agents/unit-postgresql-test-app-0/charm/venv/lib/python3.10/site-packages/psycopg2/__init__.py", line 122, in connect
    conn = _connect(dsn, connection_factory=connection_factory, **kwasync)
psycopg2.OperationalError: connection to server at "10.244.155.96", port 5432 failed: Connection timed out
	Is the server running on that host and accepting TCP/IP connections?

unit-postgresql-test-app-0: 02:31:38 ERROR unit.postgresql-test-app/0.juju-log Uncaught exception while in charm code:
Traceback (most recent call last):
  File "/var/lib/juju/agents/unit-postgresql-test-app-0/charm/src/charm.py", line 560, in <module>
    main(ApplicationCharm)
  File "/var/lib/juju/agents/unit-postgresql-test-app-0/charm/venv/lib/python3.10/site-packages/ops/__init__.py", line 343, in __call__
    return _main.main(charm_class=charm_class, use_juju_for_storage=use_juju_for_storage)
  File "/var/lib/juju/agents/unit-postgresql-test-app-0/charm/venv/lib/python3.10/site-packages/ops/_main.py", line 558, in main
    manager.run()
  File "/var/lib/juju/agents/unit-postgresql-test-app-0/charm/venv/lib/python3.10/site-packages/ops/_main.py", line 543, in run
    self._emit()
  File "/var/lib/juju/agents/unit-postgresql-test-app-0/charm/venv/lib/python3.10/site-packages/ops/_main.py", line 502, in _emit
    self._emit_charm_event(self.dispatcher.event_name)
  File "/var/lib/juju/agents/unit-postgresql-test-app-0/charm/venv/lib/python3.10/site-packages/ops/_main.py", line 530, in _emit_charm_event
    event_to_emit.emit(*args, **kwargs)
  File "/var/lib/juju/agents/unit-postgresql-test-app-0/charm/venv/lib/python3.10/site-packages/ops/framework.py", line 347, in emit
    framework._emit(event)
  File "/var/lib/juju/agents/unit-postgresql-test-app-0/charm/venv/lib/python3.10/site-packages/ops/framework.py", line 906, in _emit
    self._reemit(event_path)
  File "/var/lib/juju/agents/unit-postgresql-test-app-0/charm/venv/lib/python3.10/site-packages/ops/framework.py", line 996, in _reemit
    custom_handler(event)
  File "/var/lib/juju/agents/unit-postgresql-test-app-0/charm/src/charm.py", line 327, in _on_clear_continuous_writes_action
    connection.close()
UnboundLocalError: local variable 'connection' referenced before assignment
unit-postgresql-3: 02:31:40 ERROR unit.postgresql/3.juju-log Failed to list PostgreSQL database users: connection to server at "10.244.155.96", port 5432 failed: timeout expired

unit-postgresql-test-app-0: 02:31:43 ERROR unit.postgresql-test-app/0.juju-log Unable to drop table
Traceback (most recent call last):
  File "/var/lib/juju/agents/unit-postgresql-test-app-0/charm/src/charm.py", line 318, in _on_clear_continuous_writes_action
    psycopg2.connect(self._connection_string) as connection,
  File "/var/lib/juju/agents/unit-postgresql-test-app-0/charm/venv/lib/python3.10/site-packages/psycopg2/__init__.py", line 122, in connect
    conn = _connect(dsn, connection_factory=connection_factory, **kwasync)
psycopg2.OperationalError: connection to server at "10.244.155.96", port 5432 failed: Connection timed out
	Is the server running on that host and accepting TCP/IP connections?

unit-postgresql-test-app-0: 02:31:43 ERROR unit.postgresql-test-app/0.juju-log Uncaught exception while in charm code:
Traceback (most recent call last):
  File "/var/lib/juju/agents/unit-postgresql-test-app-0/charm/src/charm.py", line 560, in <module>
    main(ApplicationCharm)
  File "/var/lib/juju/agents/unit-postgresql-test-app-0/charm/venv/lib/python3.10/site-packages/ops/__init__.py", line 343, in __call__
    return _main.main(charm_class=charm_class, use_juju_for_storage=use_juju_for_storage)
  File "/var/lib/juju/agents/unit-postgresql-test-app-0/charm/venv/lib/python3.10/site-packages/ops/_main.py", line 558, in main
    manager.run()
  File "/var/lib/juju/agents/unit-postgresql-test-app-0/charm/venv/lib/python3.10/site-packages/ops/_main.py", line 543, in run
    self._emit()
  File "/var/lib/juju/agents/unit-postgresql-test-app-0/charm/venv/lib/python3.10/site-packages/ops/_main.py", line 502, in _emit
    self._emit_charm_event(self.dispatcher.event_name)
  File "/var/lib/juju/agents/unit-postgresql-test-app-0/charm/venv/lib/python3.10/site-packages/ops/_main.py", line 530, in _emit_charm_event
    event_to_emit.emit(*args, **kwargs)
  File "/var/lib/juju/agents/unit-postgresql-test-app-0/charm/venv/lib/python3.10/site-packages/ops/framework.py", line 347, in emit
    framework._emit(event)
  File "/var/lib/juju/agents/unit-postgresql-test-app-0/charm/venv/lib/python3.10/site-packages/ops/framework.py", line 906, in _emit
    self._reemit(event_path)
  File "/var/lib/juju/agents/unit-postgresql-test-app-0/charm/venv/lib/python3.10/site-packages/ops/framework.py", line 996, in _reemit
    custom_handler(event)
  File "/var/lib/juju/agents/unit-postgresql-test-app-0/charm/src/charm.py", line 327, in _on_clear_continuous_writes_action
    connection.close()
UnboundLocalError: local variable 'connection' referenced before assignment
unit-postgresql-test-app-0: 02:31:48 ERROR unit.postgresql-test-app/0.juju-log Unable to drop table
Traceback (most recent call last):
  File "/var/lib/juju/agents/unit-postgresql-test-app-0/charm/src/charm.py", line 318, in _on_clear_continuous_writes_action
    psycopg2.connect(self._connection_string) as connection,
  File "/var/lib/juju/agents/unit-postgresql-test-app-0/charm/venv/lib/python3.10/site-packages/psycopg2/__init__.py", line 122, in connect
    conn = _connect(dsn, connection_factory=connection_factory, **kwasync)
psycopg2.OperationalError: connection to server at "10.244.155.96", port 5432 failed: Connection timed out
	Is the server running on that host and accepting TCP/IP connections?

unit-postgresql-test-app-0: 02:31:48 ERROR unit.postgresql-test-app/0.juju-log Uncaught exception while in charm code:
Traceback (most recent call last):
  File "/var/lib/juju/agents/unit-postgresql-test-app-0/charm/src/charm.py", line 560, in <module>
    main(ApplicationCharm)
  File "/var/lib/juju/agents/unit-postgresql-test-app-0/charm/venv/lib/python3.10/site-packages/ops/__init__.py", line 343, in __call__
    return _main.main(charm_class=charm_class, use_juju_for_storage=use_juju_for_storage)
  File "/var/lib/juju/agents/unit-postgresql-test-app-0/charm/venv/lib/python3.10/site-packages/ops/_main.py", line 558, in main
    manager.run()
  File "/var/lib/juju/agents/unit-postgresql-test-app-0/charm/venv/lib/python3.10/site-packages/ops/_main.py", line 543, in run
    self._emit()
  File "/var/lib/juju/agents/unit-postgresql-test-app-0/charm/venv/lib/python3.10/site-packages/ops/_main.py", line 502, in _emit
    self._emit_charm_event(self.dispatcher.event_name)
  File "/var/lib/juju/agents/unit-postgresql-test-app-0/charm/venv/lib/python3.10/site-packages/ops/_main.py", line 530, in _emit_charm_event
    event_to_emit.emit(*args, **kwargs)
  File "/var/lib/juju/agents/unit-postgresql-test-app-0/charm/venv/lib/python3.10/site-packages/ops/framework.py", line 347, in emit
    framework._emit(event)
  File "/var/lib/juju/agents/unit-postgresql-test-app-0/charm/venv/lib/python3.10/site-packages/ops/framework.py", line 906, in _emit
    self._reemit(event_path)
  File "/var/lib/juju/agents/unit-postgresql-test-app-0/charm/venv/lib/python3.10/site-packages/ops/framework.py", line 996, in _reemit
    custom_handler(event)
  File "/var/lib/juju/agents/unit-postgresql-test-app-0/charm/src/charm.py", line 327, in _on_clear_continuous_writes_action
    connection.close()
UnboundLocalError: local variable 'connection' referenced before assignment
unit-postgresql-3: 02:31:50 ERROR unit.postgresql/3.juju-log Failed to list PostgreSQL database users: connection to server at "10.244.155.96", port 5432 failed: timeout expired

unit-postgresql-test-app-0: 02:31:53 ERROR unit.postgresql-test-app/0.juju-log Unable to drop table
Traceback (most recent call last):
  File "/var/lib/juju/agents/unit-postgresql-test-app-0/charm/src/charm.py", line 318, in _on_clear_continuous_writes_action
    psycopg2.connect(self._connection_string) as connection,
  File "/var/lib/juju/agents/unit-postgresql-test-app-0/charm/venv/lib/python3.10/site-packages/psycopg2/__init__.py", line 122, in connect
    conn = _connect(dsn, connection_factory=connection_factory, **kwasync)
psycopg2.OperationalError: connection to server at "10.244.155.96", port 5432 failed: Connection timed out
	Is the server running on that host and accepting TCP/IP connections?

unit-postgresql-test-app-0: 02:31:53 ERROR unit.postgresql-test-app/0.juju-log Uncaught exception while in charm code:
Traceback (most recent call last):
  File "/var/lib/juju/agents/unit-postgresql-test-app-0/charm/src/charm.py", line 560, in <module>
    main(ApplicationCharm)
  File "/var/lib/juju/agents/unit-postgresql-test-app-0/charm/venv/lib/python3.10/site-packages/ops/__init__.py", line 343, in __call__
    return _main.main(charm_class=charm_class, use_juju_for_storage=use_juju_for_storage)
  File "/var/lib/juju/agents/unit-postgresql-test-app-0/charm/venv/lib/python3.10/site-packages/ops/_main.py", line 558, in main
    manager.run()
  File "/var/lib/juju/agents/unit-postgresql-test-app-0/charm/venv/lib/python3.10/site-packages/ops/_main.py", line 543, in run
    self._emit()
  File "/var/lib/juju/agents/unit-postgresql-test-app-0/charm/venv/lib/python3.10/site-packages/ops/_main.py", line 502, in _emit
    self._emit_charm_event(self.dispatcher.event_name)
  File "/var/lib/juju/agents/unit-postgresql-test-app-0/charm/venv/lib/python3.10/site-packages/ops/_main.py", line 530, in _emit_charm_event
    event_to_emit.emit(*args, **kwargs)
  File "/var/lib/juju/agents/unit-postgresql-test-app-0/charm/venv/lib/python3.10/site-packages/ops/framework.py", line 347, in emit
    framework._emit(event)
  File "/var/lib/juju/agents/unit-postgresql-test-app-0/charm/venv/lib/python3.10/site-packages/ops/framework.py", line 906, in _emit
    self._reemit(event_path)
  File "/var/lib/juju/agents/unit-postgresql-test-app-0/charm/venv/lib/python3.10/site-packages/ops/framework.py", line 996, in _reemit
    custom_handler(event)
  File "/var/lib/juju/agents/unit-postgresql-test-app-0/charm/src/charm.py", line 327, in _on_clear_continuous_writes_action
    connection.close()
UnboundLocalError: local variable 'connection' referenced before assignment
unit-postgresql-test-app-0: 02:31:58 ERROR unit.postgresql-test-app/0.juju-log Unable to drop table
Traceback (most recent call last):
  File "/var/lib/juju/agents/unit-postgresql-test-app-0/charm/src/charm.py", line 318, in _on_clear_continuous_writes_action
    psycopg2.connect(self._connection_string) as connection,
  File "/var/lib/juju/agents/unit-postgresql-test-app-0/charm/venv/lib/python3.10/site-packages/psycopg2/__init__.py", line 122, in connect
    conn = _connect(dsn, connection_factory=connection_factory, **kwasync)
psycopg2.OperationalError: connection to server at "10.244.155.96", port 5432 failed: Connection timed out
	Is the server running on that host and accepting TCP/IP connections?

unit-postgresql-test-app-0: 02:31:58 ERROR unit.postgresql-test-app/0.juju-log Uncaught exception while in charm code:
Traceback (most recent call last):
  File "/var/lib/juju/agents/unit-postgresql-test-app-0/charm/src/charm.py", line 560, in <module>
    main(ApplicationCharm)
  File "/var/lib/juju/agents/unit-postgresql-test-app-0/charm/venv/lib/python3.10/site-packages/ops/__init__.py", line 343, in __call__
    return _main.main(charm_class=charm_class, use_juju_for_storage=use_juju_for_storage)
  File "/var/lib/juju/agents/unit-postgresql-test-app-0/charm/venv/lib/python3.10/site-packages/ops/_main.py", line 558, in main
    manager.run()
  File "/var/lib/juju/agents/unit-postgresql-test-app-0/charm/venv/lib/python3.10/site-packages/ops/_main.py", line 543, in run
    self._emit()
  File "/var/lib/juju/agents/unit-postgresql-test-app-0/charm/venv/lib/python3.10/site-packages/ops/_main.py", line 502, in _emit
    self._emit_charm_event(self.dispatcher.event_name)
  File "/var/lib/juju/agents/unit-postgresql-test-app-0/charm/venv/lib/python3.10/site-packages/ops/_main.py", line 530, in _emit_charm_event
    event_to_emit.emit(*args, **kwargs)
  File "/var/lib/juju/agents/unit-postgresql-test-app-0/charm/venv/lib/python3.10/site-packages/ops/framework.py", line 347, in emit
    framework._emit(event)
  File "/var/lib/juju/agents/unit-postgresql-test-app-0/charm/venv/lib/python3.10/site-packages/ops/framework.py", line 906, in _emit
    self._reemit(event_path)
  File "/var/lib/juju/agents/unit-postgresql-test-app-0/charm/venv/lib/python3.10/site-packages/ops/framework.py", line 996, in _reemit
    custom_handler(event)
  File "/var/lib/juju/agents/unit-postgresql-test-app-0/charm/src/charm.py", line 327, in _on_clear_continuous_writes_action
    connection.close()
UnboundLocalError: local variable 'connection' referenced before assignment
unit-postgresql-3: 02:32:01 ERROR unit.postgresql/3.juju-log Failed to list PostgreSQL database users: connection to server at "10.244.155.96", port 5432 failed: timeout expired

unit-postgresql-test-app-0: 02:32:03 ERROR unit.postgresql-test-app/0.juju-log Unable to drop table
Traceback (most recent call last):
  File "/var/lib/juju/agents/unit-postgresql-test-app-0/charm/src/charm.py", line 318, in _on_clear_continuous_writes_action
    psycopg2.connect(self._connection_string) as connection,
  File "/var/lib/juju/agents/unit-postgresql-test-app-0/charm/venv/lib/python3.10/site-packages/psycopg2/__init__.py", line 122, in connect
    conn = _connect(dsn, connection_factory=connection_factory, **kwasync)
psycopg2.OperationalError: connection to server at "10.244.155.96", port 5432 failed: Connection timed out
	Is the server running on that host and accepting TCP/IP connections?

unit-postgresql-test-app-0: 02:32:03 ERROR unit.postgresql-test-app/0.juju-log Uncaught exception while in charm code:
Traceback (most recent call last):
  File "/var/lib/juju/agents/unit-postgresql-test-app-0/charm/src/charm.py", line 560, in <module>
    main(ApplicationCharm)
  File "/var/lib/juju/agents/unit-postgresql-test-app-0/charm/venv/lib/python3.10/site-packages/ops/__init__.py", line 343, in __call__
    return _main.main(charm_class=charm_class, use_juju_for_storage=use_juju_for_storage)
  File "/var/lib/juju/agents/unit-postgresql-test-app-0/charm/venv/lib/python3.10/site-packages/ops/_main.py", line 558, in main
    manager.run()
  File "/var/lib/juju/agents/unit-postgresql-test-app-0/charm/venv/lib/python3.10/site-packages/ops/_main.py", line 543, in run
    self._emit()
  File "/var/lib/juju/agents/unit-postgresql-test-app-0/charm/venv/lib/python3.10/site-packages/ops/_main.py", line 502, in _emit
    self._emit_charm_event(self.dispatcher.event_name)
  File "/var/lib/juju/agents/unit-postgresql-test-app-0/charm/venv/lib/python3.10/site-packages/ops/_main.py", line 530, in _emit_charm_event
    event_to_emit.emit(*args, **kwargs)
  File "/var/lib/juju/agents/unit-postgresql-test-app-0/charm/venv/lib/python3.10/site-packages/ops/framework.py", line 347, in emit
    framework._emit(event)
  File "/var/lib/juju/agents/unit-postgresql-test-app-0/charm/venv/lib/python3.10/site-packages/ops/framework.py", line 906, in _emit
    self._reemit(event_path)
  File "/var/lib/juju/agents/unit-postgresql-test-app-0/charm/venv/lib/python3.10/site-packages/ops/framework.py", line 996, in _reemit
    custom_handler(event)
  File "/var/lib/juju/agents/unit-postgresql-test-app-0/charm/src/charm.py", line 327, in _on_clear_continuous_writes_action
    connection.close()
UnboundLocalError: local variable 'connection' referenced before assignment
unit-postgresql-test-app-0: 02:32:08 ERROR unit.postgresql-test-app/0.juju-log Unable to drop table
Traceback (most recent call last):
  File "/var/lib/juju/agents/unit-postgresql-test-app-0/charm/src/charm.py", line 318, in _on_clear_continuous_writes_action
    psycopg2.connect(self._connection_string) as connection,
  File "/var/lib/juju/agents/unit-postgresql-test-app-0/charm/venv/lib/python3.10/site-packages/psycopg2/__init__.py", line 122, in connect
    conn = _connect(dsn, connection_factory=connection_factory, **kwasync)
psycopg2.OperationalError: connection to server at "10.244.155.96", port 5432 failed: Connection timed out
	Is the server running on that host and accepting TCP/IP connections?

unit-postgresql-test-app-0: 02:32:08 ERROR unit.postgresql-test-app/0.juju-log Uncaught exception while in charm code:
Traceback (most recent call last):
  File "/var/lib/juju/agents/unit-postgresql-test-app-0/charm/src/charm.py", line 560, in <module>
    main(ApplicationCharm)
  File "/var/lib/juju/agents/unit-postgresql-test-app-0/charm/venv/lib/python3.10/site-packages/ops/__init__.py", line 343, in __call__
    return _main.main(charm_class=charm_class, use_juju_for_storage=use_juju_for_storage)
  File "/var/lib/juju/agents/unit-postgresql-test-app-0/charm/venv/lib/python3.10/site-packages/ops/_main.py", line 558, in main
    manager.run()
  File "/var/lib/juju/agents/unit-postgresql-test-app-0/charm/venv/lib/python3.10/site-packages/ops/_main.py", line 543, in run
    self._emit()
  File "/var/lib/juju/agents/unit-postgresql-test-app-0/charm/venv/lib/python3.10/site-packages/ops/_main.py", line 502, in _emit
    self._emit_charm_event(self.dispatcher.event_name)
  File "/var/lib/juju/agents/unit-postgresql-test-app-0/charm/venv/lib/python3.10/site-packages/ops/_main.py", line 530, in _emit_charm_event
    event_to_emit.emit(*args, **kwargs)
  File "/var/lib/juju/agents/unit-postgresql-test-app-0/charm/venv/lib/python3.10/site-packages/ops/framework.py", line 347, in emit
    framework._emit(event)
  File "/var/lib/juju/agents/unit-postgresql-test-app-0/charm/venv/lib/python3.10/site-packages/ops/framework.py", line 906, in _emit
    self._reemit(event_path)
  File "/var/lib/juju/agents/unit-postgresql-test-app-0/charm/venv/lib/python3.10/site-packages/ops/framework.py", line 996, in _reemit
    custom_handler(event)
  File "/var/lib/juju/agents/unit-postgresql-test-app-0/charm/src/charm.py", line 327, in _on_clear_continuous_writes_action
    connection.close()
UnboundLocalError: local variable 'connection' referenced before assignment
unit-postgresql-3: 02:32:09 ERROR unit.postgresql/3.juju-log Failed to list PostgreSQL database users: connection to server at "10.244.155.96", port 5432 failed: timeout expired

unit-postgresql-3: 02:32:18 ERROR unit.postgresql/3.juju-log Failed to list PostgreSQL database users: connection to server at "10.244.155.96", port 5432 failed: timeout expired


[32mINFO    [0m pytest_operator.plugin:plugin.py:1017 Forgetting model main...