[33mWARNING [0m juju.client.connection:connection.py:858 unexpected facade SSHServer received from the controller
[32mINFO    [0m pytest_operator.plugin:plugin.py:795 Connecting to existing model concierge-lxd:testing on unspecified cloud
[33mWARNING [0m juju.client.connection:connection.py:858 unexpected facade SSHServer received from the controller
[33mWARNING [0m juju.client.connection:connection.py:858 unexpected facade SSHSession received from the controller
[33mWARNING [0m juju.client.connection:connection.py:858 unexpected facade SSHTunneler received from the controller
[33mWARNING [0m juju.client.connection:connection.py:858 unexpected facade SSHServer received from the controller
[32mINFO    [0m integration.test_backups_pitr_aws:test_backups_pitr_aws.py:57 deploying the next charms: s3-integrator, self-signed-certificates, postgresql
[32mINFO    [0m juju.model:__init__.py:2301 Deploying ch:amd64/jammy/s3-integrator-145
[32mINFO    [0m juju.model:__init__.py:2301 Deploying ch:amd64/jammy/self-signed-certificates-264
[32mINFO    [0m juju.model:__init__.py:2301 Deploying local:postgresql-0
[32mINFO    [0m integration.test_backups_pitr_aws:test_backups_pitr_aws.py:68 integrating self-signed-certificates with postgresql and waiting them to stabilize
[33mWARNING [0m juju.model:__init__.py:1683 relate is deprecated and will be removed. Use integrate instead.
[32mINFO    [0m juju.model:__init__.py:3254 Waiting for model:
  postgresql-aws/0 [allocating] waiting: waiting for machine
  postgresql-aws/1 [allocating] waiting: waiting for machine
  self-signed-certificates/0 [allocating] waiting: waiting for machine
[32mINFO    [0m juju.model:__init__.py:3254 Waiting for model:
  postgresql-aws/0 [allocating] waiting: waiting for machine
  postgresql-aws/1 [allocating] waiting: waiting for machine
  self-signed-certificates/0 [allocating] waiting: waiting for machine
[32mINFO    [0m juju.model:__init__.py:3254 Waiting for model:
  postgresql-aws/0 [allocating] waiting: waiting for machine
  postgresql-aws/1 [allocating] waiting: waiting for machine
  self-signed-certificates/0 [allocating] waiting: waiting for machine
[32mINFO    [0m juju.model:__init__.py:3254 Waiting for model:
  postgresql-aws/0 [allocating] waiting: waiting for machine
  postgresql-aws/1 [allocating] waiting: waiting for machine
  self-signed-certificates/0 [allocating] waiting: waiting for machine
[32mINFO    [0m juju.model:__init__.py:3254 Waiting for model:
  postgresql-aws/0 [allocating] waiting: waiting for machine
  postgresql-aws/1 [allocating] waiting: waiting for machine
  self-signed-certificates/0 [allocating] waiting: waiting for machine
[32mINFO    [0m juju.model:__init__.py:3254 Waiting for model:
  postgresql-aws/0 [allocating] waiting: waiting for machine
  postgresql-aws/1 [allocating] waiting: waiting for machine
  self-signed-certificates/0 [allocating] waiting: waiting for machine
[32mINFO    [0m juju.model:__init__.py:3254 Waiting for model:
  postgresql-aws/0 [allocating] waiting: waiting for machine
  postgresql-aws/1 [allocating] waiting: waiting for machine
  self-signed-certificates/0 [allocating] waiting: agent initialising
[32mINFO    [0m juju.model:__init__.py:3254 Waiting for model:
  postgresql-aws/0 [executing] maintenance: installing PostgreSQL
  postgresql-aws/1 [executing] maintenance: installing PostgreSQL
[32mINFO    [0m juju.model:__init__.py:3254 Waiting for model:
  postgresql-aws/0 [executing] waiting: awaiting for member to start
  postgresql-aws/1 [executing] waiting: awaiting for cluster to start
  self-signed-certificates/0 [idle] active: 
[32mINFO    [0m juju.model:__init__.py:3254 Waiting for model:
  postgresql-aws/0 [executing] active: Primary (degraded)
  postgresql-aws/1 [executing] waiting: awaiting for cluster to start
[32mINFO    [0m juju.model:__init__.py:3254 Waiting for model:
  postgresql-aws/0 [executing] active: 
  postgresql-aws/1 [executing] waiting: awaiting for cluster to start
[32mINFO    [0m juju.model:__init__.py:3254 Waiting for model:
  postgresql-aws/0 [executing] maintenance: reconfiguring cluster
  postgresql-aws/1 [idle] waiting: awaiting for cluster to start
[32mINFO    [0m juju.model:__init__.py:3254 Waiting for model:
  postgresql-aws/0 [executing] maintenance: reconfiguring cluster
  postgresql-aws/1 [idle] waiting: awaiting for cluster to start
[32mINFO    [0m juju.model:__init__.py:3254 Waiting for model:
  postgresql-aws/0 [executing] active: Primary (degraded)
  postgresql-aws/1 [idle] waiting: awaiting for cluster to start
[32mINFO    [0m juju.model:__init__.py:3254 Waiting for model:
  postgresql-aws/1 [idle] waiting: awaiting for cluster to start
[32mINFO    [0m juju.model:__init__.py:3254 Waiting for model:
  postgresql-aws/1 [idle] waiting: awaiting for cluster to start
[32mINFO    [0m juju.model:__init__.py:3254 Waiting for model:
  postgresql-aws/1 [idle] waiting: awaiting for cluster to start
[32mINFO    [0m juju.model:__init__.py:3254 Waiting for model:
  postgresql-aws/1 [idle] waiting: awaiting for cluster to start
[32mINFO    [0m juju.model:__init__.py:3254 Waiting for model:
  postgresql-aws/1 [executing] waiting: awaiting for cluster to start
[32mINFO    [0m juju.model:__init__.py:3254 Waiting for model:
  postgresql-aws/0 [idle] active: 
[32mINFO    [0m integration.test_backups_pitr_aws:test_backups_pitr_aws.py:79 configuring s3-integrator for AWS
[32mINFO    [0m integration.test_backups_pitr_aws:test_backups_pitr_aws.py:87 integrating s3-integrator with postgresql and waiting model to stabilize
[33mWARNING [0m juju.model:__init__.py:1683 relate is deprecated and will be removed. Use integrate instead.
[32mINFO    [0m juju.model:__init__.py:3254 Waiting for model:
  s3-integrator/0 [executing] active: 
  self-signed-certificates/0 [idle] active: 
  postgresql-aws/0 [executing] active: 
  postgresql-aws/1 [executing] active: 
[32mINFO    [0m juju.model:__init__.py:3254 Waiting for model:
  postgresql-aws/0 [executing] maintenance: initialising stanza
  postgresql-aws/1 [idle] active: 
[32mINFO    [0m juju.model:__init__.py:3254 Waiting for model:
  postgresql-aws/0 [executing] maintenance: initialising stanza
  postgresql-aws/1 [executing] active: 
[32mINFO    [0m juju.model:__init__.py:3254 Waiting for model:
  postgresql-aws/0 [executing] active: Primary
[32mINFO    [0m juju.model:__init__.py:3254 Waiting for model:
  postgresql-aws/0 [idle] active: Primary
[32mINFO    [0m integration.test_backups_pitr_aws:test_backups_pitr_aws.py:100 1: creating table
[32mINFO    [0m integration.test_backups_pitr_aws:test_backups_pitr_aws.py:103 1: creating backup b1
[32mINFO    [0m juju.model:__init__.py:3254 Waiting for model:
  s3-integrator/0 [idle] active: 
  self-signed-certificates/0 [idle] active: 
  postgresql-aws/0 [executing] active: Primary
  postgresql-aws/1 [idle] active: 
[32mINFO    [0m juju.model:__init__.py:3254 Waiting for model:
  postgresql-aws/0 [idle] active: Primary
[32mINFO    [0m integration.test_backups_pitr_aws:test_backups_pitr_aws.py:384 listing the available backups
[32mINFO    [0m juju.model:__init__.py:3254 Waiting for model:
  s3-integrator/0 [idle] active: 
  self-signed-certificates/0 [idle] active: 
  postgresql-aws/0 [idle] active: Primary
  postgresql-aws/1 [idle] active: 
[32mINFO    [0m integration.test_backups_pitr_aws:test_backups_pitr_aws.py:111 1: creating test data td1
[32mINFO    [0m integration.test_backups_pitr_aws:test_backups_pitr_aws.py:114 1: get timestamp ts1
[32mINFO    [0m integration.test_backups_pitr_aws:test_backups_pitr_aws.py:124 1: creating test data td2
[32mINFO    [0m integration.test_backups_pitr_aws:test_backups_pitr_aws.py:127 1: switching wal
[32mINFO    [0m integration.test_backups_pitr_aws:test_backups_pitr_aws.py:130 1: scaling down to do restore
[32mINFO    [0m juju.model:__init__.py:3254 Waiting for model:
  s3-integrator/0 [idle] active: 
  self-signed-certificates/0 [executing] active: 
  postgresql-aws/0 [executing] active: Primary
  postgresql-aws/1 [executing] active: 
[32mINFO    [0m juju.model:__init__.py:3254 Waiting for model:
  postgresql-aws/0 [executing] maintenance: reconfiguring cluster
[32mINFO    [0m integration.test_backups_pitr_aws:test_backups_pitr_aws.py:138 1: restoring the backup b1 with bad restore-to-time parameter
[32mINFO    [0m integration.test_backups_pitr_aws:test_backups_pitr_aws.py:147 1: restoring the backup b1 with unreachable restore-to-time parameter
[32mINFO    [0m integration.test_backups_pitr_aws:test_backups_pitr_aws.py:152 1: waiting for the database charm to become blocked after restore
[32mINFO    [0m integration.test_backups_pitr_aws:test_backups_pitr_aws.py:158 1: database charm become in blocked state after restore, as supposed to be with unreachable PITR parameter
[32mINFO    [0m integration.test_backups_pitr_aws:test_backups_pitr_aws.py:166 1: restoring to the timestamp ts1
[32mINFO    [0m juju.model:__init__.py:3254 Waiting for model:
  s3-integrator/0 [idle] active: 
  self-signed-certificates/0 [idle] active: 
  postgresql-aws/0 [executing] maintenance: restoring backup
[32mINFO    [0m juju.model:__init__.py:3254 Waiting for model:
  postgresql-aws/0 [idle] maintenance: reconfiguring cluster
[32mINFO    [0m juju.model:__init__.py:3254 Waiting for model:
  postgresql-aws/0 [idle] maintenance: reconfiguring cluster
[32mINFO    [0m juju.model:__init__.py:3254 Waiting for model:
  postgresql-aws/0 [idle] maintenance: reconfiguring cluster
[32mINFO    [0m juju.model:__init__.py:3254 Waiting for model:
  postgresql-aws/0 [idle] maintenance: reconfiguring cluster
[32mINFO    [0m juju.model:__init__.py:3254 Waiting for model:
  postgresql-aws/0 [idle] maintenance: reconfiguring cluster
[32mINFO    [0m juju.model:__init__.py:3254 Waiting for model:
  postgresql-aws/0 [idle] maintenance: reconfiguring cluster
[32mINFO    [0m juju.model:__init__.py:3254 Waiting for model:
  postgresql-aws/0 [idle] maintenance: reconfiguring cluster
[32mINFO    [0m juju.model:__init__.py:3254 Waiting for model:
  postgresql-aws/0 [idle] maintenance: reconfiguring cluster
[32mINFO    [0m juju.model:__init__.py:3254 Waiting for model:
  postgresql-aws/0 [idle] maintenance: reconfiguring cluster
[32mINFO    [0m juju.model:__init__.py:3254 Waiting for model:
  postgresql-aws/0 [idle] maintenance: reconfiguring cluster
[32mINFO    [0m juju.model:__init__.py:3254 Waiting for model:
  postgresql-aws/0 [executing] active: Primary
[32mINFO    [0m juju.model:__init__.py:3254 Waiting for model:
  postgresql-aws/0 [idle] active: Primary
[32mINFO    [0m integration.test_backups_pitr_aws:test_backups_pitr_aws.py:175 2: successful restore
[32mINFO    [0m integration.test_backups_pitr_aws:test_backups_pitr_aws.py:384 listing the available backups
[32mINFO    [0m juju.model:__init__.py:3254 Waiting for model:
  s3-integrator/0 [idle] active: 
  self-signed-certificates/0 [idle] active: 
  postgresql-aws/0 [idle] active: Primary
[32mINFO    [0m integration.test_backups_pitr_aws:test_backups_pitr_aws.py:181 2: checking test data td1
[32mINFO    [0m integration.test_backups_pitr_aws:test_backups_pitr_aws.py:184 2: checking not test data td2
[32mINFO    [0m integration.test_backups_pitr_aws:test_backups_pitr_aws.py:189 2: creating test data td3
[32mINFO    [0m integration.test_backups_pitr_aws:test_backups_pitr_aws.py:192 2: get timestamp ts2
[32mINFO    [0m integration.test_backups_pitr_aws:test_backups_pitr_aws.py:198 2: creating test data td4
[32mINFO    [0m integration.test_backups_pitr_aws:test_backups_pitr_aws.py:201 2: switching wal
[32mINFO    [0m integration.test_backups_pitr_aws:test_backups_pitr_aws.py:208 2: restoring the backup b1 to the latest
[32mINFO    [0m juju.model:__init__.py:3254 Waiting for model:
  s3-integrator/0 [idle] active: 
  self-signed-certificates/0 [idle] active: 
  postgresql-aws/0 [executing] maintenance: restoring backup
[32mINFO    [0m juju.model:__init__.py:3254 Waiting for model:
  postgresql-aws/0 [idle] maintenance: reconfiguring cluster
[32mINFO    [0m juju.model:__init__.py:3254 Waiting for model:
  postgresql-aws/0 [idle] maintenance: reconfiguring cluster
[32mINFO    [0m juju.model:__init__.py:3254 Waiting for model:
  postgresql-aws/0 [idle] active: 
[32mINFO    [0m integration.test_backups_pitr_aws:test_backups_pitr_aws.py:217 3: successful restore
[32mINFO    [0m integration.test_backups_pitr_aws:test_backups_pitr_aws.py:384 listing the available backups
[32mINFO    [0m juju.model:__init__.py:3254 Waiting for model:
  s3-integrator/0 [idle] active: 
  self-signed-certificates/0 [idle] active: 
  postgresql-aws/0 [idle] active: 
[32mINFO    [0m integration.test_backups_pitr_aws:test_backups_pitr_aws.py:225 3: checking test data td1
[32mINFO    [0m integration.test_backups_pitr_aws:test_backups_pitr_aws.py:228 3: checking test data td2
[32mINFO    [0m integration.test_backups_pitr_aws:test_backups_pitr_aws.py:231 3: checking not test data td3
[32mINFO    [0m integration.test_backups_pitr_aws:test_backups_pitr_aws.py:236 3: checking not test data td4
[32mINFO    [0m integration.test_backups_pitr_aws:test_backups_pitr_aws.py:241 3: switching wal
[32mINFO    [0m integration.test_backups_pitr_aws:test_backups_pitr_aws.py:248 3: restoring the timeline 2 to the latest
[32mINFO    [0m juju.model:__init__.py:3254 Waiting for model:
  s3-integrator/0 [idle] active: 
  self-signed-certificates/0 [idle] active: 
  postgresql-aws/0 [executing] maintenance: reconfiguring cluster
[32mINFO    [0m juju.model:__init__.py:3254 Waiting for model:
  postgresql-aws/0 [idle] maintenance: reconfiguring cluster
[32mINFO    [0m juju.model:__init__.py:3254 Waiting for model:
  postgresql-aws/0 [idle] maintenance: reconfiguring cluster
[32mINFO    [0m juju.model:__init__.py:3254 Waiting for model:
  postgresql-aws/0 [idle] maintenance: reconfiguring cluster
[32mINFO    [0m juju.model:__init__.py:3254 Waiting for model:
  postgresql-aws/0 [executing] active: Primary
[32mINFO    [0m juju.model:__init__.py:3254 Waiting for model:
  postgresql-aws/0 [idle] active: Primary
[32mINFO    [0m integration.test_backups_pitr_aws:test_backups_pitr_aws.py:257 4: successful restore
[32mINFO    [0m integration.test_backups_pitr_aws:test_backups_pitr_aws.py:384 listing the available backups
[32mINFO    [0m juju.model:__init__.py:3254 Waiting for model:
  s3-integrator/0 [idle] active: 
  self-signed-certificates/0 [idle] active: 
  postgresql-aws/0 [idle] active: Primary
[32mINFO    [0m integration.test_backups_pitr_aws:test_backups_pitr_aws.py:265 4: checking test data td1
[32mINFO    [0m integration.test_backups_pitr_aws:test_backups_pitr_aws.py:268 4: checking not test data td2
[32mINFO    [0m integration.test_backups_pitr_aws:test_backups_pitr_aws.py:273 4: checking test data td3
[32mINFO    [0m integration.test_backups_pitr_aws:test_backups_pitr_aws.py:276 4: checking test data td4
[32mINFO    [0m integration.test_backups_pitr_aws:test_backups_pitr_aws.py:279 4: switching wal
[32mINFO    [0m integration.test_backups_pitr_aws:test_backups_pitr_aws.py:286 4: restoring to the timestamp ts2
[32mINFO    [0m juju.model:__init__.py:3254 Waiting for model:
  s3-integrator/0 [idle] active: 
  self-signed-certificates/0 [idle] active: 
  postgresql-aws/0 [executing] maintenance: restoring backup
[32mINFO    [0m juju.model:__init__.py:3254 Waiting for model:
  postgresql-aws/0 [idle] maintenance: reconfiguring cluster
[32mINFO    [0m juju.model:__init__.py:3254 Waiting for model:
  postgresql-aws/0 [idle] maintenance: reconfiguring cluster
[32mINFO    [0m juju.model:__init__.py:3254 Waiting for model:
  postgresql-aws/0 [idle] active: 
[32mINFO    [0m integration.test_backups_pitr_aws:test_backups_pitr_aws.py:295 5: successful restore
[32mINFO    [0m integration.test_backups_pitr_aws:test_backups_pitr_aws.py:384 listing the available backups
[32mINFO    [0m juju.model:__init__.py:3254 Waiting for model:
  s3-integrator/0 [idle] active: 
  self-signed-certificates/0 [idle] active: 
  postgresql-aws/0 [idle] active: 
[32mINFO    [0m integration.test_backups_pitr_aws:test_backups_pitr_aws.py:306 5: checking test data td1
[32mINFO    [0m integration.test_backups_pitr_aws:test_backups_pitr_aws.py:309 5: checking not test data td2
[32mINFO    [0m integration.test_backups_pitr_aws:test_backups_pitr_aws.py:314 5: checking test data td3
[32mINFO    [0m integration.test_backups_pitr_aws:test_backups_pitr_aws.py:317 5: checking not test data td4
[32mINFO    [0m integration.conftest:conftest.py:54 deleting the previously created backups
[32mINFO    [0m pytest_operator.plugin:plugin.py:937 Model status:

Model    Controller     Cloud/Region         Version  SLA          Timestamp
testing  concierge-lxd  localhost/localhost  3.6.5    unsupported  02:12:09Z

App            Version  Status  Scale  Charm          Channel        Rev  Exposed  Message
s3-integrator           active      1  s3-integrator  latest/stable  145  no       

Unit              Workload  Agent  Machine  Public address  Ports  Message
s3-integrator/0*  active    idle   0        10.122.81.184          

Machine  State    Address        Inst id        Base          AZ  Message
0        started  10.122.81.184  juju-4ff4c3-0  ubuntu@22.04      Running
1        stopped  10.122.81.72   juju-4ff4c3-1  ubuntu@22.04      Running

[32mINFO    [0m pytest_operator.plugin:plugin.py:943 Juju error logs:

machine-0: 01:42:50 ERROR juju.worker.dependency "lxd-container-provisioner" manifold worker returned unexpected error: container types not yet available
machine-0: 01:42:50 ERROR juju.worker.dependency "kvm-container-provisioner" manifold worker returned unexpected error: container types not yet available
unit-s3-integrator-0: 01:42:50 ERROR juju.worker.meterstatus error running "meter-status-changed": charm missing from disk
machine-1: 01:44:19 ERROR juju.worker.dependency "lxd-container-provisioner" manifold worker returned unexpected error: container types not yet available
machine-1: 01:44:19 ERROR juju.worker.dependency "kvm-container-provisioner" manifold worker returned unexpected error: container types not yet available
unit-self-signed-certificates-0: 01:44:19 ERROR juju.worker.meterstatus error running "meter-status-changed": charm missing from disk
machine-2: 01:44:33 ERROR juju.worker.dependency "lxd-container-provisioner" manifold worker returned unexpected error: container types not yet available
machine-2: 01:44:33 ERROR juju.worker.dependency "kvm-container-provisioner" manifold worker returned unexpected error: container types not yet available
unit-postgresql-aws-0: 01:44:33 ERROR juju.worker.meterstatus error running "meter-status-changed": charm missing from disk
machine-3: 01:44:37 ERROR juju.worker.dependency "lxd-container-provisioner" manifold worker returned unexpected error: container types not yet available
machine-3: 01:44:37 ERROR juju.worker.dependency "kvm-container-provisioner" manifold worker returned unexpected error: container types not yet available
unit-postgresql-aws-1: 01:44:38 ERROR juju.worker.meterstatus error running "meter-status-changed": charm missing from disk
unit-postgresql-aws-0: 01:45:12 ERROR unit.postgresql-aws/0.juju-log Unable to get the state of the cluster
Traceback (most recent call last):
  File "/var/lib/juju/agents/unit-postgresql-aws-0/charm/venv/lib/python3.10/site-packages/urllib3/connection.py", line 198, in _new_conn
    sock = connection.create_connection(
  File "/var/lib/juju/agents/unit-postgresql-aws-0/charm/venv/lib/python3.10/site-packages/urllib3/util/connection.py", line 85, in create_connection
    raise err
  File "/var/lib/juju/agents/unit-postgresql-aws-0/charm/venv/lib/python3.10/site-packages/urllib3/util/connection.py", line 73, in create_connection
    sock.connect(sa)
ConnectionRefusedError: [Errno 111] Connection refused

The above exception was the direct cause of the following exception:

Traceback (most recent call last):
  File "/var/lib/juju/agents/unit-postgresql-aws-0/charm/venv/lib/python3.10/site-packages/urllib3/connectionpool.py", line 787, in urlopen
    response = self._make_request(
  File "/var/lib/juju/agents/unit-postgresql-aws-0/charm/venv/lib/python3.10/site-packages/urllib3/connectionpool.py", line 493, in _make_request
    conn.request(
  File "/var/lib/juju/agents/unit-postgresql-aws-0/charm/venv/lib/python3.10/site-packages/urllib3/connection.py", line 445, in request
    self.endheaders()
  File "/usr/lib/python3.10/http/client.py", line 1278, in endheaders
    self._send_output(message_body, encode_chunked=encode_chunked)
  File "/usr/lib/python3.10/http/client.py", line 1038, in _send_output
    self.send(msg)
  File "/usr/lib/python3.10/http/client.py", line 976, in send
    self.connect()
  File "/var/lib/juju/agents/unit-postgresql-aws-0/charm/venv/lib/python3.10/site-packages/urllib3/connection.py", line 276, in connect
    self.sock = self._new_conn()
  File "/var/lib/juju/agents/unit-postgresql-aws-0/charm/venv/lib/python3.10/site-packages/urllib3/connection.py", line 213, in _new_conn
    raise NewConnectionError(
urllib3.exceptions.NewConnectionError: <urllib3.connection.HTTPConnection object at 0x7fc0f4811270>: Failed to establish a new connection: [Errno 111] Connection refused

The above exception was the direct cause of the following exception:

Traceback (most recent call last):
  File "/var/lib/juju/agents/unit-postgresql-aws-0/charm/venv/lib/python3.10/site-packages/requests/adapters.py", line 667, in send
    resp = conn.urlopen(
  File "/var/lib/juju/agents/unit-postgresql-aws-0/charm/venv/lib/python3.10/site-packages/urllib3/connectionpool.py", line 841, in urlopen
    retries = retries.increment(
  File "/var/lib/juju/agents/unit-postgresql-aws-0/charm/venv/lib/python3.10/site-packages/urllib3/util/retry.py", line 519, in increment
    raise MaxRetryError(_pool, url, reason) from reason  # type: ignore[arg-type]
urllib3.exceptions.MaxRetryError: HTTPConnectionPool(host='10.122.81.154', port=8008): Max retries exceeded with url: /cluster (Caused by NewConnectionError('<urllib3.connection.HTTPConnection object at 0x7fc0f4811270>: Failed to establish a new connection: [Errno 111] Connection refused'))

During handling of the above exception, another exception occurred:

Traceback (most recent call last):
  File "/var/lib/juju/agents/unit-postgresql-aws-0/charm/src/cluster.py", line 563, in are_replicas_up
    response = requests.get(
  File "/var/lib/juju/agents/unit-postgresql-aws-0/charm/venv/lib/python3.10/site-packages/requests/api.py", line 73, in get
    return request("get", url, params=params, **kwargs)
  File "/var/lib/juju/agents/unit-postgresql-aws-0/charm/venv/lib/python3.10/site-packages/requests/api.py", line 59, in request
    return session.request(method=method, url=url, **kwargs)
  File "/var/lib/juju/agents/unit-postgresql-aws-0/charm/venv/lib/python3.10/site-packages/requests/sessions.py", line 589, in request
    resp = self.send(prep, **send_kwargs)
  File "/var/lib/juju/agents/unit-postgresql-aws-0/charm/venv/lib/python3.10/site-packages/requests/sessions.py", line 703, in send
    r = adapter.send(request, **kwargs)
  File "/var/lib/juju/agents/unit-postgresql-aws-0/charm/venv/lib/python3.10/site-packages/requests/adapters.py", line 700, in send
    raise ConnectionError(e, request=request)
requests.exceptions.ConnectionError: HTTPConnectionPool(host='10.122.81.154', port=8008): Max retries exceeded with url: /cluster (Caused by NewConnectionError('<urllib3.connection.HTTPConnection object at 0x7fc0f4811270>: Failed to establish a new connection: [Errno 111] Connection refused'))
unit-postgresql-aws-0: 01:45:25 ERROR unit.postgresql-aws/0.juju-log Failed to list PostgreSQL database users: could not translate host name "None" to address: Temporary failure in name resolution

unit-postgresql-aws-0: 01:46:02 ERROR unit.postgresql-aws/0.juju-log certificates:4: Unable to get the state of the cluster
Traceback (most recent call last):
  File "/var/lib/juju/agents/unit-postgresql-aws-0/charm/venv/lib/python3.10/site-packages/urllib3/connectionpool.py", line 464, in _make_request
    self._validate_conn(conn)
  File "/var/lib/juju/agents/unit-postgresql-aws-0/charm/venv/lib/python3.10/site-packages/urllib3/connectionpool.py", line 1093, in _validate_conn
    conn.connect()
  File "/var/lib/juju/agents/unit-postgresql-aws-0/charm/venv/lib/python3.10/site-packages/urllib3/connection.py", line 741, in connect
    sock_and_verified = _ssl_wrap_socket_and_match_hostname(
  File "/var/lib/juju/agents/unit-postgresql-aws-0/charm/venv/lib/python3.10/site-packages/urllib3/connection.py", line 920, in _ssl_wrap_socket_and_match_hostname
    ssl_sock = ssl_wrap_socket(
  File "/var/lib/juju/agents/unit-postgresql-aws-0/charm/venv/lib/python3.10/site-packages/urllib3/util/ssl_.py", line 480, in ssl_wrap_socket
    ssl_sock = _ssl_wrap_socket_impl(sock, context, tls_in_tls, server_hostname)
  File "/var/lib/juju/agents/unit-postgresql-aws-0/charm/venv/lib/python3.10/site-packages/urllib3/util/ssl_.py", line 524, in _ssl_wrap_socket_impl
    return ssl_context.wrap_socket(sock, server_hostname=server_hostname)
  File "/usr/lib/python3.10/ssl.py", line 513, in wrap_socket
    return self.sslsocket_class._create(
  File "/usr/lib/python3.10/ssl.py", line 1100, in _create
    self.do_handshake()
  File "/usr/lib/python3.10/ssl.py", line 1371, in do_handshake
    self._sslobj.do_handshake()
ssl.SSLError: [SSL: WRONG_VERSION_NUMBER] wrong version number (_ssl.c:1007)

During handling of the above exception, another exception occurred:

Traceback (most recent call last):
  File "/var/lib/juju/agents/unit-postgresql-aws-0/charm/venv/lib/python3.10/site-packages/urllib3/connectionpool.py", line 787, in urlopen
    response = self._make_request(
  File "/var/lib/juju/agents/unit-postgresql-aws-0/charm/venv/lib/python3.10/site-packages/urllib3/connectionpool.py", line 488, in _make_request
    raise new_e
urllib3.exceptions.SSLError: [SSL: WRONG_VERSION_NUMBER] wrong version number (_ssl.c:1007)

The above exception was the direct cause of the following exception:

Traceback (most recent call last):
  File "/var/lib/juju/agents/unit-postgresql-aws-0/charm/venv/lib/python3.10/site-packages/requests/adapters.py", line 667, in send
    resp = conn.urlopen(
  File "/var/lib/juju/agents/unit-postgresql-aws-0/charm/venv/lib/python3.10/site-packages/urllib3/connectionpool.py", line 841, in urlopen
    retries = retries.increment(
  File "/var/lib/juju/agents/unit-postgresql-aws-0/charm/venv/lib/python3.10/site-packages/urllib3/util/retry.py", line 519, in increment
    raise MaxRetryError(_pool, url, reason) from reason  # type: ignore[arg-type]
urllib3.exceptions.MaxRetryError: HTTPSConnectionPool(host='10.122.81.154', port=8008): Max retries exceeded with url: /cluster (Caused by SSLError(SSLError(1, '[SSL: WRONG_VERSION_NUMBER] wrong version number (_ssl.c:1007)')))

During handling of the above exception, another exception occurred:

Traceback (most recent call last):
  File "/var/lib/juju/agents/unit-postgresql-aws-0/charm/src/cluster.py", line 563, in are_replicas_up
    response = requests.get(
  File "/var/lib/juju/agents/unit-postgresql-aws-0/charm/venv/lib/python3.10/site-packages/requests/api.py", line 73, in get
    return request("get", url, params=params, **kwargs)
  File "/var/lib/juju/agents/unit-postgresql-aws-0/charm/venv/lib/python3.10/site-packages/requests/api.py", line 59, in request
    return session.request(method=method, url=url, **kwargs)
  File "/var/lib/juju/agents/unit-postgresql-aws-0/charm/venv/lib/python3.10/site-packages/requests/sessions.py", line 589, in request
    resp = self.send(prep, **send_kwargs)
  File "/var/lib/juju/agents/unit-postgresql-aws-0/charm/venv/lib/python3.10/site-packages/requests/sessions.py", line 703, in send
    r = adapter.send(request, **kwargs)
  File "/var/lib/juju/agents/unit-postgresql-aws-0/charm/venv/lib/python3.10/site-packages/requests/adapters.py", line 698, in send
    raise SSLError(e, request=request)
requests.exceptions.SSLError: HTTPSConnectionPool(host='10.122.81.154', port=8008): Max retries exceeded with url: /cluster (Caused by SSLError(SSLError(1, '[SSL: WRONG_VERSION_NUMBER] wrong version number (_ssl.c:1007)')))
unit-postgresql-aws-0: 02:04:13 ERROR juju.worker.dependency "log-sender" manifold worker returned unexpected error: sending log message: websocket: close 1005 (no status): websocket: close sent
unit-postgresql-aws-0: 02:06:25 ERROR unit.postgresql-aws/0.juju-log Unable to get the state of the cluster
Traceback (most recent call last):
  File "/var/lib/juju/agents/unit-postgresql-aws-0/charm/venv/lib/python3.10/site-packages/urllib3/connection.py", line 198, in _new_conn
    sock = connection.create_connection(
  File "/var/lib/juju/agents/unit-postgresql-aws-0/charm/venv/lib/python3.10/site-packages/urllib3/util/connection.py", line 85, in create_connection
    raise err
  File "/var/lib/juju/agents/unit-postgresql-aws-0/charm/venv/lib/python3.10/site-packages/urllib3/util/connection.py", line 73, in create_connection
    sock.connect(sa)
ConnectionRefusedError: [Errno 111] Connection refused

The above exception was the direct cause of the following exception:

Traceback (most recent call last):
  File "/var/lib/juju/agents/unit-postgresql-aws-0/charm/venv/lib/python3.10/site-packages/urllib3/connectionpool.py", line 787, in urlopen
    response = self._make_request(
  File "/var/lib/juju/agents/unit-postgresql-aws-0/charm/venv/lib/python3.10/site-packages/urllib3/connectionpool.py", line 488, in _make_request
    raise new_e
  File "/var/lib/juju/agents/unit-postgresql-aws-0/charm/venv/lib/python3.10/site-packages/urllib3/connectionpool.py", line 464, in _make_request
    self._validate_conn(conn)
  File "/var/lib/juju/agents/unit-postgresql-aws-0/charm/venv/lib/python3.10/site-packages/urllib3/connectionpool.py", line 1093, in _validate_conn
    conn.connect()
  File "/var/lib/juju/agents/unit-postgresql-aws-0/charm/venv/lib/python3.10/site-packages/urllib3/connection.py", line 704, in connect
    self.sock = sock = self._new_conn()
  File "/var/lib/juju/agents/unit-postgresql-aws-0/charm/venv/lib/python3.10/site-packages/urllib3/connection.py", line 213, in _new_conn
    raise NewConnectionError(
urllib3.exceptions.NewConnectionError: <urllib3.connection.HTTPSConnection object at 0x7f09c792e170>: Failed to establish a new connection: [Errno 111] Connection refused

The above exception was the direct cause of the following exception:

Traceback (most recent call last):
  File "/var/lib/juju/agents/unit-postgresql-aws-0/charm/venv/lib/python3.10/site-packages/requests/adapters.py", line 667, in send
    resp = conn.urlopen(
  File "/var/lib/juju/agents/unit-postgresql-aws-0/charm/venv/lib/python3.10/site-packages/urllib3/connectionpool.py", line 841, in urlopen
    retries = retries.increment(
  File "/var/lib/juju/agents/unit-postgresql-aws-0/charm/venv/lib/python3.10/site-packages/urllib3/util/retry.py", line 519, in increment
    raise MaxRetryError(_pool, url, reason) from reason  # type: ignore[arg-type]
urllib3.exceptions.MaxRetryError: HTTPSConnectionPool(host='10.122.81.154', port=8008): Max retries exceeded with url: /cluster (Caused by NewConnectionError('<urllib3.connection.HTTPSConnection object at 0x7f09c792e170>: Failed to establish a new connection: [Errno 111] Connection refused'))

During handling of the above exception, another exception occurred:

Traceback (most recent call last):
  File "/var/lib/juju/agents/unit-postgresql-aws-0/charm/src/cluster.py", line 563, in are_replicas_up
    response = requests.get(
  File "/var/lib/juju/agents/unit-postgresql-aws-0/charm/venv/lib/python3.10/site-packages/requests/api.py", line 73, in get
    return request("get", url, params=params, **kwargs)
  File "/var/lib/juju/agents/unit-postgresql-aws-0/charm/venv/lib/python3.10/site-packages/requests/api.py", line 59, in request
    return session.request(method=method, url=url, **kwargs)
  File "/var/lib/juju/agents/unit-postgresql-aws-0/charm/venv/lib/python3.10/site-packages/requests/sessions.py", line 589, in request
    resp = self.send(prep, **send_kwargs)
  File "/var/lib/juju/agents/unit-postgresql-aws-0/charm/venv/lib/python3.10/site-packages/requests/sessions.py", line 703, in send
    r = adapter.send(request, **kwargs)
  File "/var/lib/juju/agents/unit-postgresql-aws-0/charm/venv/lib/python3.10/site-packages/requests/adapters.py", line 700, in send
    raise ConnectionError(e, request=request)
requests.exceptions.ConnectionError: HTTPSConnectionPool(host='10.122.81.154', port=8008): Max retries exceeded with url: /cluster (Caused by NewConnectionError('<urllib3.connection.HTTPSConnection object at 0x7f09c792e170>: Failed to establish a new connection: [Errno 111] Connection refused'))
unit-s3-integrator-0: 02:07:17 ERROR juju.worker.dependency "log-sender" manifold worker returned unexpected error: sending log message: websocket: close 1005 (no status): websocket: close sent
unit-self-signed-certificates-0: 02:08:33 ERROR juju.worker.dependency "log-sender" manifold worker returned unexpected error: sending log message: websocket: close 1005 (no status): websocket: close sent

[32mINFO    [0m pytest_operator.plugin:plugin.py:1025 Forgetting model main...