[32mINFO    [0m pytest_operator.plugin:plugin.py:951 Model status:

Model    Controller     Cloud/Region         Version  SLA          Timestamp
testing  concierge-lxd  localhost/localhost  3.6.8    unsupported  01:42:11Z

App         Version  Status  Scale  Charm       Channel  Rev  Exposed  Message
postgresql  14.18    active      3  postgresql             0  no       

Unit           Workload     Agent      Machine  Public address  Ports     Message
postgresql/0*  maintenance  executing  0        10.7.178.8      5432/tcp  reconfiguring cluster
postgresql/1   active       executing  1        10.7.178.214    5432/tcp  
postgresql/2   error        idle       2        10.7.178.23               hook failed: "database-peers-relation-changed"

Machine  State    Address       Inst id        Base          AZ  Message
0        started  10.7.178.8    juju-ed5b0e-0  ubuntu@22.04      Running
1        started  10.7.178.214  juju-ed5b0e-1  ubuntu@22.04      Running
2        started  10.7.178.23   juju-ed5b0e-2  ubuntu@22.04      Running

[32mINFO    [0m pytest_operator.plugin:plugin.py:957 Juju error logs:

machine-0: 01:33:47 ERROR juju.worker.dependency "kvm-container-provisioner" manifold worker returned unexpected error: container types not yet available
machine-0: 01:33:47 ERROR juju.worker.dependency "lxd-container-provisioner" manifold worker returned unexpected error: container types not yet available
unit-postgresql-0: 01:33:47 ERROR juju.worker.meterstatus error running "meter-status-changed": charm missing from disk
machine-2: 01:34:50 ERROR juju.worker.dependency "kvm-container-provisioner" manifold worker returned unexpected error: container types not yet available
machine-2: 01:34:50 ERROR juju.worker.dependency "lxd-container-provisioner" manifold worker returned unexpected error: container types not yet available
unit-postgresql-2: 01:34:50 ERROR juju.worker.meterstatus error running "meter-status-changed": charm missing from disk
unit-postgresql-0: 01:34:56 ERROR unit.postgresql/0.juju-log Unable to get the state of the cluster
Traceback (most recent call last):
  File "/var/lib/juju/agents/unit-postgresql-0/charm/venv/lib/python3.10/site-packages/urllib3/connection.py", line 198, in _new_conn
    sock = connection.create_connection(
  File "/var/lib/juju/agents/unit-postgresql-0/charm/venv/lib/python3.10/site-packages/urllib3/util/connection.py", line 85, in create_connection
    raise err
  File "/var/lib/juju/agents/unit-postgresql-0/charm/venv/lib/python3.10/site-packages/urllib3/util/connection.py", line 73, in create_connection
    sock.connect(sa)
ConnectionRefusedError: [Errno 111] Connection refused

The above exception was the direct cause of the following exception:

Traceback (most recent call last):
  File "/var/lib/juju/agents/unit-postgresql-0/charm/venv/lib/python3.10/site-packages/urllib3/connectionpool.py", line 787, in urlopen
    response = self._make_request(
  File "/var/lib/juju/agents/unit-postgresql-0/charm/venv/lib/python3.10/site-packages/urllib3/connectionpool.py", line 493, in _make_request
    conn.request(
  File "/var/lib/juju/agents/unit-postgresql-0/charm/venv/lib/python3.10/site-packages/urllib3/connection.py", line 494, in request
    self.endheaders()
  File "/usr/lib/python3.10/http/client.py", line 1278, in endheaders
    self._send_output(message_body, encode_chunked=encode_chunked)
  File "/usr/lib/python3.10/http/client.py", line 1038, in _send_output
    self.send(msg)
  File "/usr/lib/python3.10/http/client.py", line 976, in send
    self.connect()
  File "/var/lib/juju/agents/unit-postgresql-0/charm/venv/lib/python3.10/site-packages/urllib3/connection.py", line 325, in connect
    self.sock = self._new_conn()
  File "/var/lib/juju/agents/unit-postgresql-0/charm/venv/lib/python3.10/site-packages/urllib3/connection.py", line 213, in _new_conn
    raise NewConnectionError(
urllib3.exceptions.NewConnectionError: <urllib3.connection.HTTPConnection object at 0x7f0146c25e10>: Failed to establish a new connection: [Errno 111] Connection refused

The above exception was the direct cause of the following exception:

Traceback (most recent call last):
  File "/var/lib/juju/agents/unit-postgresql-0/charm/venv/lib/python3.10/site-packages/requests/adapters.py", line 667, in send
    resp = conn.urlopen(
  File "/var/lib/juju/agents/unit-postgresql-0/charm/venv/lib/python3.10/site-packages/urllib3/connectionpool.py", line 841, in urlopen
    retries = retries.increment(
  File "/var/lib/juju/agents/unit-postgresql-0/charm/venv/lib/python3.10/site-packages/urllib3/util/retry.py", line 519, in increment
    raise MaxRetryError(_pool, url, reason) from reason  # type: ignore[arg-type]
urllib3.exceptions.MaxRetryError: HTTPConnectionPool(host='10.7.178.8', port=8008): Max retries exceeded with url: /cluster (Caused by NewConnectionError('<urllib3.connection.HTTPConnection object at 0x7f0146c25e10>: Failed to establish a new connection: [Errno 111] Connection refused'))

During handling of the above exception, another exception occurred:

Traceback (most recent call last):
  File "/var/lib/juju/agents/unit-postgresql-0/charm/src/cluster.py", line 571, in are_replicas_up
    response = requests.get(
  File "/var/lib/juju/agents/unit-postgresql-0/charm/venv/lib/python3.10/site-packages/requests/api.py", line 73, in get
    return request("get", url, params=params, **kwargs)
  File "/var/lib/juju/agents/unit-postgresql-0/charm/venv/lib/python3.10/site-packages/requests/api.py", line 59, in request
    return session.request(method=method, url=url, **kwargs)
  File "/var/lib/juju/agents/unit-postgresql-0/charm/venv/lib/python3.10/site-packages/requests/sessions.py", line 589, in request
    resp = self.send(prep, **send_kwargs)
  File "/var/lib/juju/agents/unit-postgresql-0/charm/venv/lib/python3.10/site-packages/requests/sessions.py", line 703, in send
    r = adapter.send(request, **kwargs)
  File "/var/lib/juju/agents/unit-postgresql-0/charm/venv/lib/python3.10/site-packages/requests/adapters.py", line 700, in send
    raise ConnectionError(e, request=request)
requests.exceptions.ConnectionError: HTTPConnectionPool(host='10.7.178.8', port=8008): Max retries exceeded with url: /cluster (Caused by NewConnectionError('<urllib3.connection.HTTPConnection object at 0x7f0146c25e10>: Failed to establish a new connection: [Errno 111] Connection refused'))
unit-postgresql-0: 01:35:08 ERROR unit.postgresql/0.juju-log Failed to list PostgreSQL database users: could not translate host name "None" to address: Temporary failure in name resolution

machine-1: 01:35:16 ERROR juju.worker.dependency "lxd-container-provisioner" manifold worker returned unexpected error: container types not yet available
machine-1: 01:35:16 ERROR juju.worker.dependency "kvm-container-provisioner" manifold worker returned unexpected error: container types not yet available
unit-postgresql-1: 01:35:16 ERROR juju.worker.meterstatus error running "meter-status-changed": charm missing from disk
unit-postgresql-1: 01:36:56 ERROR unit.postgresql/1.juju-log Failed to list PostgreSQL database users: connection to server at "10.7.178.214", port 5432 failed: FATAL:  the database system is starting up

unit-postgresql-2: 01:41:29 ERROR unit.postgresql/2.juju-log An exception occurred when installing charmed-postgresql. Reason: Snap: 'charmed-postgresql' -- command ['snap', 'install', 'charmed-postgresql', '--revision="184"'] failed!
Stderr:
error: cannot perform the following tasks:
- Download snap "charmed-postgresql" (184) from channel "stable" (Get "https://canonical-bos01.cdn.snapcraftcontent.com/download-origin/canonical-lgw01/mAiAP9VqaDs9TXjjb9RpIULHkYwb9IoH_184.snap?interactive=1&token=1755406800_cbbc6eeebb095cfa6f9f369a1d4510cdda6622c5": net/http: timeout awaiting response headers)

Latest logs:
Aug 17 01:34:17 juju-ed5b0e-2 systemd[1]: /lib/systemd/system/snapd.service:23: Unknown key name 'RestartMode' in section 'Service', ignoring.
Aug 17 01:34:36 juju-ed5b0e-2 systemd[1]: /lib/systemd/system/snapd.service:23: Unknown key name 'RestartMode' in section 'Service', ignoring.
Aug 17 01:34:36 juju-ed5b0e-2 systemd[1]: /lib/systemd/system/snapd.service:23: Unknown key name 'RestartMode' in section 'Service', ignoring.
Aug 17 01:34:40 juju-ed5b0e-2 snapd[232]: storehelpers.go:916: cannot refresh: snap has no updates available: "core20", "lxd", "snapd"
Aug 17 01:34:43 juju-ed5b0e-2 systemd[1]: /lib/systemd/system/snapd.service:23: Unknown key name 'RestartMode' in section 'Service', ignoring.
Aug 17 01:34:43 juju-ed5b0e-2 systemd[1]: /lib/systemd/system/snapd.service:23: Unknown key name 'RestartMode' in section 'Service', ignoring.
Aug 17 01:34:50 juju-ed5b0e-2 systemd[1]: /lib/systemd/system/snapd.service:23: Unknown key name 'RestartMode' in section 'Service', ignoring.
Aug 17 01:34:50 juju-ed5b0e-2 systemd[1]: /lib/systemd/system/snapd.service:23: Unknown key name 'RestartMode' in section 'Service', ignoring.
Aug 17 01:34:50 juju-ed5b0e-2 systemd[1]: /lib/systemd/system/snapd.service:23: Unknown key name 'RestartMode' in section 'Service', ignoring.
Aug 17 01:35:01 juju-ed5b0e-2 snapd[232]: api_snaps.go:467: Installing snap "charmed-postgresql" revision 184
Aug 17 01:35:02 juju-ed5b0e-2 groupadd[2749]: group added to /etc/group: name=snapd-range-524288-root, GID=524288
Aug 17 01:35:02 juju-ed5b0e-2 groupadd[2749]: group added to /etc/gshadow: name=snapd-range-524288-root
Aug 17 01:35:02 juju-ed5b0e-2 groupadd[2749]: new group: name=snapd-range-524288-root, GID=524288
Aug 17 01:35:02 juju-ed5b0e-2 useradd[2755]: new user: name=snapd-range-524288-root, UID=524288, GID=524288, home=/nonexistent, shell=/usr/bin/false, from=none
Aug 17 01:35:02 juju-ed5b0e-2 groupadd[2764]: group added to /etc/group: name=snap_daemon, GID=584788
Aug 17 01:35:02 juju-ed5b0e-2 groupadd[2764]: group added to /etc/gshadow: name=snap_daemon
Aug 17 01:35:02 juju-ed5b0e-2 groupadd[2764]: new group: name=snap_daemon, GID=584788
Aug 17 01:35:02 juju-ed5b0e-2 useradd[2770]: new user: name=snap_daemon, UID=584788, GID=584788, home=/nonexistent, shell=/usr/bin/false, from=none
Aug 17 01:35:07 juju-ed5b0e-2 systemd[1]: /lib/systemd/system/snapd.service:23: Unknown key name 'RestartMode' in section 'Service', ignoring.
Aug 17 01:41:29 juju-ed5b0e-2 snapd[232]: taskrunner.go:299: Change 5 task (Download snap "charmed-postgresql" (184) from channel "stable") failed: Get "https://canonical-bos01.cdn.snapcraftcontent.com/download-origin/canonical-lgw01/mAiAP9VqaDs9TXjjb9RpIULHkYwb9IoH_184.snap?interactive=1&token=1755406800_cbbc6eeebb095cfa6f9f369a1d4510cdda6622c5": net/http: timeout awaiting response headers


[32mINFO    [0m pytest_operator.plugin:plugin.py:1039 Forgetting model main...