[32mINFO    [0m integration.ha_tests.test_self_healing:test_self_healing.py:491 checking whether the connectivity to the database is working
[32mINFO    [0m integration.ha_tests.test_self_healing:test_self_healing.py:496 Cutting network for postgresql/2
[32mINFO    [0m integration.ha_tests.test_self_healing:test_self_healing.py:504 checking for no connectivity between postgresql/2 and postgresql/3
[32mINFO    [0m integration.ha_tests.test_self_healing:test_self_healing.py:504 checking for no connectivity between postgresql/2 and postgresql/3
[32mINFO    [0m integration.ha_tests.test_self_healing:test_self_healing.py:504 checking for no connectivity between postgresql/2 and postgresql/0
[32mINFO    [0m integration.ha_tests.test_self_healing:test_self_healing.py:511 checking for no connectivity between postgresql/2 and the controller
[32mINFO    [0m integration.ha_tests.test_self_healing:test_self_healing.py:518 checking whether the connectivity to the database is not working
[32mINFO    [0m integration.ha_tests.test_self_healing:test_self_healing.py:524 checking whether writes are increasing
[32mINFO    [0m integration.ha_tests.helpers:helpers.py:103 Initial writes {'testing.postgresql-0': 153, 'testing.postgresql-3': 153}
[32mINFO    [0m integration.ha_tests.helpers:helpers.py:113 Retry writes {'testing.postgresql-0': 156, 'testing.postgresql-3': 156}
[32mINFO    [0m integration.ha_tests.test_self_healing:test_self_healing.py:527 checking whether a new primary was elected
[32mINFO    [0m integration.ha_tests.test_self_healing:test_self_healing.py:534 Restoring network for postgresql/2
[32mINFO    [0m integration.ha_tests.test_self_healing:test_self_healing.py:538 waiting for cluster to become idle
[32mINFO    [0m juju.model:__init__.py:3254 Waiting for model:
  postgresql/0 [idle] active: 
  postgresql/2 [idle] active: Primary
  postgresql/3 [idle] active: 
[32mINFO    [0m integration.ha_tests.test_self_healing:test_self_healing.py:543 waiting for the database service to be ready on postgresql/2
[32mINFO    [0m integration.ha_tests.test_self_healing:test_self_healing.py:547 checking whether the connectivity to the database is working
[32mINFO    [0m integration.ha_tests.helpers:helpers.py:222 checking that the former primary is now a replica
[32mINFO    [0m integration.ha_tests.helpers:helpers.py:228 checking that all units are part of the same cluster
[32mINFO    [0m integration.ha_tests.helpers:helpers.py:242 checking that no writes to the database were missed after stopping the writes
[32mINFO    [0m integration.ha_tests.helpers:helpers.py:248 checking that the former primary is up to date with the cluster after restarting
[32mINFO    [0m pytest_operator.plugin:plugin.py:951 Model status:

Model    Controller     Cloud/Region         Version  SLA          Timestamp
testing  concierge-lxd  localhost/localhost  3.6.9    unsupported  02:10:45Z

App                  Version  Status  Scale  Charm                Channel      Rev  Exposed  Message
postgresql           14.19    active      3  postgresql                          0  no       
postgresql-test-app           active      1  postgresql-test-app  latest/edge  406  no       received database credentials of the first database

Unit                    Workload  Agent  Machine  Public address  Ports     Message
postgresql-test-app/0*  active    idle   3        10.161.245.207            received database credentials of the first database
postgresql/0*           active    idle   0        10.161.245.194  5432/tcp  Primary
postgresql/2            active    idle   2        10.161.245.110  5432/tcp  
postgresql/3            active    idle   4        10.161.245.219  5432/tcp  

Machine  State    Address         Inst id        Base          AZ             Message
0        started  10.161.245.194  juju-29a8fe-0  ubuntu@22.04  runnervmf4ws1  Running
2        started  10.161.245.110  juju-29a8fe-2  ubuntu@22.04  runnervmf4ws1  Running
3        started  10.161.245.207  juju-29a8fe-3  ubuntu@22.04  runnervmf4ws1  Running
4        started  10.161.245.219  juju-29a8fe-4  ubuntu@22.04  runnervmf4ws1  Running

[32mINFO    [0m pytest_operator.plugin:plugin.py:957 Juju error logs:

machine-0: 01:35:59 ERROR juju.worker.dependency "kvm-container-provisioner" manifold worker returned unexpected error: container types not yet available
machine-0: 01:35:59 ERROR juju.worker.dependency "lxd-container-provisioner" manifold worker returned unexpected error: container types not yet available
unit-postgresql-0: 01:35:59 ERROR juju.worker.meterstatus error running "meter-status-changed": charm missing from disk
unit-postgresql-0: 01:37:09 ERROR unit.postgresql/0.juju-log Unable to get the state of the cluster
Traceback (most recent call last):
  File "/var/lib/juju/agents/unit-postgresql-0/charm/venv/lib/python3.10/site-packages/urllib3/connection.py", line 198, in _new_conn
    sock = connection.create_connection(
  File "/var/lib/juju/agents/unit-postgresql-0/charm/venv/lib/python3.10/site-packages/urllib3/util/connection.py", line 85, in create_connection
    raise err
  File "/var/lib/juju/agents/unit-postgresql-0/charm/venv/lib/python3.10/site-packages/urllib3/util/connection.py", line 73, in create_connection
    sock.connect(sa)
ConnectionRefusedError: [Errno 111] Connection refused

The above exception was the direct cause of the following exception:

Traceback (most recent call last):
  File "/var/lib/juju/agents/unit-postgresql-0/charm/venv/lib/python3.10/site-packages/urllib3/connectionpool.py", line 787, in urlopen
    response = self._make_request(
  File "/var/lib/juju/agents/unit-postgresql-0/charm/venv/lib/python3.10/site-packages/urllib3/connectionpool.py", line 493, in _make_request
    conn.request(
  File "/var/lib/juju/agents/unit-postgresql-0/charm/venv/lib/python3.10/site-packages/urllib3/connection.py", line 494, in request
    self.endheaders()
  File "/usr/lib/python3.10/http/client.py", line 1278, in endheaders
    self._send_output(message_body, encode_chunked=encode_chunked)
  File "/usr/lib/python3.10/http/client.py", line 1038, in _send_output
    self.send(msg)
  File "/usr/lib/python3.10/http/client.py", line 976, in send
    self.connect()
  File "/var/lib/juju/agents/unit-postgresql-0/charm/venv/lib/python3.10/site-packages/urllib3/connection.py", line 325, in connect
    self.sock = self._new_conn()
  File "/var/lib/juju/agents/unit-postgresql-0/charm/venv/lib/python3.10/site-packages/urllib3/connection.py", line 213, in _new_conn
    raise NewConnectionError(
urllib3.exceptions.NewConnectionError: <urllib3.connection.HTTPConnection object at 0x7fcce1a0a500>: Failed to establish a new connection: [Errno 111] Connection refused

The above exception was the direct cause of the following exception:

Traceback (most recent call last):
  File "/var/lib/juju/agents/unit-postgresql-0/charm/venv/lib/python3.10/site-packages/requests/adapters.py", line 644, in send
    resp = conn.urlopen(
  File "/var/lib/juju/agents/unit-postgresql-0/charm/venv/lib/python3.10/site-packages/urllib3/connectionpool.py", line 841, in urlopen
    retries = retries.increment(
  File "/var/lib/juju/agents/unit-postgresql-0/charm/venv/lib/python3.10/site-packages/urllib3/util/retry.py", line 519, in increment
    raise MaxRetryError(_pool, url, reason) from reason  # type: ignore[arg-type]
urllib3.exceptions.MaxRetryError: HTTPConnectionPool(host='10.161.245.194', port=8008): Max retries exceeded with url: /cluster (Caused by NewConnectionError('<urllib3.connection.HTTPConnection object at 0x7fcce1a0a500>: Failed to establish a new connection: [Errno 111] Connection refused'))

During handling of the above exception, another exception occurred:

Traceback (most recent call last):
  File "/var/lib/juju/agents/unit-postgresql-0/charm/src/cluster.py", line 577, in are_replicas_up
    response = requests.get(
  File "/var/lib/juju/agents/unit-postgresql-0/charm/venv/lib/python3.10/site-packages/requests/api.py", line 73, in get
    return request("get", url, params=params, **kwargs)
  File "/var/lib/juju/agents/unit-postgresql-0/charm/venv/lib/python3.10/site-packages/requests/api.py", line 59, in request
    return session.request(method=method, url=url, **kwargs)
  File "/var/lib/juju/agents/unit-postgresql-0/charm/venv/lib/python3.10/site-packages/requests/sessions.py", line 589, in request
    resp = self.send(prep, **send_kwargs)
  File "/var/lib/juju/agents/unit-postgresql-0/charm/venv/lib/python3.10/site-packages/requests/sessions.py", line 703, in send
    r = adapter.send(request, **kwargs)
  File "/var/lib/juju/agents/unit-postgresql-0/charm/venv/lib/python3.10/site-packages/requests/adapters.py", line 677, in send
    raise ConnectionError(e, request=request)
requests.exceptions.ConnectionError: HTTPConnectionPool(host='10.161.245.194', port=8008): Max retries exceeded with url: /cluster (Caused by NewConnectionError('<urllib3.connection.HTTPConnection object at 0x7fcce1a0a500>: Failed to establish a new connection: [Errno 111] Connection refused'))
unit-postgresql-0: 01:37:33 ERROR unit.postgresql/0.juju-log Failed to list PostgreSQL database users: could not translate host name "None" to address: Temporary failure in name resolution

unit-postgresql-0: 01:37:37 ERROR unit.postgresql/0.juju-log upgrade:2: Failed to list PostgreSQL database users: could not translate host name "None" to address: Temporary failure in name resolution

machine-3: 01:37:46 ERROR juju.worker.dependency "lxd-container-provisioner" manifold worker returned unexpected error: container types not yet available
machine-3: 01:37:46 ERROR juju.worker.dependency "kvm-container-provisioner" manifold worker returned unexpected error: container types not yet available
unit-postgresql-test-app-0: 01:37:47 ERROR juju.worker.meterstatus error running "meter-status-changed": charm missing from disk
machine-1: 01:38:04 ERROR juju.worker.dependency "kvm-container-provisioner" manifold worker returned unexpected error: container types not yet available
machine-1: 01:38:04 ERROR juju.worker.dependency "lxd-container-provisioner" manifold worker returned unexpected error: container types not yet available
unit-postgresql-1: 01:38:04 ERROR juju.worker.meterstatus error running "meter-status-changed": charm missing from disk
machine-2: 01:38:13 ERROR juju.worker.dependency "lxd-container-provisioner" manifold worker returned unexpected error: container types not yet available
machine-2: 01:38:13 ERROR juju.worker.dependency "kvm-container-provisioner" manifold worker returned unexpected error: container types not yet available
unit-postgresql-2: 01:38:13 ERROR juju.worker.meterstatus error running "meter-status-changed": charm missing from disk
unit-postgresql-1: 01:39:29 ERROR unit.postgresql/1.juju-log restart:1: Failed to list PostgreSQL database users: connection to server at "10.161.245.78", port 5432 failed: Connection refused
	Is the server running on that host and accepting TCP/IP connections?

machine-4: 01:45:57 ERROR juju.worker.dependency "lxd-container-provisioner" manifold worker returned unexpected error: container types not yet available
machine-4: 01:45:57 ERROR juju.worker.dependency "kvm-container-provisioner" manifold worker returned unexpected error: container types not yet available
unit-postgresql-3: 01:45:57 ERROR juju.worker.meterstatus error running "meter-status-changed": charm missing from disk
unit-postgresql-2: 01:46:46 ERROR juju.worker.dependency "log-sender" manifold worker returned unexpected error: sending log message: websocket: close 1005 (no status): websocket: close sent
unit-postgresql-0: 01:46:46 ERROR juju.worker.dependency "log-sender" manifold worker returned unexpected error: sending log message: websocket: close 1005 (no status): websocket: close sent
unit-postgresql-test-app-0: 01:46:53 ERROR juju.worker.dependency "log-sender" manifold worker returned unexpected error: sending log message: websocket: close 1005 (no status): websocket: close sent
machine-2: 01:49:18 ERROR juju.worker.dependency "log-sender" manifold worker returned unexpected error: sending log message: websocket: close 1005 (no status): websocket: close sent
machine-0: 01:49:18 ERROR juju.worker.dependency "log-sender" manifold worker returned unexpected error: sending log message: websocket: close 1005 (no status): websocket: close sent
machine-3: 01:49:18 ERROR juju.worker.dependency "log-sender" manifold worker returned unexpected error: sending log message: websocket: close 1005 (no status): websocket: close sent
unit-postgresql-0: 01:51:22 ERROR juju.worker.dependency "log-sender" manifold worker returned unexpected error: sending log message: websocket: close 1005 (no status): websocket: close sent
unit-postgresql-2: 01:51:22 ERROR juju.worker.dependency "log-sender" manifold worker returned unexpected error: sending log message: websocket: close 1005 (no status): websocket: close sent
unit-postgresql-0: 01:56:23 ERROR unit.postgresql/0.juju-log Unable to get the state of the cluster
Traceback (most recent call last):
  File "/var/lib/juju/agents/unit-postgresql-0/charm/venv/lib/python3.10/site-packages/urllib3/connectionpool.py", line 534, in _make_request
    response = conn.getresponse()
  File "/var/lib/juju/agents/unit-postgresql-0/charm/venv/lib/python3.10/site-packages/urllib3/connection.py", line 565, in getresponse
    httplib_response = super().getresponse()
  File "/usr/lib/python3.10/http/client.py", line 1375, in getresponse
    response.begin()
  File "/usr/lib/python3.10/http/client.py", line 318, in begin
    version, status, reason = self._read_status()
  File "/usr/lib/python3.10/http/client.py", line 279, in _read_status
    line = str(self.fp.readline(_MAXLINE + 1), "iso-8859-1")
  File "/usr/lib/python3.10/socket.py", line 705, in readinto
    return self._sock.recv_into(b)
TimeoutError: timed out

The above exception was the direct cause of the following exception:

Traceback (most recent call last):
  File "/var/lib/juju/agents/unit-postgresql-0/charm/venv/lib/python3.10/site-packages/requests/adapters.py", line 644, in send
    resp = conn.urlopen(
  File "/var/lib/juju/agents/unit-postgresql-0/charm/venv/lib/python3.10/site-packages/urllib3/connectionpool.py", line 841, in urlopen
    retries = retries.increment(
  File "/var/lib/juju/agents/unit-postgresql-0/charm/venv/lib/python3.10/site-packages/urllib3/util/retry.py", line 474, in increment
    raise reraise(type(error), error, _stacktrace)
  File "/var/lib/juju/agents/unit-postgresql-0/charm/venv/lib/python3.10/site-packages/urllib3/util/util.py", line 39, in reraise
    raise value
  File "/var/lib/juju/agents/unit-postgresql-0/charm/venv/lib/python3.10/site-packages/urllib3/connectionpool.py", line 787, in urlopen
    response = self._make_request(
  File "/var/lib/juju/agents/unit-postgresql-0/charm/venv/lib/python3.10/site-packages/urllib3/connectionpool.py", line 536, in _make_request
    self._raise_timeout(err=e, url=url, timeout_value=read_timeout)
  File "/var/lib/juju/agents/unit-postgresql-0/charm/venv/lib/python3.10/site-packages/urllib3/connectionpool.py", line 367, in _raise_timeout
    raise ReadTimeoutError(
urllib3.exceptions.ReadTimeoutError: HTTPConnectionPool(host='10.161.245.194', port=8008): Read timed out. (read timeout=10)

During handling of the above exception, another exception occurred:

Traceback (most recent call last):
  File "/var/lib/juju/agents/unit-postgresql-0/charm/src/cluster.py", line 577, in are_replicas_up
    response = requests.get(
  File "/var/lib/juju/agents/unit-postgresql-0/charm/venv/lib/python3.10/site-packages/requests/api.py", line 73, in get
    return request("get", url, params=params, **kwargs)
  File "/var/lib/juju/agents/unit-postgresql-0/charm/venv/lib/python3.10/site-packages/requests/api.py", line 59, in request
    return session.request(method=method, url=url, **kwargs)
  File "/var/lib/juju/agents/unit-postgresql-0/charm/venv/lib/python3.10/site-packages/requests/sessions.py", line 589, in request
    resp = self.send(prep, **send_kwargs)
  File "/var/lib/juju/agents/unit-postgresql-0/charm/venv/lib/python3.10/site-packages/requests/sessions.py", line 703, in send
    r = adapter.send(request, **kwargs)
  File "/var/lib/juju/agents/unit-postgresql-0/charm/venv/lib/python3.10/site-packages/requests/adapters.py", line 690, in send
    raise ReadTimeout(e, request=request)
requests.exceptions.ReadTimeout: HTTPConnectionPool(host='10.161.245.194', port=8008): Read timed out. (read timeout=10)
unit-postgresql-test-app-0: 02:04:02 ERROR juju.worker.dependency "log-sender" manifold worker returned unexpected error: sending log message: websocket: close 1005 (no status): websocket: close sent
machine-4: 02:05:27 ERROR juju.worker.dependency "api-caller" manifold worker returned unexpected error: api connection broken unexpectedly
unit-postgresql-2: 02:07:13 ERROR juju.worker.dependency "log-sender" manifold worker returned unexpected error: sending log message: websocket: close 1005 (no status): websocket: close sent
unit-postgresql-0: 02:07:14 ERROR juju.worker.dependency "log-sender" manifold worker returned unexpected error: sending log message: websocket: close 1005 (no status): websocket: close sent
machine-2: 02:08:43 ERROR juju.worker.dependency "api-caller" manifold worker returned unexpected error: api connection broken unexpectedly
machine-2: 02:08:46 ERROR juju.worker.dependency "api-caller" manifold worker returned unexpected error: [fe74b2] "machine-2" cannot open api: unable to connect to API: dial tcp 10.161.245.69:17070: connect: no route to host
machine-2: 02:08:53 ERROR juju.worker.dependency "api-caller" manifold worker returned unexpected error: [fe74b2] "machine-2" cannot open api: unable to connect to API: dial tcp 10.161.245.69:17070: connect: no route to host
machine-2: 02:08:59 ERROR juju.worker.dependency "api-caller" manifold worker returned unexpected error: [fe74b2] "machine-2" cannot open api: unable to connect to API: dial tcp 10.161.245.69:17070: connect: no route to host
machine-2: 02:09:05 ERROR juju.worker.dependency "api-caller" manifold worker returned unexpected error: [fe74b2] "machine-2" cannot open api: unable to connect to API: dial tcp 10.161.245.69:17070: connect: no route to host
machine-2: 02:09:14 ERROR juju.worker.dependency "api-caller" manifold worker returned unexpected error: [fe74b2] "machine-2" cannot open api: unable to connect to API: dial tcp 10.161.245.69:17070: connect: no route to host
machine-2: 02:09:23 ERROR juju.worker.dependency "api-caller" manifold worker returned unexpected error: [fe74b2] "machine-2" cannot open api: unable to connect to API: dial tcp 10.161.245.69:17070: connect: no route to host
machine-2: 02:09:36 ERROR juju.worker.dependency "api-caller" manifold worker returned unexpected error: [fe74b2] "machine-2" cannot open api: unable to connect to API: dial tcp 10.161.245.69:17070: i/o timeout
machine-2: 02:09:50 ERROR juju.worker.dependency "api-caller" manifold worker returned unexpected error: [fe74b2] "machine-2" cannot open api: unable to connect to API: dial tcp 10.161.245.69:17070: i/o timeout

[32mINFO    [0m pytest_operator.plugin:plugin.py:1039 Forgetting model main...