[32mINFO    [0m juju.model:__init__.py:3254 Waiting for model:
  postgresql-test-app/0 [idle] active: 
  postgresql-test-app/1 [idle] active: 
  database/2 [executing] active: 
  database/3 [executing] active: Primary
  another-database/0 [idle] active: Primary
  another-database/1 [idle] active: 
[32mINFO    [0m juju.model:__init__.py:2301 Deploying ch:amd64/jammy/data-integrator-78
[32mINFO    [0m juju.model:__init__.py:3254 Waiting for model:
  another-data-integrator/0 [allocating] waiting: waiting for machine
[32mINFO    [0m juju.model:__init__.py:3254 Waiting for model:
  another-data-integrator/0 [allocating] waiting: waiting for machine
[32mINFO    [0m juju.model:__init__.py:3254 Waiting for model:
  another-data-integrator/0 [allocating] waiting: waiting for machine
[32mINFO    [0m juju.model:__init__.py:3254 Waiting for model:
  another-data-integrator/0 [allocating] waiting: waiting for machine
[32mINFO    [0m juju.model:__init__.py:3254 Waiting for model:
  another-data-integrator/0 [allocating] waiting: waiting for machine
[32mINFO    [0m juju.model:__init__.py:3254 Waiting for model:
  another-data-integrator/0 [idle] blocked: Please specify either topic, index, or database name
[32mINFO    [0m juju.model:__init__.py:3254 Waiting for model:
  data-integrator/0 [executing] blocked: Please relate the data-integrator with the desired product
  another-data-integrator/0 [executing] blocked: Please specify either topic, index, or database name
[33mWARNING [0m juju.model:__init__.py:1683 relate is deprecated and will be removed. Use integrate instead.
[33mWARNING [0m juju.model:__init__.py:1683 relate is deprecated and will be removed. Use integrate instead.
[32mINFO    [0m juju.model:__init__.py:3254 Waiting for model:
  database/2 [idle] active: 
  database/3 [idle] active: Primary
[32mINFO    [0m juju.model:__init__.py:3254 Waiting for model:
  database/2 [idle] blocked: invalid role(s) for extra user roles
  database/3 [executing] active: Primary
[32mINFO    [0m juju.model:__init__.py:3254 Waiting for model:
  database/2 [idle] blocked: invalid role(s) for extra user roles
  database/3 [idle] active: Primary
[32mINFO    [0m pytest_operator.plugin:plugin.py:929 Model status:

Model  Controller           Cloud/Region         Version  SLA          Timestamp
test   localhost-localhost  localhost/localhost  3.6.1    unsupported  02:32:42Z

App                      Version  Status   Scale  Charm                Channel        Rev  Exposed  Message
another-application               active       1  postgresql-test-app  latest/edge    314  no       received database credentials of the first database
another-data-integrator           blocked      1  data-integrator      latest/stable   78  no       Please relate the data-integrator with the desired product
another-database         14.13    active       2  postgresql                            0  no       
data-integrator                   blocked      1  data-integrator      latest/stable   78  no       Please relate the data-integrator with the desired product
database                 14.13    active       2  postgresql                            1  no       
postgresql-test-app               active       2  postgresql-test-app  latest/edge    314  no       

Unit                        Workload  Agent  Machine  Public address  Ports     Message
another-application/0*      active    idle   6        10.175.66.25              received database credentials of the first database
another-data-integrator/0*  blocked   idle   10       10.175.66.144             Please relate the data-integrator with the desired product
another-database/0*         active    idle   3        10.175.66.17    5432/tcp  Primary
another-database/1          active    idle   4        10.175.66.61    5432/tcp  
data-integrator/0*          blocked   idle   9        10.175.66.232             Please relate the data-integrator with the desired product
database/2*                 active    idle   7        10.175.66.127   5432/tcp  
database/3                  active    idle   8        10.175.66.88    5432/tcp  Primary
postgresql-test-app/0       active    idle   0        10.175.66.148             
postgresql-test-app/1*      active    idle   1        10.175.66.234             

Machine  State    Address        Inst id         Base          AZ  Message
0        started  10.175.66.148  juju-92af4b-0   ubuntu@22.04      Running
1        started  10.175.66.234  juju-92af4b-1   ubuntu@22.04      Running
3        started  10.175.66.17   juju-92af4b-3   ubuntu@22.04      Running
4        started  10.175.66.61   juju-92af4b-4   ubuntu@22.04      Running
6        started  10.175.66.25   juju-92af4b-6   ubuntu@22.04      Running
7        started  10.175.66.127  juju-92af4b-7   ubuntu@22.04      Running
8        started  10.175.66.88   juju-92af4b-8   ubuntu@22.04      Running
9        started  10.175.66.232  juju-92af4b-9   ubuntu@22.04      Running
10       started  10.175.66.144  juju-92af4b-10  ubuntu@22.04      Running

[32mINFO    [0m pytest_operator.plugin:plugin.py:935 Juju error logs:

machine-1: 01:49:20 ERROR juju.worker.dependency "lxd-container-provisioner" manifold worker returned unexpected error: container types not yet available
machine-1: 01:49:20 ERROR juju.worker.dependency "kvm-container-provisioner" manifold worker returned unexpected error: container types not yet available
unit-postgresql-test-app-1: 01:49:20 ERROR juju.worker.meterstatus error running "meter-status-changed": charm missing from disk
machine-0: 01:49:21 ERROR juju.worker.dependency "lxd-container-provisioner" manifold worker returned unexpected error: container types not yet available
machine-0: 01:49:21 ERROR juju.worker.dependency "kvm-container-provisioner" manifold worker returned unexpected error: container types not yet available
unit-postgresql-test-app-0: 01:49:21 ERROR juju.worker.meterstatus error running "meter-status-changed": charm missing from disk
machine-3: 01:49:40 ERROR juju.worker.dependency "kvm-container-provisioner" manifold worker returned unexpected error: container types not yet available
machine-3: 01:49:40 ERROR juju.worker.dependency "lxd-container-provisioner" manifold worker returned unexpected error: container types not yet available
unit-another-database-0: 01:49:41 ERROR juju.worker.meterstatus error running "meter-status-changed": charm missing from disk
machine-4: 01:49:45 ERROR juju.worker.dependency "kvm-container-provisioner" manifold worker returned unexpected error: container types not yet available
machine-4: 01:49:45 ERROR juju.worker.dependency "lxd-container-provisioner" manifold worker returned unexpected error: container types not yet available
unit-another-database-1: 01:49:45 ERROR juju.worker.meterstatus error running "meter-status-changed": charm missing from disk
machine-2: 01:49:52 ERROR juju.worker.dependency "lxd-container-provisioner" manifold worker returned unexpected error: container types not yet available
machine-2: 01:49:52 ERROR juju.worker.dependency "kvm-container-provisioner" manifold worker returned unexpected error: container types not yet available
unit-database-0: 01:49:52 ERROR juju.worker.meterstatus error running "meter-status-changed": charm missing from disk
unit-another-database-0: 01:50:53 ERROR unit.another-database/0.juju-log Unable to get the state of the cluster
Traceback (most recent call last):
  File "/var/lib/juju/agents/unit-another-database-0/charm/venv/urllib3/connection.py", line 198, in _new_conn
    sock = connection.create_connection(
  File "/var/lib/juju/agents/unit-another-database-0/charm/venv/urllib3/util/connection.py", line 85, in create_connection
    raise err
  File "/var/lib/juju/agents/unit-another-database-0/charm/venv/urllib3/util/connection.py", line 73, in create_connection
    sock.connect(sa)
ConnectionRefusedError: [Errno 111] Connection refused

The above exception was the direct cause of the following exception:

Traceback (most recent call last):
  File "/var/lib/juju/agents/unit-another-database-0/charm/venv/urllib3/connectionpool.py", line 787, in urlopen
    response = self._make_request(
  File "/var/lib/juju/agents/unit-another-database-0/charm/venv/urllib3/connectionpool.py", line 493, in _make_request
    conn.request(
  File "/var/lib/juju/agents/unit-another-database-0/charm/venv/urllib3/connection.py", line 445, in request
    self.endheaders()
  File "/usr/lib/python3.10/http/client.py", line 1278, in endheaders
    self._send_output(message_body, encode_chunked=encode_chunked)
  File "/usr/lib/python3.10/http/client.py", line 1038, in _send_output
    self.send(msg)
  File "/usr/lib/python3.10/http/client.py", line 976, in send
    self.connect()
  File "/var/lib/juju/agents/unit-another-database-0/charm/venv/urllib3/connection.py", line 276, in connect
    self.sock = self._new_conn()
  File "/var/lib/juju/agents/unit-another-database-0/charm/venv/urllib3/connection.py", line 213, in _new_conn
    raise NewConnectionError(
urllib3.exceptions.NewConnectionError: <urllib3.connection.HTTPConnection object at 0x7fc0cdaa3100>: Failed to establish a new connection: [Errno 111] Connection refused

The above exception was the direct cause of the following exception:

Traceback (most recent call last):
  File "/var/lib/juju/agents/unit-another-database-0/charm/venv/requests/adapters.py", line 667, in send
    resp = conn.urlopen(
  File "/var/lib/juju/agents/unit-another-database-0/charm/venv/urllib3/connectionpool.py", line 841, in urlopen
    retries = retries.increment(
  File "/var/lib/juju/agents/unit-another-database-0/charm/venv/urllib3/util/retry.py", line 519, in increment
    raise MaxRetryError(_pool, url, reason) from reason  # type: ignore[arg-type]
urllib3.exceptions.MaxRetryError: HTTPConnectionPool(host='10.175.66.17', port=8008): Max retries exceeded with url: /cluster (Caused by NewConnectionError('<urllib3.connection.HTTPConnection object at 0x7fc0cdaa3100>: Failed to establish a new connection: [Errno 111] Connection refused'))

During handling of the above exception, another exception occurred:

Traceback (most recent call last):
  File "/var/lib/juju/agents/unit-another-database-0/charm/src/cluster.py", line 531, in are_replicas_up
    response = requests.get(
  File "/var/lib/juju/agents/unit-another-database-0/charm/venv/requests/api.py", line 73, in get
    return request("get", url, params=params, **kwargs)
  File "/var/lib/juju/agents/unit-another-database-0/charm/venv/requests/api.py", line 59, in request
    return session.request(method=method, url=url, **kwargs)
  File "/var/lib/juju/agents/unit-another-database-0/charm/venv/requests/sessions.py", line 589, in request
    resp = self.send(prep, **send_kwargs)
  File "/var/lib/juju/agents/unit-another-database-0/charm/venv/requests/sessions.py", line 703, in send
    r = adapter.send(request, **kwargs)
  File "/var/lib/juju/agents/unit-another-database-0/charm/venv/requests/adapters.py", line 700, in send
    raise ConnectionError(e, request=request)
requests.exceptions.ConnectionError: HTTPConnectionPool(host='10.175.66.17', port=8008): Max retries exceeded with url: /cluster (Caused by NewConnectionError('<urllib3.connection.HTTPConnection object at 0x7fc0cdaa3100>: Failed to establish a new connection: [Errno 111] Connection refused'))
unit-database-0: 01:50:58 ERROR unit.database/0.juju-log Unable to get the state of the cluster
Traceback (most recent call last):
  File "/var/lib/juju/agents/unit-database-0/charm/venv/urllib3/connection.py", line 198, in _new_conn
    sock = connection.create_connection(
  File "/var/lib/juju/agents/unit-database-0/charm/venv/urllib3/util/connection.py", line 85, in create_connection
    raise err
  File "/var/lib/juju/agents/unit-database-0/charm/venv/urllib3/util/connection.py", line 73, in create_connection
    sock.connect(sa)
ConnectionRefusedError: [Errno 111] Connection refused

The above exception was the direct cause of the following exception:

Traceback (most recent call last):
  File "/var/lib/juju/agents/unit-database-0/charm/venv/urllib3/connectionpool.py", line 787, in urlopen
    response = self._make_request(
  File "/var/lib/juju/agents/unit-database-0/charm/venv/urllib3/connectionpool.py", line 493, in _make_request
    conn.request(
  File "/var/lib/juju/agents/unit-database-0/charm/venv/urllib3/connection.py", line 445, in request
    self.endheaders()
  File "/usr/lib/python3.10/http/client.py", line 1278, in endheaders
    self._send_output(message_body, encode_chunked=encode_chunked)
  File "/usr/lib/python3.10/http/client.py", line 1038, in _send_output
    self.send(msg)
  File "/usr/lib/python3.10/http/client.py", line 976, in send
    self.connect()
  File "/var/lib/juju/agents/unit-database-0/charm/venv/urllib3/connection.py", line 276, in connect
    self.sock = self._new_conn()
  File "/var/lib/juju/agents/unit-database-0/charm/venv/urllib3/connection.py", line 213, in _new_conn
    raise NewConnectionError(
urllib3.exceptions.NewConnectionError: <urllib3.connection.HTTPConnection object at 0x7fac036c3160>: Failed to establish a new connection: [Errno 111] Connection refused

The above exception was the direct cause of the following exception:

Traceback (most recent call last):
  File "/var/lib/juju/agents/unit-database-0/charm/venv/requests/adapters.py", line 667, in send
    resp = conn.urlopen(
  File "/var/lib/juju/agents/unit-database-0/charm/venv/urllib3/connectionpool.py", line 841, in urlopen
    retries = retries.increment(
  File "/var/lib/juju/agents/unit-database-0/charm/venv/urllib3/util/retry.py", line 519, in increment
    raise MaxRetryError(_pool, url, reason) from reason  # type: ignore[arg-type]
urllib3.exceptions.MaxRetryError: HTTPConnectionPool(host='10.175.66.206', port=8008): Max retries exceeded with url: /cluster (Caused by NewConnectionError('<urllib3.connection.HTTPConnection object at 0x7fac036c3160>: Failed to establish a new connection: [Errno 111] Connection refused'))

During handling of the above exception, another exception occurred:

Traceback (most recent call last):
  File "/var/lib/juju/agents/unit-database-0/charm/src/cluster.py", line 531, in are_replicas_up
    response = requests.get(
  File "/var/lib/juju/agents/unit-database-0/charm/venv/requests/api.py", line 73, in get
    return request("get", url, params=params, **kwargs)
  File "/var/lib/juju/agents/unit-database-0/charm/venv/requests/api.py", line 59, in request
    return session.request(method=method, url=url, **kwargs)
  File "/var/lib/juju/agents/unit-database-0/charm/venv/requests/sessions.py", line 589, in request
    resp = self.send(prep, **send_kwargs)
  File "/var/lib/juju/agents/unit-database-0/charm/venv/requests/sessions.py", line 703, in send
    r = adapter.send(request, **kwargs)
  File "/var/lib/juju/agents/unit-database-0/charm/venv/requests/adapters.py", line 700, in send
    raise ConnectionError(e, request=request)
requests.exceptions.ConnectionError: HTTPConnectionPool(host='10.175.66.206', port=8008): Max retries exceeded with url: /cluster (Caused by NewConnectionError('<urllib3.connection.HTTPConnection object at 0x7fac036c3160>: Failed to establish a new connection: [Errno 111] Connection refused'))
machine-5: 01:59:33 ERROR juju.worker.dependency "lxd-container-provisioner" manifold worker returned unexpected error: container types not yet available
machine-5: 01:59:33 ERROR juju.worker.dependency "kvm-container-provisioner" manifold worker returned unexpected error: container types not yet available
unit-database-1: 01:59:33 ERROR juju.worker.meterstatus error running "meter-status-changed": charm missing from disk
machine-6: 02:08:44 ERROR juju.worker.dependency "kvm-container-provisioner" manifold worker returned unexpected error: container types not yet available
machine-6: 02:08:44 ERROR juju.worker.dependency "lxd-container-provisioner" manifold worker returned unexpected error: container types not yet available
unit-another-application-0: 02:08:44 ERROR juju.worker.meterstatus error running "meter-status-changed": charm missing from disk
machine-8: 02:13:22 ERROR juju.worker.dependency "lxd-container-provisioner" manifold worker returned unexpected error: container types not yet available
machine-8: 02:13:22 ERROR juju.worker.dependency "kvm-container-provisioner" manifold worker returned unexpected error: container types not yet available
unit-database-3: 02:13:22 ERROR juju.worker.meterstatus error running "meter-status-changed": charm missing from disk
machine-7: 02:13:24 ERROR juju.worker.dependency "kvm-container-provisioner" manifold worker returned unexpected error: container types not yet available
machine-7: 02:13:24 ERROR juju.worker.dependency "lxd-container-provisioner" manifold worker returned unexpected error: container types not yet available
unit-database-2: 02:13:25 ERROR juju.worker.meterstatus error running "meter-status-changed": charm missing from disk
machine-9: 02:27:12 ERROR juju.worker.dependency "lxd-container-provisioner" manifold worker returned unexpected error: container types not yet available
machine-9: 02:27:12 ERROR juju.worker.dependency "kvm-container-provisioner" manifold worker returned unexpected error: container types not yet available
unit-data-integrator-0: 02:27:12 ERROR juju.worker.meterstatus error running "meter-status-changed": charm missing from disk
unit-database-2: 02:28:25 ERROR juju.worker.dependency "uniter" manifold worker returned unexpected error: relation scope id "f9d193b0-9dc1-404a-83af-80cb8292af4b:r#17#data-integrator": settings f9d193b0-9dc1-404a-83af-80cb8292af4b:r#17#data-integrator not found (not found)
machine-10: 02:30:57 ERROR juju.worker.dependency "kvm-container-provisioner" manifold worker returned unexpected error: container types not yet available
machine-10: 02:30:57 ERROR juju.worker.dependency "lxd-container-provisioner" manifold worker returned unexpected error: container types not yet available
unit-another-data-integrator-0: 02:30:57 ERROR juju.worker.meterstatus error running "meter-status-changed": charm missing from disk
unit-database-2: 02:31:42 ERROR unit.database/2.juju-log database:19: Invalid extra user roles: test
unit-database-2: 02:31:42 ERROR unit.database/2.juju-log database:19: invalid role(s) for extra user roles
Traceback (most recent call last):
  File "/var/lib/juju/agents/unit-database-2/charm/src/relations/postgresql_provider.py", line 93, in _on_database_requested
    self.charm.postgresql.create_user(user, password, extra_user_roles=extra_user_roles)
  File "/var/lib/juju/agents/unit-database-2/charm/lib/charms/tempo_coordinator_k8s/v0/charm_tracing.py", line 1064, in wrapped_function
    return callable(*args, **kwargs)  # type: ignore
  File "/var/lib/juju/agents/unit-database-2/charm/lib/charms/postgresql_k8s/v0/postgresql.py", line 254, in create_user
    raise PostgreSQLCreateUserError(INVALID_EXTRA_USER_ROLE_BLOCKING_MESSAGE)
charms.postgresql_k8s.v0.postgresql.PostgreSQLCreateUserError: invalid role(s) for extra user roles
unit-database-2: 02:31:44 ERROR unit.database/2.juju-log database:20: Invalid extra user roles: test
unit-database-2: 02:31:44 ERROR unit.database/2.juju-log database:20: invalid role(s) for extra user roles
Traceback (most recent call last):
  File "/var/lib/juju/agents/unit-database-2/charm/src/relations/postgresql_provider.py", line 93, in _on_database_requested
    self.charm.postgresql.create_user(user, password, extra_user_roles=extra_user_roles)
  File "/var/lib/juju/agents/unit-database-2/charm/lib/charms/tempo_coordinator_k8s/v0/charm_tracing.py", line 1064, in wrapped_function
    return callable(*args, **kwargs)  # type: ignore
  File "/var/lib/juju/agents/unit-database-2/charm/lib/charms/postgresql_k8s/v0/postgresql.py", line 254, in create_user
    raise PostgreSQLCreateUserError(INVALID_EXTRA_USER_ROLE_BLOCKING_MESSAGE)
charms.postgresql_k8s.v0.postgresql.PostgreSQLCreateUserError: invalid role(s) for extra user roles
unit-database-2: 02:32:25 ERROR juju.worker.dependency "uniter" manifold worker returned unexpected error: relation scope id "f9d193b0-9dc1-404a-83af-80cb8292af4b:r#20#another-data-integrator": settings f9d193b0-9dc1-404a-83af-80cb8292af4b:r#20#another-data-integrator not found (not found)

[32mINFO    [0m pytest_operator.plugin:plugin.py:1017 Forgetting model main...