[32mINFO    [0m integration.ha_tests.test_self_healing:test_self_healing.py:491 checking whether the connectivity to the database is working
[32mINFO    [0m integration.ha_tests.test_self_healing:test_self_healing.py:496 Cutting network for postgresql/0
[32mINFO    [0m integration.ha_tests.test_self_healing:test_self_healing.py:504 checking for no connectivity between postgresql/0 and postgresql/3
[32mINFO    [0m integration.ha_tests.test_self_healing:test_self_healing.py:504 checking for no connectivity between postgresql/0 and postgresql/3
[32mINFO    [0m integration.ha_tests.test_self_healing:test_self_healing.py:504 checking for no connectivity between postgresql/0 and postgresql/2
[32mINFO    [0m integration.ha_tests.test_self_healing:test_self_healing.py:511 checking for no connectivity between postgresql/0 and the controller
[32mINFO    [0m integration.ha_tests.test_self_healing:test_self_healing.py:518 checking whether the connectivity to the database is not working
[32mINFO    [0m integration.ha_tests.test_self_healing:test_self_healing.py:524 checking whether writes are increasing
[32mINFO    [0m integration.ha_tests.helpers:helpers.py:103 Initial writes {'testing.postgresql-2': 8, 'testing.postgresql-3': 8}
[32mINFO    [0m integration.ha_tests.helpers:helpers.py:113 Retry writes {'testing.postgresql-2': 8, 'testing.postgresql-3': 8}
[32mINFO    [0m integration.ha_tests.helpers:helpers.py:113 Retry writes {'testing.postgresql-2': 8, 'testing.postgresql-3': 8}
[32mINFO    [0m integration.ha_tests.helpers:helpers.py:113 Retry writes {'testing.postgresql-2': 8, 'testing.postgresql-3': 8}
[32mINFO    [0m integration.ha_tests.helpers:helpers.py:113 Retry writes {'testing.postgresql-2': 8, 'testing.postgresql-3': 8}
[32mINFO    [0m integration.ha_tests.helpers:helpers.py:113 Retry writes {'testing.postgresql-2': 8, 'testing.postgresql-3': 8}
[32mINFO    [0m integration.ha_tests.helpers:helpers.py:113 Retry writes {'testing.postgresql-2': 8, 'testing.postgresql-3': 8}
[32mINFO    [0m integration.ha_tests.helpers:helpers.py:113 Retry writes {'testing.postgresql-2': 8, 'testing.postgresql-3': 8}
[32mINFO    [0m integration.ha_tests.helpers:helpers.py:113 Retry writes {'testing.postgresql-2': 8, 'testing.postgresql-3': 8}
[32mINFO    [0m integration.ha_tests.helpers:helpers.py:113 Retry writes {'testing.postgresql-2': 8, 'testing.postgresql-3': 8}
[32mINFO    [0m integration.ha_tests.helpers:helpers.py:113 Retry writes {'testing.postgresql-2': 8, 'testing.postgresql-3': 8}
[32mINFO    [0m integration.ha_tests.helpers:helpers.py:113 Retry writes {'testing.postgresql-2': 8, 'testing.postgresql-3': 8}
[32mINFO    [0m integration.ha_tests.helpers:helpers.py:113 Retry writes {'testing.postgresql-2': 8, 'testing.postgresql-3': 8}
[32mINFO    [0m integration.ha_tests.helpers:helpers.py:113 Retry writes {'testing.postgresql-2': 8, 'testing.postgresql-3': 8}
[32mINFO    [0m integration.ha_tests.helpers:helpers.py:113 Retry writes {'testing.postgresql-2': 8, 'testing.postgresql-3': 8}
[32mINFO    [0m integration.ha_tests.helpers:helpers.py:113 Retry writes {'testing.postgresql-2': 8, 'testing.postgresql-3': 8}
[32mINFO    [0m integration.ha_tests.helpers:helpers.py:113 Retry writes {'testing.postgresql-2': 8, 'testing.postgresql-3': 8}
[32mINFO    [0m integration.ha_tests.helpers:helpers.py:113 Retry writes {'testing.postgresql-2': 8, 'testing.postgresql-3': 8}
[32mINFO    [0m integration.ha_tests.helpers:helpers.py:113 Retry writes {'testing.postgresql-2': 8, 'testing.postgresql-3': 8}
[32mINFO    [0m integration.ha_tests.helpers:helpers.py:113 Retry writes {'testing.postgresql-2': 8, 'testing.postgresql-3': 8}
[32mINFO    [0m integration.ha_tests.helpers:helpers.py:113 Retry writes {'testing.postgresql-2': 8, 'testing.postgresql-3': 8}
[32mINFO    [0m integration.ha_tests.helpers:helpers.py:113 Retry writes {'testing.postgresql-2': 8, 'testing.postgresql-3': 8}
[32mINFO    [0m integration.ha_tests.helpers:helpers.py:113 Retry writes {'testing.postgresql-2': 8, 'testing.postgresql-3': 8}
[32mINFO    [0m integration.ha_tests.helpers:helpers.py:113 Retry writes {'testing.postgresql-2': 8, 'testing.postgresql-3': 8}
[32mINFO    [0m integration.ha_tests.helpers:helpers.py:113 Retry writes {'testing.postgresql-2': 8, 'testing.postgresql-3': 8}
[32mINFO    [0m integration.ha_tests.helpers:helpers.py:113 Retry writes {'testing.postgresql-2': 8, 'testing.postgresql-3': 8}
[32mINFO    [0m integration.ha_tests.helpers:helpers.py:113 Retry writes {'testing.postgresql-2': 8, 'testing.postgresql-3': 8}
[32mINFO    [0m integration.ha_tests.helpers:helpers.py:113 Retry writes {'testing.postgresql-2': 8, 'testing.postgresql-3': 8}
[32mINFO    [0m integration.ha_tests.helpers:helpers.py:113 Retry writes {'testing.postgresql-2': 8, 'testing.postgresql-3': 8}
[32mINFO    [0m integration.ha_tests.helpers:helpers.py:113 Retry writes {'testing.postgresql-2': 8, 'testing.postgresql-3': 8}
[32mINFO    [0m integration.ha_tests.helpers:helpers.py:113 Retry writes {'testing.postgresql-2': 8, 'testing.postgresql-3': 8}
[32mINFO    [0m integration.ha_tests.helpers:helpers.py:113 Retry writes {'testing.postgresql-2': 8, 'testing.postgresql-3': 8}
[32mINFO    [0m integration.ha_tests.helpers:helpers.py:113 Retry writes {'testing.postgresql-2': 8, 'testing.postgresql-3': 8}
[32mINFO    [0m integration.ha_tests.helpers:helpers.py:113 Retry writes {'testing.postgresql-2': 8, 'testing.postgresql-3': 8}
[32mINFO    [0m integration.ha_tests.helpers:helpers.py:113 Retry writes {'testing.postgresql-2': 8, 'testing.postgresql-3': 8}
[32mINFO    [0m integration.ha_tests.helpers:helpers.py:113 Retry writes {'testing.postgresql-2': 8, 'testing.postgresql-3': 8}
[32mINFO    [0m integration.ha_tests.helpers:helpers.py:113 Retry writes {'testing.postgresql-2': 8, 'testing.postgresql-3': 8}
[32mINFO    [0m integration.ha_tests.helpers:helpers.py:113 Retry writes {'testing.postgresql-2': 8, 'testing.postgresql-3': 8}
[32mINFO    [0m integration.ha_tests.helpers:helpers.py:113 Retry writes {'testing.postgresql-2': 8, 'testing.postgresql-3': 8}
[32mINFO    [0m pytest_operator.plugin:plugin.py:951 Model status:

Model    Controller     Cloud/Region         Version  SLA          Timestamp
testing  concierge-lxd  localhost/localhost  3.6.9    unsupported  02:27:34Z

App                  Version  Status  Scale  Charm                Channel      Rev  Exposed  Message
postgresql           14.18    active    2/3  postgresql                          0  no       
postgresql-test-app           active      1  postgresql-test-app  latest/edge  402  no       received database credentials of the first database

Unit                    Workload  Agent  Machine  Public address  Ports     Message
postgresql-test-app/0*  active    idle   3        10.21.124.42              received database credentials of the first database
postgresql/0            unknown   lost   0        10.21.124.142   5432/tcp  agent lost, see 'juju show-status-log postgresql/0'
postgresql/2            active    idle   2        10.21.124.117   5432/tcp  Primary (degraded)
postgresql/3*           active    idle   4        10.21.124.251   5432/tcp  

Machine  State    Address        Inst id        Base          AZ               Message
0        down     10.21.124.142  juju-7bee64-0  ubuntu@22.04  pkrvmqc4gcfdwos  Running
2        started  10.21.124.117  juju-7bee64-2  ubuntu@22.04  pkrvmqc4gcfdwos  Running
3        started  10.21.124.42   juju-7bee64-3  ubuntu@22.04  pkrvmqc4gcfdwos  Running
4        started  10.21.124.251  juju-7bee64-4  ubuntu@22.04  pkrvmqc4gcfdwos  Running

[32mINFO    [0m pytest_operator.plugin:plugin.py:957 Juju error logs:

machine-0: 01:32:43 ERROR juju.worker.dependency "lxd-container-provisioner" manifold worker returned unexpected error: container types not yet available
machine-0: 01:32:43 ERROR juju.worker.dependency "kvm-container-provisioner" manifold worker returned unexpected error: container types not yet available
unit-postgresql-0: 01:32:43 ERROR juju.worker.meterstatus error running "meter-status-changed": charm missing from disk
unit-postgresql-0: 01:34:02 ERROR unit.postgresql/0.juju-log Unable to get the state of the cluster
Traceback (most recent call last):
  File "/var/lib/juju/agents/unit-postgresql-0/charm/venv/lib/python3.10/site-packages/urllib3/connection.py", line 198, in _new_conn
    sock = connection.create_connection(
  File "/var/lib/juju/agents/unit-postgresql-0/charm/venv/lib/python3.10/site-packages/urllib3/util/connection.py", line 85, in create_connection
    raise err
  File "/var/lib/juju/agents/unit-postgresql-0/charm/venv/lib/python3.10/site-packages/urllib3/util/connection.py", line 73, in create_connection
    sock.connect(sa)
ConnectionRefusedError: [Errno 111] Connection refused

The above exception was the direct cause of the following exception:

Traceback (most recent call last):
  File "/var/lib/juju/agents/unit-postgresql-0/charm/venv/lib/python3.10/site-packages/urllib3/connectionpool.py", line 787, in urlopen
    response = self._make_request(
  File "/var/lib/juju/agents/unit-postgresql-0/charm/venv/lib/python3.10/site-packages/urllib3/connectionpool.py", line 493, in _make_request
    conn.request(
  File "/var/lib/juju/agents/unit-postgresql-0/charm/venv/lib/python3.10/site-packages/urllib3/connection.py", line 494, in request
    self.endheaders()
  File "/usr/lib/python3.10/http/client.py", line 1278, in endheaders
    self._send_output(message_body, encode_chunked=encode_chunked)
  File "/usr/lib/python3.10/http/client.py", line 1038, in _send_output
    self.send(msg)
  File "/usr/lib/python3.10/http/client.py", line 976, in send
    self.connect()
  File "/var/lib/juju/agents/unit-postgresql-0/charm/venv/lib/python3.10/site-packages/urllib3/connection.py", line 325, in connect
    self.sock = self._new_conn()
  File "/var/lib/juju/agents/unit-postgresql-0/charm/venv/lib/python3.10/site-packages/urllib3/connection.py", line 213, in _new_conn
    raise NewConnectionError(
urllib3.exceptions.NewConnectionError: <urllib3.connection.HTTPConnection object at 0x7f9bd0676950>: Failed to establish a new connection: [Errno 111] Connection refused

The above exception was the direct cause of the following exception:

Traceback (most recent call last):
  File "/var/lib/juju/agents/unit-postgresql-0/charm/venv/lib/python3.10/site-packages/requests/adapters.py", line 644, in send
    resp = conn.urlopen(
  File "/var/lib/juju/agents/unit-postgresql-0/charm/venv/lib/python3.10/site-packages/urllib3/connectionpool.py", line 841, in urlopen
    retries = retries.increment(
  File "/var/lib/juju/agents/unit-postgresql-0/charm/venv/lib/python3.10/site-packages/urllib3/util/retry.py", line 519, in increment
    raise MaxRetryError(_pool, url, reason) from reason  # type: ignore[arg-type]
urllib3.exceptions.MaxRetryError: HTTPConnectionPool(host='10.21.124.142', port=8008): Max retries exceeded with url: /cluster (Caused by NewConnectionError('<urllib3.connection.HTTPConnection object at 0x7f9bd0676950>: Failed to establish a new connection: [Errno 111] Connection refused'))

During handling of the above exception, another exception occurred:

Traceback (most recent call last):
  File "/var/lib/juju/agents/unit-postgresql-0/charm/src/cluster.py", line 571, in are_replicas_up
    response = requests.get(
  File "/var/lib/juju/agents/unit-postgresql-0/charm/venv/lib/python3.10/site-packages/requests/api.py", line 73, in get
    return request("get", url, params=params, **kwargs)
  File "/var/lib/juju/agents/unit-postgresql-0/charm/venv/lib/python3.10/site-packages/requests/api.py", line 59, in request
    return session.request(method=method, url=url, **kwargs)
  File "/var/lib/juju/agents/unit-postgresql-0/charm/venv/lib/python3.10/site-packages/requests/sessions.py", line 589, in request
    resp = self.send(prep, **send_kwargs)
  File "/var/lib/juju/agents/unit-postgresql-0/charm/venv/lib/python3.10/site-packages/requests/sessions.py", line 703, in send
    r = adapter.send(request, **kwargs)
  File "/var/lib/juju/agents/unit-postgresql-0/charm/venv/lib/python3.10/site-packages/requests/adapters.py", line 677, in send
    raise ConnectionError(e, request=request)
requests.exceptions.ConnectionError: HTTPConnectionPool(host='10.21.124.142', port=8008): Max retries exceeded with url: /cluster (Caused by NewConnectionError('<urllib3.connection.HTTPConnection object at 0x7f9bd0676950>: Failed to establish a new connection: [Errno 111] Connection refused'))
unit-postgresql-0: 01:34:21 ERROR unit.postgresql/0.juju-log Failed to list PostgreSQL database users: could not translate host name "None" to address: Temporary failure in name resolution

machine-3: 01:35:01 ERROR juju.worker.dependency "kvm-container-provisioner" manifold worker returned unexpected error: container types not yet available
machine-3: 01:35:01 ERROR juju.worker.dependency "lxd-container-provisioner" manifold worker returned unexpected error: container types not yet available
unit-postgresql-test-app-0: 01:35:01 ERROR juju.worker.meterstatus error running "meter-status-changed": charm missing from disk
machine-2: 01:35:12 ERROR juju.worker.dependency "lxd-container-provisioner" manifold worker returned unexpected error: container types not yet available
machine-2: 01:35:12 ERROR juju.worker.dependency "kvm-container-provisioner" manifold worker returned unexpected error: container types not yet available
unit-postgresql-2: 01:35:12 ERROR juju.worker.meterstatus error running "meter-status-changed": charm missing from disk
machine-1: 01:35:16 ERROR juju.worker.dependency "kvm-container-provisioner" manifold worker returned unexpected error: container types not yet available
machine-1: 01:35:16 ERROR juju.worker.dependency "lxd-container-provisioner" manifold worker returned unexpected error: container types not yet available
unit-postgresql-1: 01:35:16 ERROR juju.worker.meterstatus error running "meter-status-changed": charm missing from disk
unit-postgresql-1: 01:37:38 ERROR unit.postgresql/1.juju-log Failed to list PostgreSQL database users: connection to server at "10.21.124.44", port 5432 failed: Connection refused
	Is the server running on that host and accepting TCP/IP connections?

unit-postgresql-2: 01:46:09 ERROR juju.worker.dependency "log-sender" manifold worker returned unexpected error: sending log message: websocket: close 1005 (no status): websocket: close sent
machine-4: 01:46:12 ERROR juju.worker.dependency "kvm-container-provisioner" manifold worker returned unexpected error: container types not yet available
machine-4: 01:46:12 ERROR juju.worker.dependency "lxd-container-provisioner" manifold worker returned unexpected error: container types not yet available
unit-postgresql-3: 01:46:12 ERROR juju.worker.meterstatus error running "meter-status-changed": charm missing from disk
unit-postgresql-0: 01:46:16 ERROR juju.worker.dependency "log-sender" manifold worker returned unexpected error: sending log message: websocket: close 1005 (no status): websocket: close sent
unit-postgresql-test-app-0: 01:46:18 ERROR juju.worker.dependency "log-sender" manifold worker returned unexpected error: sending log message: websocket: close 1005 (no status): websocket: close sent
unit-postgresql-2: 01:47:50 ERROR juju.worker.dependency "log-sender" manifold worker returned unexpected error: sending log message: websocket: close 1005 (no status): websocket: close sent
unit-postgresql-3: 01:47:50 ERROR juju.worker.dependency "log-sender" manifold worker returned unexpected error: sending log message: websocket: close 1005 (no status): websocket: close sent
machine-2: 01:50:06 ERROR juju.worker.dependency "log-sender" manifold worker returned unexpected error: sending log message: websocket: close 1005 (no status): websocket: close sent
machine-0: 01:50:06 ERROR juju.worker.dependency "log-sender" manifold worker returned unexpected error: sending log message: websocket: close 1005 (no status): websocket: close sent
machine-4: 01:50:06 ERROR juju.worker.dependency "log-sender" manifold worker returned unexpected error: sending log message: websocket: close 1005 (no status): websocket: close sent
machine-3: 01:50:06 ERROR juju.worker.dependency "log-sender" manifold worker returned unexpected error: sending log message: websocket: close 1005 (no status): websocket: close sent
unit-postgresql-test-app-0: 01:50:21 ERROR juju.worker.dependency "log-sender" manifold worker returned unexpected error: sending log message: websocket: close 1005 (no status): websocket: close sent
unit-postgresql-0: 01:50:22 ERROR juju.worker.dependency "log-sender" manifold worker returned unexpected error: sending log message: websocket: close 1005 (no status): websocket: close sent
unit-postgresql-3: 02:00:36 ERROR juju.worker.dependency "log-sender" manifold worker returned unexpected error: sending log message: websocket: close 1005 (no status): websocket: close sent
unit-postgresql-2: 02:02:45 ERROR juju.worker.dependency "log-sender" manifold worker returned unexpected error: sending log message: websocket: close 1005 (no status): websocket: close sent
unit-postgresql-0: 02:06:40 ERROR juju.worker.dependency "log-sender" manifold worker returned unexpected error: sending log message: websocket: close 1005 (no status): websocket: close sent
unit-postgresql-test-app-0: 02:06:44 ERROR juju.worker.dependency "log-sender" manifold worker returned unexpected error: sending log message: websocket: close 1005 (no status): websocket: close sent
machine-4: 02:09:42 ERROR juju.worker.dependency "api-caller" manifold worker returned unexpected error: api connection broken unexpectedly
machine-4: 02:09:45 ERROR juju.worker.dependency "api-caller" manifold worker returned unexpected error: [524767] "machine-4" cannot open api: unable to connect to API: dial tcp 10.21.124.32:17070: connect: network is unreachable
machine-4: 02:09:48 ERROR juju.worker.dependency "api-caller" manifold worker returned unexpected error: [524767] "machine-4" cannot open api: unable to connect to API: dial tcp 10.21.124.32:17070: connect: network is unreachable
machine-4: 02:09:53 ERROR juju.worker.dependency "api-caller" manifold worker returned unexpected error: [524767] "machine-4" cannot open api: unable to connect to API: dial tcp 10.21.124.32:17070: connect: network is unreachable
machine-4: 02:09:58 ERROR juju.worker.dependency "api-caller" manifold worker returned unexpected error: [524767] "machine-4" cannot open api: unable to connect to API: dial tcp 10.21.124.32:17070: connect: network is unreachable
unit-postgresql-0: 02:11:43 ERROR juju.worker.dependency "log-sender" manifold worker returned unexpected error: sending log message: websocket: close 1005 (no status): websocket: close sent
unit-postgresql-3: 02:19:46 ERROR juju.worker.dependency "log-sender" manifold worker returned unexpected error: sending log message: websocket: close 1005 (no status): websocket: close sent
unit-postgresql-2: 02:19:52 ERROR juju.worker.dependency "log-sender" manifold worker returned unexpected error: sending log message: websocket: close 1005 (no status): websocket: close sent
unit-postgresql-test-app-0: 02:25:49 ERROR juju.worker.dependency "log-sender" manifold worker returned unexpected error: sending log message: websocket: close 1005 (no status): websocket: close sent
unit-postgresql-test-app-0: 02:25:49 ERROR unit.postgresql-test-app/0.juju-log Uncaught exception while in charm code:
Traceback (most recent call last):
  File "/var/lib/juju/agents/unit-postgresql-test-app-0/charm/src/charm.py", line 579, in <module>
    main(ApplicationCharm)
  File "/var/lib/juju/agents/unit-postgresql-test-app-0/charm/venv/lib/python3.10/site-packages/ops/__init__.py", line 356, in __call__
    return _main.main(charm_class=charm_class, use_juju_for_storage=use_juju_for_storage)
  File "/var/lib/juju/agents/unit-postgresql-test-app-0/charm/venv/lib/python3.10/site-packages/ops/_main.py", line 504, in main
    manager.run()
  File "/var/lib/juju/agents/unit-postgresql-test-app-0/charm/venv/lib/python3.10/site-packages/ops/_main.py", line 488, in run
    self._emit()
  File "/var/lib/juju/agents/unit-postgresql-test-app-0/charm/venv/lib/python3.10/site-packages/ops/_main.py", line 423, in _emit
    self._emit_charm_event(self.dispatcher.event_name)
  File "/var/lib/juju/agents/unit-postgresql-test-app-0/charm/venv/lib/python3.10/site-packages/ops/_main.py", line 467, in _emit_charm_event
    event_to_emit.emit(*args, **kwargs)
  File "/var/lib/juju/agents/unit-postgresql-test-app-0/charm/venv/lib/python3.10/site-packages/ops/framework.py", line 351, in emit
    framework._emit(event)
  File "/var/lib/juju/agents/unit-postgresql-test-app-0/charm/venv/lib/python3.10/site-packages/ops/framework.py", line 924, in _emit
    self._reemit(event_path)
  File "/var/lib/juju/agents/unit-postgresql-test-app-0/charm/venv/lib/python3.10/site-packages/ops/framework.py", line 1030, in _reemit
    custom_handler(event)
  File "/var/lib/juju/agents/unit-postgresql-test-app-0/charm/src/charm.py", line 343, in _on_clear_continuous_writes_action
    connection.close()
UnboundLocalError: local variable 'connection' referenced before assignment
unit-postgresql-test-app-0: 02:25:53 ERROR unit.postgresql-test-app/0.juju-log Unable to drop table
Traceback (most recent call last):
  File "/var/lib/juju/agents/unit-postgresql-test-app-0/charm/src/charm.py", line 334, in _on_clear_continuous_writes_action
    psycopg2.connect(self._connection_string) as connection,
  File "/var/lib/juju/agents/unit-postgresql-test-app-0/charm/venv/lib/python3.10/site-packages/psycopg2/__init__.py", line 122, in connect
    conn = _connect(dsn, connection_factory=connection_factory, **kwasync)
psycopg2.OperationalError: connection to server at "10.21.124.117", port 5432 failed: FATAL:  no pg_hba.conf entry for host "10.21.124.42", user "relation-4", database "postgresql_test_app_database", no encryption

unit-postgresql-test-app-0: 02:25:53 ERROR unit.postgresql-test-app/0.juju-log Uncaught exception while in charm code:
Traceback (most recent call last):
  File "/var/lib/juju/agents/unit-postgresql-test-app-0/charm/src/charm.py", line 579, in <module>
    main(ApplicationCharm)
  File "/var/lib/juju/agents/unit-postgresql-test-app-0/charm/venv/lib/python3.10/site-packages/ops/__init__.py", line 356, in __call__
    return _main.main(charm_class=charm_class, use_juju_for_storage=use_juju_for_storage)
  File "/var/lib/juju/agents/unit-postgresql-test-app-0/charm/venv/lib/python3.10/site-packages/ops/_main.py", line 504, in main
    manager.run()
  File "/var/lib/juju/agents/unit-postgresql-test-app-0/charm/venv/lib/python3.10/site-packages/ops/_main.py", line 488, in run
    self._emit()
  File "/var/lib/juju/agents/unit-postgresql-test-app-0/charm/venv/lib/python3.10/site-packages/ops/_main.py", line 423, in _emit
    self._emit_charm_event(self.dispatcher.event_name)
  File "/var/lib/juju/agents/unit-postgresql-test-app-0/charm/venv/lib/python3.10/site-packages/ops/_main.py", line 467, in _emit_charm_event
    event_to_emit.emit(*args, **kwargs)
  File "/var/lib/juju/agents/unit-postgresql-test-app-0/charm/venv/lib/python3.10/site-packages/ops/framework.py", line 351, in emit
    framework._emit(event)
  File "/var/lib/juju/agents/unit-postgresql-test-app-0/charm/venv/lib/python3.10/site-packages/ops/framework.py", line 924, in _emit
    self._reemit(event_path)
  File "/var/lib/juju/agents/unit-postgresql-test-app-0/charm/venv/lib/python3.10/site-packages/ops/framework.py", line 1030, in _reemit
    custom_handler(event)
  File "/var/lib/juju/agents/unit-postgresql-test-app-0/charm/src/charm.py", line 343, in _on_clear_continuous_writes_action
    connection.close()
UnboundLocalError: local variable 'connection' referenced before assignment
unit-postgresql-test-app-0: 02:25:57 ERROR unit.postgresql-test-app/0.juju-log Unable to drop table
Traceback (most recent call last):
  File "/var/lib/juju/agents/unit-postgresql-test-app-0/charm/src/charm.py", line 334, in _on_clear_continuous_writes_action
    psycopg2.connect(self._connection_string) as connection,
  File "/var/lib/juju/agents/unit-postgresql-test-app-0/charm/venv/lib/python3.10/site-packages/psycopg2/__init__.py", line 122, in connect
    conn = _connect(dsn, connection_factory=connection_factory, **kwasync)
psycopg2.OperationalError: connection to server at "10.21.124.117", port 5432 failed: FATAL:  no pg_hba.conf entry for host "10.21.124.42", user "relation-4", database "postgresql_test_app_database", no encryption

unit-postgresql-test-app-0: 02:25:57 ERROR unit.postgresql-test-app/0.juju-log Uncaught exception while in charm code:
Traceback (most recent call last):
  File "/var/lib/juju/agents/unit-postgresql-test-app-0/charm/src/charm.py", line 579, in <module>
    main(ApplicationCharm)
  File "/var/lib/juju/agents/unit-postgresql-test-app-0/charm/venv/lib/python3.10/site-packages/ops/__init__.py", line 356, in __call__
    return _main.main(charm_class=charm_class, use_juju_for_storage=use_juju_for_storage)
  File "/var/lib/juju/agents/unit-postgresql-test-app-0/charm/venv/lib/python3.10/site-packages/ops/_main.py", line 504, in main
    manager.run()
  File "/var/lib/juju/agents/unit-postgresql-test-app-0/charm/venv/lib/python3.10/site-packages/ops/_main.py", line 488, in run
    self._emit()
  File "/var/lib/juju/agents/unit-postgresql-test-app-0/charm/venv/lib/python3.10/site-packages/ops/_main.py", line 423, in _emit
    self._emit_charm_event(self.dispatcher.event_name)
  File "/var/lib/juju/agents/unit-postgresql-test-app-0/charm/venv/lib/python3.10/site-packages/ops/_main.py", line 467, in _emit_charm_event
    event_to_emit.emit(*args, **kwargs)
  File "/var/lib/juju/agents/unit-postgresql-test-app-0/charm/venv/lib/python3.10/site-packages/ops/framework.py", line 351, in emit
    framework._emit(event)
  File "/var/lib/juju/agents/unit-postgresql-test-app-0/charm/venv/lib/python3.10/site-packages/ops/framework.py", line 924, in _emit
    self._reemit(event_path)
  File "/var/lib/juju/agents/unit-postgresql-test-app-0/charm/venv/lib/python3.10/site-packages/ops/framework.py", line 1030, in _reemit
    custom_handler(event)
  File "/var/lib/juju/agents/unit-postgresql-test-app-0/charm/src/charm.py", line 343, in _on_clear_continuous_writes_action
    connection.close()
UnboundLocalError: local variable 'connection' referenced before assignment
unit-postgresql-test-app-0: 02:26:01 ERROR unit.postgresql-test-app/0.juju-log Unable to drop table
Traceback (most recent call last):
  File "/var/lib/juju/agents/unit-postgresql-test-app-0/charm/src/charm.py", line 334, in _on_clear_continuous_writes_action
    psycopg2.connect(self._connection_string) as connection,
  File "/var/lib/juju/agents/unit-postgresql-test-app-0/charm/venv/lib/python3.10/site-packages/psycopg2/__init__.py", line 122, in connect
    conn = _connect(dsn, connection_factory=connection_factory, **kwasync)
psycopg2.OperationalError: connection to server at "10.21.124.117", port 5432 failed: FATAL:  no pg_hba.conf entry for host "10.21.124.42", user "relation-4", database "postgresql_test_app_database", no encryption

unit-postgresql-test-app-0: 02:26:01 ERROR unit.postgresql-test-app/0.juju-log Uncaught exception while in charm code:
Traceback (most recent call last):
  File "/var/lib/juju/agents/unit-postgresql-test-app-0/charm/src/charm.py", line 579, in <module>
    main(ApplicationCharm)
  File "/var/lib/juju/agents/unit-postgresql-test-app-0/charm/venv/lib/python3.10/site-packages/ops/__init__.py", line 356, in __call__
    return _main.main(charm_class=charm_class, use_juju_for_storage=use_juju_for_storage)
  File "/var/lib/juju/agents/unit-postgresql-test-app-0/charm/venv/lib/python3.10/site-packages/ops/_main.py", line 504, in main
    manager.run()
  File "/var/lib/juju/agents/unit-postgresql-test-app-0/charm/venv/lib/python3.10/site-packages/ops/_main.py", line 488, in run
    self._emit()
  File "/var/lib/juju/agents/unit-postgresql-test-app-0/charm/venv/lib/python3.10/site-packages/ops/_main.py", line 423, in _emit
    self._emit_charm_event(self.dispatcher.event_name)
  File "/var/lib/juju/agents/unit-postgresql-test-app-0/charm/venv/lib/python3.10/site-packages/ops/_main.py", line 467, in _emit_charm_event
    event_to_emit.emit(*args, **kwargs)
  File "/var/lib/juju/agents/unit-postgresql-test-app-0/charm/venv/lib/python3.10/site-packages/ops/framework.py", line 351, in emit
    framework._emit(event)
  File "/var/lib/juju/agents/unit-postgresql-test-app-0/charm/venv/lib/python3.10/site-packages/ops/framework.py", line 924, in _emit
    self._reemit(event_path)
  File "/var/lib/juju/agents/unit-postgresql-test-app-0/charm/venv/lib/python3.10/site-packages/ops/framework.py", line 1030, in _reemit
    custom_handler(event)
  File "/var/lib/juju/agents/unit-postgresql-test-app-0/charm/src/charm.py", line 343, in _on_clear_continuous_writes_action
    connection.close()
UnboundLocalError: local variable 'connection' referenced before assignment
unit-postgresql-test-app-0: 02:26:05 ERROR unit.postgresql-test-app/0.juju-log Unable to drop table
Traceback (most recent call last):
  File "/var/lib/juju/agents/unit-postgresql-test-app-0/charm/src/charm.py", line 334, in _on_clear_continuous_writes_action
    psycopg2.connect(self._connection_string) as connection,
  File "/var/lib/juju/agents/unit-postgresql-test-app-0/charm/venv/lib/python3.10/site-packages/psycopg2/__init__.py", line 122, in connect
    conn = _connect(dsn, connection_factory=connection_factory, **kwasync)
psycopg2.OperationalError: connection to server at "10.21.124.117", port 5432 failed: FATAL:  no pg_hba.conf entry for host "10.21.124.42", user "relation-4", database "postgresql_test_app_database", no encryption

unit-postgresql-test-app-0: 02:26:05 ERROR unit.postgresql-test-app/0.juju-log Uncaught exception while in charm code:
Traceback (most recent call last):
  File "/var/lib/juju/agents/unit-postgresql-test-app-0/charm/src/charm.py", line 579, in <module>
    main(ApplicationCharm)
  File "/var/lib/juju/agents/unit-postgresql-test-app-0/charm/venv/lib/python3.10/site-packages/ops/__init__.py", line 356, in __call__
    return _main.main(charm_class=charm_class, use_juju_for_storage=use_juju_for_storage)
  File "/var/lib/juju/agents/unit-postgresql-test-app-0/charm/venv/lib/python3.10/site-packages/ops/_main.py", line 504, in main
    manager.run()
  File "/var/lib/juju/agents/unit-postgresql-test-app-0/charm/venv/lib/python3.10/site-packages/ops/_main.py", line 488, in run
    self._emit()
  File "/var/lib/juju/agents/unit-postgresql-test-app-0/charm/venv/lib/python3.10/site-packages/ops/_main.py", line 423, in _emit
    self._emit_charm_event(self.dispatcher.event_name)
  File "/var/lib/juju/agents/unit-postgresql-test-app-0/charm/venv/lib/python3.10/site-packages/ops/_main.py", line 467, in _emit_charm_event
    event_to_emit.emit(*args, **kwargs)
  File "/var/lib/juju/agents/unit-postgresql-test-app-0/charm/venv/lib/python3.10/site-packages/ops/framework.py", line 351, in emit
    framework._emit(event)
  File "/var/lib/juju/agents/unit-postgresql-test-app-0/charm/venv/lib/python3.10/site-packages/ops/framework.py", line 924, in _emit
    self._reemit(event_path)
  File "/var/lib/juju/agents/unit-postgresql-test-app-0/charm/venv/lib/python3.10/site-packages/ops/framework.py", line 1030, in _reemit
    custom_handler(event)
  File "/var/lib/juju/agents/unit-postgresql-test-app-0/charm/src/charm.py", line 343, in _on_clear_continuous_writes_action
    connection.close()
UnboundLocalError: local variable 'connection' referenced before assignment
unit-postgresql-test-app-0: 02:26:09 ERROR unit.postgresql-test-app/0.juju-log Unable to drop table
Traceback (most recent call last):
  File "/var/lib/juju/agents/unit-postgresql-test-app-0/charm/src/charm.py", line 334, in _on_clear_continuous_writes_action
    psycopg2.connect(self._connection_string) as connection,
  File "/var/lib/juju/agents/unit-postgresql-test-app-0/charm/venv/lib/python3.10/site-packages/psycopg2/__init__.py", line 122, in connect
    conn = _connect(dsn, connection_factory=connection_factory, **kwasync)
psycopg2.OperationalError: connection to server at "10.21.124.117", port 5432 failed: FATAL:  no pg_hba.conf entry for host "10.21.124.42", user "relation-4", database "postgresql_test_app_database", no encryption

unit-postgresql-test-app-0: 02:26:09 ERROR unit.postgresql-test-app/0.juju-log Uncaught exception while in charm code:
Traceback (most recent call last):
  File "/var/lib/juju/agents/unit-postgresql-test-app-0/charm/src/charm.py", line 579, in <module>
    main(ApplicationCharm)
  File "/var/lib/juju/agents/unit-postgresql-test-app-0/charm/venv/lib/python3.10/site-packages/ops/__init__.py", line 356, in __call__
    return _main.main(charm_class=charm_class, use_juju_for_storage=use_juju_for_storage)
  File "/var/lib/juju/agents/unit-postgresql-test-app-0/charm/venv/lib/python3.10/site-packages/ops/_main.py", line 504, in main
    manager.run()
  File "/var/lib/juju/agents/unit-postgresql-test-app-0/charm/venv/lib/python3.10/site-packages/ops/_main.py", line 488, in run
    self._emit()
  File "/var/lib/juju/agents/unit-postgresql-test-app-0/charm/venv/lib/python3.10/site-packages/ops/_main.py", line 423, in _emit
    self._emit_charm_event(self.dispatcher.event_name)
  File "/var/lib/juju/agents/unit-postgresql-test-app-0/charm/venv/lib/python3.10/site-packages/ops/_main.py", line 467, in _emit_charm_event
    event_to_emit.emit(*args, **kwargs)
  File "/var/lib/juju/agents/unit-postgresql-test-app-0/charm/venv/lib/python3.10/site-packages/ops/framework.py", line 351, in emit
    framework._emit(event)
  File "/var/lib/juju/agents/unit-postgresql-test-app-0/charm/venv/lib/python3.10/site-packages/ops/framework.py", line 924, in _emit
    self._reemit(event_path)
  File "/var/lib/juju/agents/unit-postgresql-test-app-0/charm/venv/lib/python3.10/site-packages/ops/framework.py", line 1030, in _reemit
    custom_handler(event)
  File "/var/lib/juju/agents/unit-postgresql-test-app-0/charm/src/charm.py", line 343, in _on_clear_continuous_writes_action
    connection.close()
UnboundLocalError: local variable 'connection' referenced before assignment
unit-postgresql-test-app-0: 02:26:13 ERROR unit.postgresql-test-app/0.juju-log Unable to drop table
Traceback (most recent call last):
  File "/var/lib/juju/agents/unit-postgresql-test-app-0/charm/src/charm.py", line 334, in _on_clear_continuous_writes_action
    psycopg2.connect(self._connection_string) as connection,
  File "/var/lib/juju/agents/unit-postgresql-test-app-0/charm/venv/lib/python3.10/site-packages/psycopg2/__init__.py", line 122, in connect
    conn = _connect(dsn, connection_factory=connection_factory, **kwasync)
psycopg2.OperationalError: connection to server at "10.21.124.117", port 5432 failed: FATAL:  no pg_hba.conf entry for host "10.21.124.42", user "relation-4", database "postgresql_test_app_database", no encryption

unit-postgresql-test-app-0: 02:26:13 ERROR unit.postgresql-test-app/0.juju-log Uncaught exception while in charm code:
Traceback (most recent call last):
  File "/var/lib/juju/agents/unit-postgresql-test-app-0/charm/src/charm.py", line 579, in <module>
    main(ApplicationCharm)
  File "/var/lib/juju/agents/unit-postgresql-test-app-0/charm/venv/lib/python3.10/site-packages/ops/__init__.py", line 356, in __call__
    return _main.main(charm_class=charm_class, use_juju_for_storage=use_juju_for_storage)
  File "/var/lib/juju/agents/unit-postgresql-test-app-0/charm/venv/lib/python3.10/site-packages/ops/_main.py", line 504, in main
    manager.run()
  File "/var/lib/juju/agents/unit-postgresql-test-app-0/charm/venv/lib/python3.10/site-packages/ops/_main.py", line 488, in run
    self._emit()
  File "/var/lib/juju/agents/unit-postgresql-test-app-0/charm/venv/lib/python3.10/site-packages/ops/_main.py", line 423, in _emit
    self._emit_charm_event(self.dispatcher.event_name)
  File "/var/lib/juju/agents/unit-postgresql-test-app-0/charm/venv/lib/python3.10/site-packages/ops/_main.py", line 467, in _emit_charm_event
    event_to_emit.emit(*args, **kwargs)
  File "/var/lib/juju/agents/unit-postgresql-test-app-0/charm/venv/lib/python3.10/site-packages/ops/framework.py", line 351, in emit
    framework._emit(event)
  File "/var/lib/juju/agents/unit-postgresql-test-app-0/charm/venv/lib/python3.10/site-packages/ops/framework.py", line 924, in _emit
    self._reemit(event_path)
  File "/var/lib/juju/agents/unit-postgresql-test-app-0/charm/venv/lib/python3.10/site-packages/ops/framework.py", line 1030, in _reemit
    custom_handler(event)
  File "/var/lib/juju/agents/unit-postgresql-test-app-0/charm/src/charm.py", line 343, in _on_clear_continuous_writes_action
    connection.close()
UnboundLocalError: local variable 'connection' referenced before assignment
unit-postgresql-test-app-0: 02:26:17 ERROR unit.postgresql-test-app/0.juju-log Unable to drop table
Traceback (most recent call last):
  File "/var/lib/juju/agents/unit-postgresql-test-app-0/charm/src/charm.py", line 334, in _on_clear_continuous_writes_action
    psycopg2.connect(self._connection_string) as connection,
  File "/var/lib/juju/agents/unit-postgresql-test-app-0/charm/venv/lib/python3.10/site-packages/psycopg2/__init__.py", line 122, in connect
    conn = _connect(dsn, connection_factory=connection_factory, **kwasync)
psycopg2.OperationalError: connection to server at "10.21.124.117", port 5432 failed: FATAL:  no pg_hba.conf entry for host "10.21.124.42", user "relation-4", database "postgresql_test_app_database", no encryption

unit-postgresql-test-app-0: 02:26:17 ERROR unit.postgresql-test-app/0.juju-log Uncaught exception while in charm code:
Traceback (most recent call last):
  File "/var/lib/juju/agents/unit-postgresql-test-app-0/charm/src/charm.py", line 579, in <module>
    main(ApplicationCharm)
  File "/var/lib/juju/agents/unit-postgresql-test-app-0/charm/venv/lib/python3.10/site-packages/ops/__init__.py", line 356, in __call__
    return _main.main(charm_class=charm_class, use_juju_for_storage=use_juju_for_storage)
  File "/var/lib/juju/agents/unit-postgresql-test-app-0/charm/venv/lib/python3.10/site-packages/ops/_main.py", line 504, in main
    manager.run()
  File "/var/lib/juju/agents/unit-postgresql-test-app-0/charm/venv/lib/python3.10/site-packages/ops/_main.py", line 488, in run
    self._emit()
  File "/var/lib/juju/agents/unit-postgresql-test-app-0/charm/venv/lib/python3.10/site-packages/ops/_main.py", line 423, in _emit
    self._emit_charm_event(self.dispatcher.event_name)
  File "/var/lib/juju/agents/unit-postgresql-test-app-0/charm/venv/lib/python3.10/site-packages/ops/_main.py", line 467, in _emit_charm_event
    event_to_emit.emit(*args, **kwargs)
  File "/var/lib/juju/agents/unit-postgresql-test-app-0/charm/venv/lib/python3.10/site-packages/ops/framework.py", line 351, in emit
    framework._emit(event)
  File "/var/lib/juju/agents/unit-postgresql-test-app-0/charm/venv/lib/python3.10/site-packages/ops/framework.py", line 924, in _emit
    self._reemit(event_path)
  File "/var/lib/juju/agents/unit-postgresql-test-app-0/charm/venv/lib/python3.10/site-packages/ops/framework.py", line 1030, in _reemit
    custom_handler(event)
  File "/var/lib/juju/agents/unit-postgresql-test-app-0/charm/src/charm.py", line 343, in _on_clear_continuous_writes_action
    connection.close()
UnboundLocalError: local variable 'connection' referenced before assignment
unit-postgresql-test-app-0: 02:26:21 ERROR unit.postgresql-test-app/0.juju-log Unable to drop table
Traceback (most recent call last):
  File "/var/lib/juju/agents/unit-postgresql-test-app-0/charm/src/charm.py", line 334, in _on_clear_continuous_writes_action
    psycopg2.connect(self._connection_string) as connection,
  File "/var/lib/juju/agents/unit-postgresql-test-app-0/charm/venv/lib/python3.10/site-packages/psycopg2/__init__.py", line 122, in connect
    conn = _connect(dsn, connection_factory=connection_factory, **kwasync)
psycopg2.OperationalError: connection to server at "10.21.124.117", port 5432 failed: FATAL:  no pg_hba.conf entry for host "10.21.124.42", user "relation-4", database "postgresql_test_app_database", no encryption

unit-postgresql-test-app-0: 02:26:21 ERROR unit.postgresql-test-app/0.juju-log Uncaught exception while in charm code:
Traceback (most recent call last):
  File "/var/lib/juju/agents/unit-postgresql-test-app-0/charm/src/charm.py", line 579, in <module>
    main(ApplicationCharm)
  File "/var/lib/juju/agents/unit-postgresql-test-app-0/charm/venv/lib/python3.10/site-packages/ops/__init__.py", line 356, in __call__
    return _main.main(charm_class=charm_class, use_juju_for_storage=use_juju_for_storage)
  File "/var/lib/juju/agents/unit-postgresql-test-app-0/charm/venv/lib/python3.10/site-packages/ops/_main.py", line 504, in main
    manager.run()
  File "/var/lib/juju/agents/unit-postgresql-test-app-0/charm/venv/lib/python3.10/site-packages/ops/_main.py", line 488, in run
    self._emit()
  File "/var/lib/juju/agents/unit-postgresql-test-app-0/charm/venv/lib/python3.10/site-packages/ops/_main.py", line 423, in _emit
    self._emit_charm_event(self.dispatcher.event_name)
  File "/var/lib/juju/agents/unit-postgresql-test-app-0/charm/venv/lib/python3.10/site-packages/ops/_main.py", line 467, in _emit_charm_event
    event_to_emit.emit(*args, **kwargs)
  File "/var/lib/juju/agents/unit-postgresql-test-app-0/charm/venv/lib/python3.10/site-packages/ops/framework.py", line 351, in emit
    framework._emit(event)
  File "/var/lib/juju/agents/unit-postgresql-test-app-0/charm/venv/lib/python3.10/site-packages/ops/framework.py", line 924, in _emit
    self._reemit(event_path)
  File "/var/lib/juju/agents/unit-postgresql-test-app-0/charm/venv/lib/python3.10/site-packages/ops/framework.py", line 1030, in _reemit
    custom_handler(event)
  File "/var/lib/juju/agents/unit-postgresql-test-app-0/charm/src/charm.py", line 343, in _on_clear_continuous_writes_action
    connection.close()
UnboundLocalError: local variable 'connection' referenced before assignment
unit-postgresql-test-app-0: 02:26:25 ERROR unit.postgresql-test-app/0.juju-log Unable to drop table
Traceback (most recent call last):
  File "/var/lib/juju/agents/unit-postgresql-test-app-0/charm/src/charm.py", line 334, in _on_clear_continuous_writes_action
    psycopg2.connect(self._connection_string) as connection,
  File "/var/lib/juju/agents/unit-postgresql-test-app-0/charm/venv/lib/python3.10/site-packages/psycopg2/__init__.py", line 122, in connect
    conn = _connect(dsn, connection_factory=connection_factory, **kwasync)
psycopg2.OperationalError: connection to server at "10.21.124.117", port 5432 failed: FATAL:  no pg_hba.conf entry for host "10.21.124.42", user "relation-4", database "postgresql_test_app_database", no encryption

unit-postgresql-test-app-0: 02:26:25 ERROR unit.postgresql-test-app/0.juju-log Uncaught exception while in charm code:
Traceback (most recent call last):
  File "/var/lib/juju/agents/unit-postgresql-test-app-0/charm/src/charm.py", line 579, in <module>
    main(ApplicationCharm)
  File "/var/lib/juju/agents/unit-postgresql-test-app-0/charm/venv/lib/python3.10/site-packages/ops/__init__.py", line 356, in __call__
    return _main.main(charm_class=charm_class, use_juju_for_storage=use_juju_for_storage)
  File "/var/lib/juju/agents/unit-postgresql-test-app-0/charm/venv/lib/python3.10/site-packages/ops/_main.py", line 504, in main
    manager.run()
  File "/var/lib/juju/agents/unit-postgresql-test-app-0/charm/venv/lib/python3.10/site-packages/ops/_main.py", line 488, in run
    self._emit()
  File "/var/lib/juju/agents/unit-postgresql-test-app-0/charm/venv/lib/python3.10/site-packages/ops/_main.py", line 423, in _emit
    self._emit_charm_event(self.dispatcher.event_name)
  File "/var/lib/juju/agents/unit-postgresql-test-app-0/charm/venv/lib/python3.10/site-packages/ops/_main.py", line 467, in _emit_charm_event
    event_to_emit.emit(*args, **kwargs)
  File "/var/lib/juju/agents/unit-postgresql-test-app-0/charm/venv/lib/python3.10/site-packages/ops/framework.py", line 351, in emit
    framework._emit(event)
  File "/var/lib/juju/agents/unit-postgresql-test-app-0/charm/venv/lib/python3.10/site-packages/ops/framework.py", line 924, in _emit
    self._reemit(event_path)
  File "/var/lib/juju/agents/unit-postgresql-test-app-0/charm/venv/lib/python3.10/site-packages/ops/framework.py", line 1030, in _reemit
    custom_handler(event)
  File "/var/lib/juju/agents/unit-postgresql-test-app-0/charm/src/charm.py", line 343, in _on_clear_continuous_writes_action
    connection.close()
UnboundLocalError: local variable 'connection' referenced before assignment
unit-postgresql-test-app-0: 02:26:29 ERROR unit.postgresql-test-app/0.juju-log Unable to drop table
Traceback (most recent call last):
  File "/var/lib/juju/agents/unit-postgresql-test-app-0/charm/src/charm.py", line 334, in _on_clear_continuous_writes_action
    psycopg2.connect(self._connection_string) as connection,
  File "/var/lib/juju/agents/unit-postgresql-test-app-0/charm/venv/lib/python3.10/site-packages/psycopg2/__init__.py", line 122, in connect
    conn = _connect(dsn, connection_factory=connection_factory, **kwasync)
psycopg2.OperationalError: connection to server at "10.21.124.117", port 5432 failed: FATAL:  no pg_hba.conf entry for host "10.21.124.42", user "relation-4", database "postgresql_test_app_database", no encryption

unit-postgresql-test-app-0: 02:26:29 ERROR unit.postgresql-test-app/0.juju-log Uncaught exception while in charm code:
Traceback (most recent call last):
  File "/var/lib/juju/agents/unit-postgresql-test-app-0/charm/src/charm.py", line 579, in <module>
    main(ApplicationCharm)
  File "/var/lib/juju/agents/unit-postgresql-test-app-0/charm/venv/lib/python3.10/site-packages/ops/__init__.py", line 356, in __call__
    return _main.main(charm_class=charm_class, use_juju_for_storage=use_juju_for_storage)
  File "/var/lib/juju/agents/unit-postgresql-test-app-0/charm/venv/lib/python3.10/site-packages/ops/_main.py", line 504, in main
    manager.run()
  File "/var/lib/juju/agents/unit-postgresql-test-app-0/charm/venv/lib/python3.10/site-packages/ops/_main.py", line 488, in run
    self._emit()
  File "/var/lib/juju/agents/unit-postgresql-test-app-0/charm/venv/lib/python3.10/site-packages/ops/_main.py", line 423, in _emit
    self._emit_charm_event(self.dispatcher.event_name)
  File "/var/lib/juju/agents/unit-postgresql-test-app-0/charm/venv/lib/python3.10/site-packages/ops/_main.py", line 467, in _emit_charm_event
    event_to_emit.emit(*args, **kwargs)
  File "/var/lib/juju/agents/unit-postgresql-test-app-0/charm/venv/lib/python3.10/site-packages/ops/framework.py", line 351, in emit
    framework._emit(event)
  File "/var/lib/juju/agents/unit-postgresql-test-app-0/charm/venv/lib/python3.10/site-packages/ops/framework.py", line 924, in _emit
    self._reemit(event_path)
  File "/var/lib/juju/agents/unit-postgresql-test-app-0/charm/venv/lib/python3.10/site-packages/ops/framework.py", line 1030, in _reemit
    custom_handler(event)
  File "/var/lib/juju/agents/unit-postgresql-test-app-0/charm/src/charm.py", line 343, in _on_clear_continuous_writes_action
    connection.close()
UnboundLocalError: local variable 'connection' referenced before assignment
unit-postgresql-test-app-0: 02:26:33 ERROR unit.postgresql-test-app/0.juju-log Unable to drop table
Traceback (most recent call last):
  File "/var/lib/juju/agents/unit-postgresql-test-app-0/charm/src/charm.py", line 334, in _on_clear_continuous_writes_action
    psycopg2.connect(self._connection_string) as connection,
  File "/var/lib/juju/agents/unit-postgresql-test-app-0/charm/venv/lib/python3.10/site-packages/psycopg2/__init__.py", line 122, in connect
    conn = _connect(dsn, connection_factory=connection_factory, **kwasync)
psycopg2.OperationalError: connection to server at "10.21.124.117", port 5432 failed: FATAL:  no pg_hba.conf entry for host "10.21.124.42", user "relation-4", database "postgresql_test_app_database", no encryption

unit-postgresql-test-app-0: 02:26:33 ERROR unit.postgresql-test-app/0.juju-log Uncaught exception while in charm code:
Traceback (most recent call last):
  File "/var/lib/juju/agents/unit-postgresql-test-app-0/charm/src/charm.py", line 579, in <module>
    main(ApplicationCharm)
  File "/var/lib/juju/agents/unit-postgresql-test-app-0/charm/venv/lib/python3.10/site-packages/ops/__init__.py", line 356, in __call__
    return _main.main(charm_class=charm_class, use_juju_for_storage=use_juju_for_storage)
  File "/var/lib/juju/agents/unit-postgresql-test-app-0/charm/venv/lib/python3.10/site-packages/ops/_main.py", line 504, in main
    manager.run()
  File "/var/lib/juju/agents/unit-postgresql-test-app-0/charm/venv/lib/python3.10/site-packages/ops/_main.py", line 488, in run
    self._emit()
  File "/var/lib/juju/agents/unit-postgresql-test-app-0/charm/venv/lib/python3.10/site-packages/ops/_main.py", line 423, in _emit
    self._emit_charm_event(self.dispatcher.event_name)
  File "/var/lib/juju/agents/unit-postgresql-test-app-0/charm/venv/lib/python3.10/site-packages/ops/_main.py", line 467, in _emit_charm_event
    event_to_emit.emit(*args, **kwargs)
  File "/var/lib/juju/agents/unit-postgresql-test-app-0/charm/venv/lib/python3.10/site-packages/ops/framework.py", line 351, in emit
    framework._emit(event)
  File "/var/lib/juju/agents/unit-postgresql-test-app-0/charm/venv/lib/python3.10/site-packages/ops/framework.py", line 924, in _emit
    self._reemit(event_path)
  File "/var/lib/juju/agents/unit-postgresql-test-app-0/charm/venv/lib/python3.10/site-packages/ops/framework.py", line 1030, in _reemit
    custom_handler(event)
  File "/var/lib/juju/agents/unit-postgresql-test-app-0/charm/src/charm.py", line 343, in _on_clear_continuous_writes_action
    connection.close()
UnboundLocalError: local variable 'connection' referenced before assignment
unit-postgresql-test-app-0: 02:26:37 ERROR unit.postgresql-test-app/0.juju-log Unable to drop table
Traceback (most recent call last):
  File "/var/lib/juju/agents/unit-postgresql-test-app-0/charm/src/charm.py", line 334, in _on_clear_continuous_writes_action
    psycopg2.connect(self._connection_string) as connection,
  File "/var/lib/juju/agents/unit-postgresql-test-app-0/charm/venv/lib/python3.10/site-packages/psycopg2/__init__.py", line 122, in connect
    conn = _connect(dsn, connection_factory=connection_factory, **kwasync)
psycopg2.OperationalError: connection to server at "10.21.124.117", port 5432 failed: FATAL:  no pg_hba.conf entry for host "10.21.124.42", user "relation-4", database "postgresql_test_app_database", no encryption

unit-postgresql-test-app-0: 02:26:37 ERROR unit.postgresql-test-app/0.juju-log Uncaught exception while in charm code:
Traceback (most recent call last):
  File "/var/lib/juju/agents/unit-postgresql-test-app-0/charm/src/charm.py", line 579, in <module>
    main(ApplicationCharm)
  File "/var/lib/juju/agents/unit-postgresql-test-app-0/charm/venv/lib/python3.10/site-packages/ops/__init__.py", line 356, in __call__
    return _main.main(charm_class=charm_class, use_juju_for_storage=use_juju_for_storage)
  File "/var/lib/juju/agents/unit-postgresql-test-app-0/charm/venv/lib/python3.10/site-packages/ops/_main.py", line 504, in main
    manager.run()
  File "/var/lib/juju/agents/unit-postgresql-test-app-0/charm/venv/lib/python3.10/site-packages/ops/_main.py", line 488, in run
    self._emit()
  File "/var/lib/juju/agents/unit-postgresql-test-app-0/charm/venv/lib/python3.10/site-packages/ops/_main.py", line 423, in _emit
    self._emit_charm_event(self.dispatcher.event_name)
  File "/var/lib/juju/agents/unit-postgresql-test-app-0/charm/venv/lib/python3.10/site-packages/ops/_main.py", line 467, in _emit_charm_event
    event_to_emit.emit(*args, **kwargs)
  File "/var/lib/juju/agents/unit-postgresql-test-app-0/charm/venv/lib/python3.10/site-packages/ops/framework.py", line 351, in emit
    framework._emit(event)
  File "/var/lib/juju/agents/unit-postgresql-test-app-0/charm/venv/lib/python3.10/site-packages/ops/framework.py", line 924, in _emit
    self._reemit(event_path)
  File "/var/lib/juju/agents/unit-postgresql-test-app-0/charm/venv/lib/python3.10/site-packages/ops/framework.py", line 1030, in _reemit
    custom_handler(event)
  File "/var/lib/juju/agents/unit-postgresql-test-app-0/charm/src/charm.py", line 343, in _on_clear_continuous_writes_action
    connection.close()
UnboundLocalError: local variable 'connection' referenced before assignment
unit-postgresql-test-app-0: 02:26:41 ERROR unit.postgresql-test-app/0.juju-log Unable to drop table
Traceback (most recent call last):
  File "/var/lib/juju/agents/unit-postgresql-test-app-0/charm/src/charm.py", line 334, in _on_clear_continuous_writes_action
    psycopg2.connect(self._connection_string) as connection,
  File "/var/lib/juju/agents/unit-postgresql-test-app-0/charm/venv/lib/python3.10/site-packages/psycopg2/__init__.py", line 122, in connect
    conn = _connect(dsn, connection_factory=connection_factory, **kwasync)
psycopg2.OperationalError: connection to server at "10.21.124.117", port 5432 failed: FATAL:  no pg_hba.conf entry for host "10.21.124.42", user "relation-4", database "postgresql_test_app_database", no encryption

unit-postgresql-test-app-0: 02:26:41 ERROR unit.postgresql-test-app/0.juju-log Uncaught exception while in charm code:
Traceback (most recent call last):
  File "/var/lib/juju/agents/unit-postgresql-test-app-0/charm/src/charm.py", line 579, in <module>
    main(ApplicationCharm)
  File "/var/lib/juju/agents/unit-postgresql-test-app-0/charm/venv/lib/python3.10/site-packages/ops/__init__.py", line 356, in __call__
    return _main.main(charm_class=charm_class, use_juju_for_storage=use_juju_for_storage)
  File "/var/lib/juju/agents/unit-postgresql-test-app-0/charm/venv/lib/python3.10/site-packages/ops/_main.py", line 504, in main
    manager.run()
  File "/var/lib/juju/agents/unit-postgresql-test-app-0/charm/venv/lib/python3.10/site-packages/ops/_main.py", line 488, in run
    self._emit()
  File "/var/lib/juju/agents/unit-postgresql-test-app-0/charm/venv/lib/python3.10/site-packages/ops/_main.py", line 423, in _emit
    self._emit_charm_event(self.dispatcher.event_name)
  File "/var/lib/juju/agents/unit-postgresql-test-app-0/charm/venv/lib/python3.10/site-packages/ops/_main.py", line 467, in _emit_charm_event
    event_to_emit.emit(*args, **kwargs)
  File "/var/lib/juju/agents/unit-postgresql-test-app-0/charm/venv/lib/python3.10/site-packages/ops/framework.py", line 351, in emit
    framework._emit(event)
  File "/var/lib/juju/agents/unit-postgresql-test-app-0/charm/venv/lib/python3.10/site-packages/ops/framework.py", line 924, in _emit
    self._reemit(event_path)
  File "/var/lib/juju/agents/unit-postgresql-test-app-0/charm/venv/lib/python3.10/site-packages/ops/framework.py", line 1030, in _reemit
    custom_handler(event)
  File "/var/lib/juju/agents/unit-postgresql-test-app-0/charm/src/charm.py", line 343, in _on_clear_continuous_writes_action
    connection.close()
UnboundLocalError: local variable 'connection' referenced before assignment
unit-postgresql-test-app-0: 02:26:45 ERROR unit.postgresql-test-app/0.juju-log Unable to drop table
Traceback (most recent call last):
  File "/var/lib/juju/agents/unit-postgresql-test-app-0/charm/src/charm.py", line 334, in _on_clear_continuous_writes_action
    psycopg2.connect(self._connection_string) as connection,
  File "/var/lib/juju/agents/unit-postgresql-test-app-0/charm/venv/lib/python3.10/site-packages/psycopg2/__init__.py", line 122, in connect
    conn = _connect(dsn, connection_factory=connection_factory, **kwasync)
psycopg2.OperationalError: connection to server at "10.21.124.117", port 5432 failed: FATAL:  no pg_hba.conf entry for host "10.21.124.42", user "relation-4", database "postgresql_test_app_database", no encryption

unit-postgresql-test-app-0: 02:26:45 ERROR unit.postgresql-test-app/0.juju-log Uncaught exception while in charm code:
Traceback (most recent call last):
  File "/var/lib/juju/agents/unit-postgresql-test-app-0/charm/src/charm.py", line 579, in <module>
    main(ApplicationCharm)
  File "/var/lib/juju/agents/unit-postgresql-test-app-0/charm/venv/lib/python3.10/site-packages/ops/__init__.py", line 356, in __call__
    return _main.main(charm_class=charm_class, use_juju_for_storage=use_juju_for_storage)
  File "/var/lib/juju/agents/unit-postgresql-test-app-0/charm/venv/lib/python3.10/site-packages/ops/_main.py", line 504, in main
    manager.run()
  File "/var/lib/juju/agents/unit-postgresql-test-app-0/charm/venv/lib/python3.10/site-packages/ops/_main.py", line 488, in run
    self._emit()
  File "/var/lib/juju/agents/unit-postgresql-test-app-0/charm/venv/lib/python3.10/site-packages/ops/_main.py", line 423, in _emit
    self._emit_charm_event(self.dispatcher.event_name)
  File "/var/lib/juju/agents/unit-postgresql-test-app-0/charm/venv/lib/python3.10/site-packages/ops/_main.py", line 467, in _emit_charm_event
    event_to_emit.emit(*args, **kwargs)
  File "/var/lib/juju/agents/unit-postgresql-test-app-0/charm/venv/lib/python3.10/site-packages/ops/framework.py", line 351, in emit
    framework._emit(event)
  File "/var/lib/juju/agents/unit-postgresql-test-app-0/charm/venv/lib/python3.10/site-packages/ops/framework.py", line 924, in _emit
    self._reemit(event_path)
  File "/var/lib/juju/agents/unit-postgresql-test-app-0/charm/venv/lib/python3.10/site-packages/ops/framework.py", line 1030, in _reemit
    custom_handler(event)
  File "/var/lib/juju/agents/unit-postgresql-test-app-0/charm/src/charm.py", line 343, in _on_clear_continuous_writes_action
    connection.close()
UnboundLocalError: local variable 'connection' referenced before assignment
unit-postgresql-test-app-0: 02:26:49 ERROR unit.postgresql-test-app/0.juju-log Unable to drop table
Traceback (most recent call last):
  File "/var/lib/juju/agents/unit-postgresql-test-app-0/charm/src/charm.py", line 334, in _on_clear_continuous_writes_action
    psycopg2.connect(self._connection_string) as connection,
  File "/var/lib/juju/agents/unit-postgresql-test-app-0/charm/venv/lib/python3.10/site-packages/psycopg2/__init__.py", line 122, in connect
    conn = _connect(dsn, connection_factory=connection_factory, **kwasync)
psycopg2.OperationalError: connection to server at "10.21.124.117", port 5432 failed: FATAL:  no pg_hba.conf entry for host "10.21.124.42", user "relation-4", database "postgresql_test_app_database", no encryption

unit-postgresql-test-app-0: 02:26:49 ERROR unit.postgresql-test-app/0.juju-log Uncaught exception while in charm code:
Traceback (most recent call last):
  File "/var/lib/juju/agents/unit-postgresql-test-app-0/charm/src/charm.py", line 579, in <module>
    main(ApplicationCharm)
  File "/var/lib/juju/agents/unit-postgresql-test-app-0/charm/venv/lib/python3.10/site-packages/ops/__init__.py", line 356, in __call__
    return _main.main(charm_class=charm_class, use_juju_for_storage=use_juju_for_storage)
  File "/var/lib/juju/agents/unit-postgresql-test-app-0/charm/venv/lib/python3.10/site-packages/ops/_main.py", line 504, in main
    manager.run()
  File "/var/lib/juju/agents/unit-postgresql-test-app-0/charm/venv/lib/python3.10/site-packages/ops/_main.py", line 488, in run
    self._emit()
  File "/var/lib/juju/agents/unit-postgresql-test-app-0/charm/venv/lib/python3.10/site-packages/ops/_main.py", line 423, in _emit
    self._emit_charm_event(self.dispatcher.event_name)
  File "/var/lib/juju/agents/unit-postgresql-test-app-0/charm/venv/lib/python3.10/site-packages/ops/_main.py", line 467, in _emit_charm_event
    event_to_emit.emit(*args, **kwargs)
  File "/var/lib/juju/agents/unit-postgresql-test-app-0/charm/venv/lib/python3.10/site-packages/ops/framework.py", line 351, in emit
    framework._emit(event)
  File "/var/lib/juju/agents/unit-postgresql-test-app-0/charm/venv/lib/python3.10/site-packages/ops/framework.py", line 924, in _emit
    self._reemit(event_path)
  File "/var/lib/juju/agents/unit-postgresql-test-app-0/charm/venv/lib/python3.10/site-packages/ops/framework.py", line 1030, in _reemit
    custom_handler(event)
  File "/var/lib/juju/agents/unit-postgresql-test-app-0/charm/src/charm.py", line 343, in _on_clear_continuous_writes_action
    connection.close()
UnboundLocalError: local variable 'connection' referenced before assignment
unit-postgresql-test-app-0: 02:26:53 ERROR unit.postgresql-test-app/0.juju-log Unable to drop table
Traceback (most recent call last):
  File "/var/lib/juju/agents/unit-postgresql-test-app-0/charm/src/charm.py", line 334, in _on_clear_continuous_writes_action
    psycopg2.connect(self._connection_string) as connection,
  File "/var/lib/juju/agents/unit-postgresql-test-app-0/charm/venv/lib/python3.10/site-packages/psycopg2/__init__.py", line 122, in connect
    conn = _connect(dsn, connection_factory=connection_factory, **kwasync)
psycopg2.OperationalError: connection to server at "10.21.124.117", port 5432 failed: FATAL:  no pg_hba.conf entry for host "10.21.124.42", user "relation-4", database "postgresql_test_app_database", no encryption

unit-postgresql-test-app-0: 02:26:53 ERROR unit.postgresql-test-app/0.juju-log Uncaught exception while in charm code:
Traceback (most recent call last):
  File "/var/lib/juju/agents/unit-postgresql-test-app-0/charm/src/charm.py", line 579, in <module>
    main(ApplicationCharm)
  File "/var/lib/juju/agents/unit-postgresql-test-app-0/charm/venv/lib/python3.10/site-packages/ops/__init__.py", line 356, in __call__
    return _main.main(charm_class=charm_class, use_juju_for_storage=use_juju_for_storage)
  File "/var/lib/juju/agents/unit-postgresql-test-app-0/charm/venv/lib/python3.10/site-packages/ops/_main.py", line 504, in main
    manager.run()
  File "/var/lib/juju/agents/unit-postgresql-test-app-0/charm/venv/lib/python3.10/site-packages/ops/_main.py", line 488, in run
    self._emit()
  File "/var/lib/juju/agents/unit-postgresql-test-app-0/charm/venv/lib/python3.10/site-packages/ops/_main.py", line 423, in _emit
    self._emit_charm_event(self.dispatcher.event_name)
  File "/var/lib/juju/agents/unit-postgresql-test-app-0/charm/venv/lib/python3.10/site-packages/ops/_main.py", line 467, in _emit_charm_event
    event_to_emit.emit(*args, **kwargs)
  File "/var/lib/juju/agents/unit-postgresql-test-app-0/charm/venv/lib/python3.10/site-packages/ops/framework.py", line 351, in emit
    framework._emit(event)
  File "/var/lib/juju/agents/unit-postgresql-test-app-0/charm/venv/lib/python3.10/site-packages/ops/framework.py", line 924, in _emit
    self._reemit(event_path)
  File "/var/lib/juju/agents/unit-postgresql-test-app-0/charm/venv/lib/python3.10/site-packages/ops/framework.py", line 1030, in _reemit
    custom_handler(event)
  File "/var/lib/juju/agents/unit-postgresql-test-app-0/charm/src/charm.py", line 343, in _on_clear_continuous_writes_action
    connection.close()
UnboundLocalError: local variable 'connection' referenced before assignment
unit-postgresql-test-app-0: 02:26:57 ERROR unit.postgresql-test-app/0.juju-log Unable to drop table
Traceback (most recent call last):
  File "/var/lib/juju/agents/unit-postgresql-test-app-0/charm/src/charm.py", line 334, in _on_clear_continuous_writes_action
    psycopg2.connect(self._connection_string) as connection,
  File "/var/lib/juju/agents/unit-postgresql-test-app-0/charm/venv/lib/python3.10/site-packages/psycopg2/__init__.py", line 122, in connect
    conn = _connect(dsn, connection_factory=connection_factory, **kwasync)
psycopg2.OperationalError: connection to server at "10.21.124.117", port 5432 failed: FATAL:  no pg_hba.conf entry for host "10.21.124.42", user "relation-4", database "postgresql_test_app_database", no encryption

unit-postgresql-test-app-0: 02:26:57 ERROR unit.postgresql-test-app/0.juju-log Uncaught exception while in charm code:
Traceback (most recent call last):
  File "/var/lib/juju/agents/unit-postgresql-test-app-0/charm/src/charm.py", line 579, in <module>
    main(ApplicationCharm)
  File "/var/lib/juju/agents/unit-postgresql-test-app-0/charm/venv/lib/python3.10/site-packages/ops/__init__.py", line 356, in __call__
    return _main.main(charm_class=charm_class, use_juju_for_storage=use_juju_for_storage)
  File "/var/lib/juju/agents/unit-postgresql-test-app-0/charm/venv/lib/python3.10/site-packages/ops/_main.py", line 504, in main
    manager.run()
  File "/var/lib/juju/agents/unit-postgresql-test-app-0/charm/venv/lib/python3.10/site-packages/ops/_main.py", line 488, in run
    self._emit()
  File "/var/lib/juju/agents/unit-postgresql-test-app-0/charm/venv/lib/python3.10/site-packages/ops/_main.py", line 423, in _emit
    self._emit_charm_event(self.dispatcher.event_name)
  File "/var/lib/juju/agents/unit-postgresql-test-app-0/charm/venv/lib/python3.10/site-packages/ops/_main.py", line 467, in _emit_charm_event
    event_to_emit.emit(*args, **kwargs)
  File "/var/lib/juju/agents/unit-postgresql-test-app-0/charm/venv/lib/python3.10/site-packages/ops/framework.py", line 351, in emit
    framework._emit(event)
  File "/var/lib/juju/agents/unit-postgresql-test-app-0/charm/venv/lib/python3.10/site-packages/ops/framework.py", line 924, in _emit
    self._reemit(event_path)
  File "/var/lib/juju/agents/unit-postgresql-test-app-0/charm/venv/lib/python3.10/site-packages/ops/framework.py", line 1030, in _reemit
    custom_handler(event)
  File "/var/lib/juju/agents/unit-postgresql-test-app-0/charm/src/charm.py", line 343, in _on_clear_continuous_writes_action
    connection.close()
UnboundLocalError: local variable 'connection' referenced before assignment
unit-postgresql-test-app-0: 02:27:01 ERROR unit.postgresql-test-app/0.juju-log Unable to drop table
Traceback (most recent call last):
  File "/var/lib/juju/agents/unit-postgresql-test-app-0/charm/src/charm.py", line 334, in _on_clear_continuous_writes_action
    psycopg2.connect(self._connection_string) as connection,
  File "/var/lib/juju/agents/unit-postgresql-test-app-0/charm/venv/lib/python3.10/site-packages/psycopg2/__init__.py", line 122, in connect
    conn = _connect(dsn, connection_factory=connection_factory, **kwasync)
psycopg2.OperationalError: connection to server at "10.21.124.117", port 5432 failed: FATAL:  no pg_hba.conf entry for host "10.21.124.42", user "relation-4", database "postgresql_test_app_database", no encryption

unit-postgresql-test-app-0: 02:27:01 ERROR unit.postgresql-test-app/0.juju-log Uncaught exception while in charm code:
Traceback (most recent call last):
  File "/var/lib/juju/agents/unit-postgresql-test-app-0/charm/src/charm.py", line 579, in <module>
    main(ApplicationCharm)
  File "/var/lib/juju/agents/unit-postgresql-test-app-0/charm/venv/lib/python3.10/site-packages/ops/__init__.py", line 356, in __call__
    return _main.main(charm_class=charm_class, use_juju_for_storage=use_juju_for_storage)
  File "/var/lib/juju/agents/unit-postgresql-test-app-0/charm/venv/lib/python3.10/site-packages/ops/_main.py", line 504, in main
    manager.run()
  File "/var/lib/juju/agents/unit-postgresql-test-app-0/charm/venv/lib/python3.10/site-packages/ops/_main.py", line 488, in run
    self._emit()
  File "/var/lib/juju/agents/unit-postgresql-test-app-0/charm/venv/lib/python3.10/site-packages/ops/_main.py", line 423, in _emit
    self._emit_charm_event(self.dispatcher.event_name)
  File "/var/lib/juju/agents/unit-postgresql-test-app-0/charm/venv/lib/python3.10/site-packages/ops/_main.py", line 467, in _emit_charm_event
    event_to_emit.emit(*args, **kwargs)
  File "/var/lib/juju/agents/unit-postgresql-test-app-0/charm/venv/lib/python3.10/site-packages/ops/framework.py", line 351, in emit
    framework._emit(event)
  File "/var/lib/juju/agents/unit-postgresql-test-app-0/charm/venv/lib/python3.10/site-packages/ops/framework.py", line 924, in _emit
    self._reemit(event_path)
  File "/var/lib/juju/agents/unit-postgresql-test-app-0/charm/venv/lib/python3.10/site-packages/ops/framework.py", line 1030, in _reemit
    custom_handler(event)
  File "/var/lib/juju/agents/unit-postgresql-test-app-0/charm/src/charm.py", line 343, in _on_clear_continuous_writes_action
    connection.close()
UnboundLocalError: local variable 'connection' referenced before assignment
unit-postgresql-test-app-0: 02:27:05 ERROR unit.postgresql-test-app/0.juju-log Unable to drop table
Traceback (most recent call last):
  File "/var/lib/juju/agents/unit-postgresql-test-app-0/charm/src/charm.py", line 334, in _on_clear_continuous_writes_action
    psycopg2.connect(self._connection_string) as connection,
  File "/var/lib/juju/agents/unit-postgresql-test-app-0/charm/venv/lib/python3.10/site-packages/psycopg2/__init__.py", line 122, in connect
    conn = _connect(dsn, connection_factory=connection_factory, **kwasync)
psycopg2.OperationalError: connection to server at "10.21.124.117", port 5432 failed: FATAL:  no pg_hba.conf entry for host "10.21.124.42", user "relation-4", database "postgresql_test_app_database", no encryption

unit-postgresql-test-app-0: 02:27:05 ERROR unit.postgresql-test-app/0.juju-log Uncaught exception while in charm code:
Traceback (most recent call last):
  File "/var/lib/juju/agents/unit-postgresql-test-app-0/charm/src/charm.py", line 579, in <module>
    main(ApplicationCharm)
  File "/var/lib/juju/agents/unit-postgresql-test-app-0/charm/venv/lib/python3.10/site-packages/ops/__init__.py", line 356, in __call__
    return _main.main(charm_class=charm_class, use_juju_for_storage=use_juju_for_storage)
  File "/var/lib/juju/agents/unit-postgresql-test-app-0/charm/venv/lib/python3.10/site-packages/ops/_main.py", line 504, in main
    manager.run()
  File "/var/lib/juju/agents/unit-postgresql-test-app-0/charm/venv/lib/python3.10/site-packages/ops/_main.py", line 488, in run
    self._emit()
  File "/var/lib/juju/agents/unit-postgresql-test-app-0/charm/venv/lib/python3.10/site-packages/ops/_main.py", line 423, in _emit
    self._emit_charm_event(self.dispatcher.event_name)
  File "/var/lib/juju/agents/unit-postgresql-test-app-0/charm/venv/lib/python3.10/site-packages/ops/_main.py", line 467, in _emit_charm_event
    event_to_emit.emit(*args, **kwargs)
  File "/var/lib/juju/agents/unit-postgresql-test-app-0/charm/venv/lib/python3.10/site-packages/ops/framework.py", line 351, in emit
    framework._emit(event)
  File "/var/lib/juju/agents/unit-postgresql-test-app-0/charm/venv/lib/python3.10/site-packages/ops/framework.py", line 924, in _emit
    self._reemit(event_path)
  File "/var/lib/juju/agents/unit-postgresql-test-app-0/charm/venv/lib/python3.10/site-packages/ops/framework.py", line 1030, in _reemit
    custom_handler(event)
  File "/var/lib/juju/agents/unit-postgresql-test-app-0/charm/src/charm.py", line 343, in _on_clear_continuous_writes_action
    connection.close()
UnboundLocalError: local variable 'connection' referenced before assignment
unit-postgresql-test-app-0: 02:27:09 ERROR unit.postgresql-test-app/0.juju-log Unable to drop table
Traceback (most recent call last):
  File "/var/lib/juju/agents/unit-postgresql-test-app-0/charm/src/charm.py", line 334, in _on_clear_continuous_writes_action
    psycopg2.connect(self._connection_string) as connection,
  File "/var/lib/juju/agents/unit-postgresql-test-app-0/charm/venv/lib/python3.10/site-packages/psycopg2/__init__.py", line 122, in connect
    conn = _connect(dsn, connection_factory=connection_factory, **kwasync)
psycopg2.OperationalError: connection to server at "10.21.124.117", port 5432 failed: FATAL:  no pg_hba.conf entry for host "10.21.124.42", user "relation-4", database "postgresql_test_app_database", no encryption

unit-postgresql-test-app-0: 02:27:09 ERROR unit.postgresql-test-app/0.juju-log Uncaught exception while in charm code:
Traceback (most recent call last):
  File "/var/lib/juju/agents/unit-postgresql-test-app-0/charm/src/charm.py", line 579, in <module>
    main(ApplicationCharm)
  File "/var/lib/juju/agents/unit-postgresql-test-app-0/charm/venv/lib/python3.10/site-packages/ops/__init__.py", line 356, in __call__
    return _main.main(charm_class=charm_class, use_juju_for_storage=use_juju_for_storage)
  File "/var/lib/juju/agents/unit-postgresql-test-app-0/charm/venv/lib/python3.10/site-packages/ops/_main.py", line 504, in main
    manager.run()
  File "/var/lib/juju/agents/unit-postgresql-test-app-0/charm/venv/lib/python3.10/site-packages/ops/_main.py", line 488, in run
    self._emit()
  File "/var/lib/juju/agents/unit-postgresql-test-app-0/charm/venv/lib/python3.10/site-packages/ops/_main.py", line 423, in _emit
    self._emit_charm_event(self.dispatcher.event_name)
  File "/var/lib/juju/agents/unit-postgresql-test-app-0/charm/venv/lib/python3.10/site-packages/ops/_main.py", line 467, in _emit_charm_event
    event_to_emit.emit(*args, **kwargs)
  File "/var/lib/juju/agents/unit-postgresql-test-app-0/charm/venv/lib/python3.10/site-packages/ops/framework.py", line 351, in emit
    framework._emit(event)
  File "/var/lib/juju/agents/unit-postgresql-test-app-0/charm/venv/lib/python3.10/site-packages/ops/framework.py", line 924, in _emit
    self._reemit(event_path)
  File "/var/lib/juju/agents/unit-postgresql-test-app-0/charm/venv/lib/python3.10/site-packages/ops/framework.py", line 1030, in _reemit
    custom_handler(event)
  File "/var/lib/juju/agents/unit-postgresql-test-app-0/charm/src/charm.py", line 343, in _on_clear_continuous_writes_action
    connection.close()
UnboundLocalError: local variable 'connection' referenced before assignment
unit-postgresql-test-app-0: 02:27:13 ERROR unit.postgresql-test-app/0.juju-log Unable to drop table
Traceback (most recent call last):
  File "/var/lib/juju/agents/unit-postgresql-test-app-0/charm/src/charm.py", line 334, in _on_clear_continuous_writes_action
    psycopg2.connect(self._connection_string) as connection,
  File "/var/lib/juju/agents/unit-postgresql-test-app-0/charm/venv/lib/python3.10/site-packages/psycopg2/__init__.py", line 122, in connect
    conn = _connect(dsn, connection_factory=connection_factory, **kwasync)
psycopg2.OperationalError: connection to server at "10.21.124.117", port 5432 failed: FATAL:  no pg_hba.conf entry for host "10.21.124.42", user "relation-4", database "postgresql_test_app_database", no encryption

unit-postgresql-test-app-0: 02:27:13 ERROR unit.postgresql-test-app/0.juju-log Uncaught exception while in charm code:
Traceback (most recent call last):
  File "/var/lib/juju/agents/unit-postgresql-test-app-0/charm/src/charm.py", line 579, in <module>
    main(ApplicationCharm)
  File "/var/lib/juju/agents/unit-postgresql-test-app-0/charm/venv/lib/python3.10/site-packages/ops/__init__.py", line 356, in __call__
    return _main.main(charm_class=charm_class, use_juju_for_storage=use_juju_for_storage)
  File "/var/lib/juju/agents/unit-postgresql-test-app-0/charm/venv/lib/python3.10/site-packages/ops/_main.py", line 504, in main
    manager.run()
  File "/var/lib/juju/agents/unit-postgresql-test-app-0/charm/venv/lib/python3.10/site-packages/ops/_main.py", line 488, in run
    self._emit()
  File "/var/lib/juju/agents/unit-postgresql-test-app-0/charm/venv/lib/python3.10/site-packages/ops/_main.py", line 423, in _emit
    self._emit_charm_event(self.dispatcher.event_name)
  File "/var/lib/juju/agents/unit-postgresql-test-app-0/charm/venv/lib/python3.10/site-packages/ops/_main.py", line 467, in _emit_charm_event
    event_to_emit.emit(*args, **kwargs)
  File "/var/lib/juju/agents/unit-postgresql-test-app-0/charm/venv/lib/python3.10/site-packages/ops/framework.py", line 351, in emit
    framework._emit(event)
  File "/var/lib/juju/agents/unit-postgresql-test-app-0/charm/venv/lib/python3.10/site-packages/ops/framework.py", line 924, in _emit
    self._reemit(event_path)
  File "/var/lib/juju/agents/unit-postgresql-test-app-0/charm/venv/lib/python3.10/site-packages/ops/framework.py", line 1030, in _reemit
    custom_handler(event)
  File "/var/lib/juju/agents/unit-postgresql-test-app-0/charm/src/charm.py", line 343, in _on_clear_continuous_writes_action
    connection.close()
UnboundLocalError: local variable 'connection' referenced before assignment
unit-postgresql-test-app-0: 02:27:17 ERROR unit.postgresql-test-app/0.juju-log Unable to drop table
Traceback (most recent call last):
  File "/var/lib/juju/agents/unit-postgresql-test-app-0/charm/src/charm.py", line 334, in _on_clear_continuous_writes_action
    psycopg2.connect(self._connection_string) as connection,
  File "/var/lib/juju/agents/unit-postgresql-test-app-0/charm/venv/lib/python3.10/site-packages/psycopg2/__init__.py", line 122, in connect
    conn = _connect(dsn, connection_factory=connection_factory, **kwasync)
psycopg2.OperationalError: connection to server at "10.21.124.117", port 5432 failed: FATAL:  no pg_hba.conf entry for host "10.21.124.42", user "relation-4", database "postgresql_test_app_database", no encryption

unit-postgresql-test-app-0: 02:27:17 ERROR unit.postgresql-test-app/0.juju-log Uncaught exception while in charm code:
Traceback (most recent call last):
  File "/var/lib/juju/agents/unit-postgresql-test-app-0/charm/src/charm.py", line 579, in <module>
    main(ApplicationCharm)
  File "/var/lib/juju/agents/unit-postgresql-test-app-0/charm/venv/lib/python3.10/site-packages/ops/__init__.py", line 356, in __call__
    return _main.main(charm_class=charm_class, use_juju_for_storage=use_juju_for_storage)
  File "/var/lib/juju/agents/unit-postgresql-test-app-0/charm/venv/lib/python3.10/site-packages/ops/_main.py", line 504, in main
    manager.run()
  File "/var/lib/juju/agents/unit-postgresql-test-app-0/charm/venv/lib/python3.10/site-packages/ops/_main.py", line 488, in run
    self._emit()
  File "/var/lib/juju/agents/unit-postgresql-test-app-0/charm/venv/lib/python3.10/site-packages/ops/_main.py", line 423, in _emit
    self._emit_charm_event(self.dispatcher.event_name)
  File "/var/lib/juju/agents/unit-postgresql-test-app-0/charm/venv/lib/python3.10/site-packages/ops/_main.py", line 467, in _emit_charm_event
    event_to_emit.emit(*args, **kwargs)
  File "/var/lib/juju/agents/unit-postgresql-test-app-0/charm/venv/lib/python3.10/site-packages/ops/framework.py", line 351, in emit
    framework._emit(event)
  File "/var/lib/juju/agents/unit-postgresql-test-app-0/charm/venv/lib/python3.10/site-packages/ops/framework.py", line 924, in _emit
    self._reemit(event_path)
  File "/var/lib/juju/agents/unit-postgresql-test-app-0/charm/venv/lib/python3.10/site-packages/ops/framework.py", line 1030, in _reemit
    custom_handler(event)
  File "/var/lib/juju/agents/unit-postgresql-test-app-0/charm/src/charm.py", line 343, in _on_clear_continuous_writes_action
    connection.close()
UnboundLocalError: local variable 'connection' referenced before assignment
unit-postgresql-test-app-0: 02:27:21 ERROR unit.postgresql-test-app/0.juju-log Unable to drop table
Traceback (most recent call last):
  File "/var/lib/juju/agents/unit-postgresql-test-app-0/charm/src/charm.py", line 334, in _on_clear_continuous_writes_action
    psycopg2.connect(self._connection_string) as connection,
  File "/var/lib/juju/agents/unit-postgresql-test-app-0/charm/venv/lib/python3.10/site-packages/psycopg2/__init__.py", line 122, in connect
    conn = _connect(dsn, connection_factory=connection_factory, **kwasync)
psycopg2.OperationalError: connection to server at "10.21.124.117", port 5432 failed: FATAL:  no pg_hba.conf entry for host "10.21.124.42", user "relation-4", database "postgresql_test_app_database", no encryption

unit-postgresql-test-app-0: 02:27:21 ERROR unit.postgresql-test-app/0.juju-log Uncaught exception while in charm code:
Traceback (most recent call last):
  File "/var/lib/juju/agents/unit-postgresql-test-app-0/charm/src/charm.py", line 579, in <module>
    main(ApplicationCharm)
  File "/var/lib/juju/agents/unit-postgresql-test-app-0/charm/venv/lib/python3.10/site-packages/ops/__init__.py", line 356, in __call__
    return _main.main(charm_class=charm_class, use_juju_for_storage=use_juju_for_storage)
  File "/var/lib/juju/agents/unit-postgresql-test-app-0/charm/venv/lib/python3.10/site-packages/ops/_main.py", line 504, in main
    manager.run()
  File "/var/lib/juju/agents/unit-postgresql-test-app-0/charm/venv/lib/python3.10/site-packages/ops/_main.py", line 488, in run
    self._emit()
  File "/var/lib/juju/agents/unit-postgresql-test-app-0/charm/venv/lib/python3.10/site-packages/ops/_main.py", line 423, in _emit
    self._emit_charm_event(self.dispatcher.event_name)
  File "/var/lib/juju/agents/unit-postgresql-test-app-0/charm/venv/lib/python3.10/site-packages/ops/_main.py", line 467, in _emit_charm_event
    event_to_emit.emit(*args, **kwargs)
  File "/var/lib/juju/agents/unit-postgresql-test-app-0/charm/venv/lib/python3.10/site-packages/ops/framework.py", line 351, in emit
    framework._emit(event)
  File "/var/lib/juju/agents/unit-postgresql-test-app-0/charm/venv/lib/python3.10/site-packages/ops/framework.py", line 924, in _emit
    self._reemit(event_path)
  File "/var/lib/juju/agents/unit-postgresql-test-app-0/charm/venv/lib/python3.10/site-packages/ops/framework.py", line 1030, in _reemit
    custom_handler(event)
  File "/var/lib/juju/agents/unit-postgresql-test-app-0/charm/src/charm.py", line 343, in _on_clear_continuous_writes_action
    connection.close()
UnboundLocalError: local variable 'connection' referenced before assignment
unit-postgresql-test-app-0: 02:27:25 ERROR unit.postgresql-test-app/0.juju-log Unable to drop table
Traceback (most recent call last):
  File "/var/lib/juju/agents/unit-postgresql-test-app-0/charm/src/charm.py", line 334, in _on_clear_continuous_writes_action
    psycopg2.connect(self._connection_string) as connection,
  File "/var/lib/juju/agents/unit-postgresql-test-app-0/charm/venv/lib/python3.10/site-packages/psycopg2/__init__.py", line 122, in connect
    conn = _connect(dsn, connection_factory=connection_factory, **kwasync)
psycopg2.OperationalError: connection to server at "10.21.124.117", port 5432 failed: FATAL:  no pg_hba.conf entry for host "10.21.124.42", user "relation-4", database "postgresql_test_app_database", no encryption

unit-postgresql-test-app-0: 02:27:25 ERROR unit.postgresql-test-app/0.juju-log Uncaught exception while in charm code:
Traceback (most recent call last):
  File "/var/lib/juju/agents/unit-postgresql-test-app-0/charm/src/charm.py", line 579, in <module>
    main(ApplicationCharm)
  File "/var/lib/juju/agents/unit-postgresql-test-app-0/charm/venv/lib/python3.10/site-packages/ops/__init__.py", line 356, in __call__
    return _main.main(charm_class=charm_class, use_juju_for_storage=use_juju_for_storage)
  File "/var/lib/juju/agents/unit-postgresql-test-app-0/charm/venv/lib/python3.10/site-packages/ops/_main.py", line 504, in main
    manager.run()
  File "/var/lib/juju/agents/unit-postgresql-test-app-0/charm/venv/lib/python3.10/site-packages/ops/_main.py", line 488, in run
    self._emit()
  File "/var/lib/juju/agents/unit-postgresql-test-app-0/charm/venv/lib/python3.10/site-packages/ops/_main.py", line 423, in _emit
    self._emit_charm_event(self.dispatcher.event_name)
  File "/var/lib/juju/agents/unit-postgresql-test-app-0/charm/venv/lib/python3.10/site-packages/ops/_main.py", line 467, in _emit_charm_event
    event_to_emit.emit(*args, **kwargs)
  File "/var/lib/juju/agents/unit-postgresql-test-app-0/charm/venv/lib/python3.10/site-packages/ops/framework.py", line 351, in emit
    framework._emit(event)
  File "/var/lib/juju/agents/unit-postgresql-test-app-0/charm/venv/lib/python3.10/site-packages/ops/framework.py", line 924, in _emit
    self._reemit(event_path)
  File "/var/lib/juju/agents/unit-postgresql-test-app-0/charm/venv/lib/python3.10/site-packages/ops/framework.py", line 1030, in _reemit
    custom_handler(event)
  File "/var/lib/juju/agents/unit-postgresql-test-app-0/charm/src/charm.py", line 343, in _on_clear_continuous_writes_action
    connection.close()
UnboundLocalError: local variable 'connection' referenced before assignment
unit-postgresql-test-app-0: 02:27:29 ERROR unit.postgresql-test-app/0.juju-log Unable to drop table
Traceback (most recent call last):
  File "/var/lib/juju/agents/unit-postgresql-test-app-0/charm/src/charm.py", line 334, in _on_clear_continuous_writes_action
    psycopg2.connect(self._connection_string) as connection,
  File "/var/lib/juju/agents/unit-postgresql-test-app-0/charm/venv/lib/python3.10/site-packages/psycopg2/__init__.py", line 122, in connect
    conn = _connect(dsn, connection_factory=connection_factory, **kwasync)
psycopg2.OperationalError: connection to server at "10.21.124.117", port 5432 failed: FATAL:  no pg_hba.conf entry for host "10.21.124.42", user "relation-4", database "postgresql_test_app_database", no encryption

unit-postgresql-test-app-0: 02:27:29 ERROR unit.postgresql-test-app/0.juju-log Uncaught exception while in charm code:
Traceback (most recent call last):
  File "/var/lib/juju/agents/unit-postgresql-test-app-0/charm/src/charm.py", line 579, in <module>
    main(ApplicationCharm)
  File "/var/lib/juju/agents/unit-postgresql-test-app-0/charm/venv/lib/python3.10/site-packages/ops/__init__.py", line 356, in __call__
    return _main.main(charm_class=charm_class, use_juju_for_storage=use_juju_for_storage)
  File "/var/lib/juju/agents/unit-postgresql-test-app-0/charm/venv/lib/python3.10/site-packages/ops/_main.py", line 504, in main
    manager.run()
  File "/var/lib/juju/agents/unit-postgresql-test-app-0/charm/venv/lib/python3.10/site-packages/ops/_main.py", line 488, in run
    self._emit()
  File "/var/lib/juju/agents/unit-postgresql-test-app-0/charm/venv/lib/python3.10/site-packages/ops/_main.py", line 423, in _emit
    self._emit_charm_event(self.dispatcher.event_name)
  File "/var/lib/juju/agents/unit-postgresql-test-app-0/charm/venv/lib/python3.10/site-packages/ops/_main.py", line 467, in _emit_charm_event
    event_to_emit.emit(*args, **kwargs)
  File "/var/lib/juju/agents/unit-postgresql-test-app-0/charm/venv/lib/python3.10/site-packages/ops/framework.py", line 351, in emit
    framework._emit(event)
  File "/var/lib/juju/agents/unit-postgresql-test-app-0/charm/venv/lib/python3.10/site-packages/ops/framework.py", line 924, in _emit
    self._reemit(event_path)
  File "/var/lib/juju/agents/unit-postgresql-test-app-0/charm/venv/lib/python3.10/site-packages/ops/framework.py", line 1030, in _reemit
    custom_handler(event)
  File "/var/lib/juju/agents/unit-postgresql-test-app-0/charm/src/charm.py", line 343, in _on_clear_continuous_writes_action
    connection.close()
UnboundLocalError: local variable 'connection' referenced before assignment

[32mINFO    [0m pytest_operator.plugin:plugin.py:1039 Forgetting model main...