[32mINFO    [0m integration.ha_tests.test_async_replication:test_async_replication.py:82 Destroying second model
[32mINFO    [0m pytest_operator.plugin:plugin.py:951 Model status:

Model    Controller     Cloud/Region         Version  SLA          Timestamp
testing  concierge-lxd  localhost/localhost  3.6.8    unsupported  02:14:19Z

App                  Version  Status   Scale  Charm                Channel      Rev  Exposed  Message
data-integrator               active       1  data-integrator      latest/edge  218  no       
postgresql           14.18    blocked      3  postgresql                          0  no       Standalone read-only cluster
postgresql-test-app           blocked      1  postgresql-test-app  latest/edge  398  no       No database integration available

Unit                    Workload  Agent      Machine  Public address  Ports     Message
data-integrator/0*      active    idle       3        10.236.101.34             
postgresql-test-app/0*  blocked   idle       4        10.236.101.136            No database integration available
postgresql/0            active    executing  0        10.236.101.90   5432/tcp  
postgresql/1*           error     idle       1        10.236.101.13   5432/tcp  hook failed: "database-peers-relation-changed"
postgresql/2            active    executing  2        10.236.101.114  5432/tcp  

Machine  State    Address         Inst id        Base          AZ  Message
0        started  10.236.101.90   juju-7c4d52-0  ubuntu@22.04      Running
1        started  10.236.101.13   juju-7c4d52-1  ubuntu@22.04      Running
2        started  10.236.101.114  juju-7c4d52-2  ubuntu@22.04      Running
3        started  10.236.101.34   juju-7c4d52-3  ubuntu@24.04      Running
4        started  10.236.101.136  juju-7c4d52-4  ubuntu@22.04      Running

Offer              Application  Charm       Rev  Connected  Endpoint           Interface         Role
replication        postgresql   postgresql  0    0/0        replication        postgresql_async  requirer
replication-offer  postgresql   postgresql  0    0/0        replication-offer  postgresql_async  provider

[32mINFO    [0m pytest_operator.plugin:plugin.py:957 Juju error logs:

machine-3: 01:32:06 ERROR juju.worker.dependency "kvm-container-provisioner" manifold worker returned unexpected error: container types not yet available
machine-3: 01:32:06 ERROR juju.worker.dependency "lxd-container-provisioner" manifold worker returned unexpected error: container types not yet available
unit-data-integrator-0: 01:32:07 ERROR juju.worker.meterstatus error running "meter-status-changed": charm missing from disk
machine-1: 01:33:57 ERROR juju.worker.dependency "lxd-container-provisioner" manifold worker returned unexpected error: container types not yet available
machine-1: 01:33:57 ERROR juju.worker.dependency "kvm-container-provisioner" manifold worker returned unexpected error: container types not yet available
unit-postgresql-1: 01:33:57 ERROR juju.worker.meterstatus error running "meter-status-changed": charm missing from disk
machine-4: 01:35:02 ERROR juju.worker.dependency "kvm-container-provisioner" manifold worker returned unexpected error: container types not yet available
machine-4: 01:35:02 ERROR juju.worker.dependency "lxd-container-provisioner" manifold worker returned unexpected error: container types not yet available
unit-postgresql-test-app-0: 01:35:02 ERROR juju.worker.meterstatus error running "meter-status-changed": charm missing from disk
unit-postgresql-1: 01:36:12 ERROR unit.postgresql/1.juju-log Unable to get the state of the cluster
Traceback (most recent call last):
  File "/var/lib/juju/agents/unit-postgresql-1/charm/venv/lib/python3.10/site-packages/urllib3/connection.py", line 198, in _new_conn
    sock = connection.create_connection(
  File "/var/lib/juju/agents/unit-postgresql-1/charm/venv/lib/python3.10/site-packages/urllib3/util/connection.py", line 85, in create_connection
    raise err
  File "/var/lib/juju/agents/unit-postgresql-1/charm/venv/lib/python3.10/site-packages/urllib3/util/connection.py", line 73, in create_connection
    sock.connect(sa)
ConnectionRefusedError: [Errno 111] Connection refused

The above exception was the direct cause of the following exception:

Traceback (most recent call last):
  File "/var/lib/juju/agents/unit-postgresql-1/charm/venv/lib/python3.10/site-packages/urllib3/connectionpool.py", line 787, in urlopen
    response = self._make_request(
  File "/var/lib/juju/agents/unit-postgresql-1/charm/venv/lib/python3.10/site-packages/urllib3/connectionpool.py", line 493, in _make_request
    conn.request(
  File "/var/lib/juju/agents/unit-postgresql-1/charm/venv/lib/python3.10/site-packages/urllib3/connection.py", line 494, in request
    self.endheaders()
  File "/usr/lib/python3.10/http/client.py", line 1278, in endheaders
    self._send_output(message_body, encode_chunked=encode_chunked)
  File "/usr/lib/python3.10/http/client.py", line 1038, in _send_output
    self.send(msg)
  File "/usr/lib/python3.10/http/client.py", line 976, in send
    self.connect()
  File "/var/lib/juju/agents/unit-postgresql-1/charm/venv/lib/python3.10/site-packages/urllib3/connection.py", line 325, in connect
    self.sock = self._new_conn()
  File "/var/lib/juju/agents/unit-postgresql-1/charm/venv/lib/python3.10/site-packages/urllib3/connection.py", line 213, in _new_conn
    raise NewConnectionError(
urllib3.exceptions.NewConnectionError: <urllib3.connection.HTTPConnection object at 0x7f8975f542b0>: Failed to establish a new connection: [Errno 111] Connection refused

The above exception was the direct cause of the following exception:

Traceback (most recent call last):
  File "/var/lib/juju/agents/unit-postgresql-1/charm/venv/lib/python3.10/site-packages/requests/adapters.py", line 667, in send
    resp = conn.urlopen(
  File "/var/lib/juju/agents/unit-postgresql-1/charm/venv/lib/python3.10/site-packages/urllib3/connectionpool.py", line 841, in urlopen
    retries = retries.increment(
  File "/var/lib/juju/agents/unit-postgresql-1/charm/venv/lib/python3.10/site-packages/urllib3/util/retry.py", line 519, in increment
    raise MaxRetryError(_pool, url, reason) from reason  # type: ignore[arg-type]
urllib3.exceptions.MaxRetryError: HTTPConnectionPool(host='10.236.101.13', port=8008): Max retries exceeded with url: /cluster (Caused by NewConnectionError('<urllib3.connection.HTTPConnection object at 0x7f8975f542b0>: Failed to establish a new connection: [Errno 111] Connection refused'))

During handling of the above exception, another exception occurred:

Traceback (most recent call last):
  File "/var/lib/juju/agents/unit-postgresql-1/charm/src/cluster.py", line 571, in are_replicas_up
    response = requests.get(
  File "/var/lib/juju/agents/unit-postgresql-1/charm/venv/lib/python3.10/site-packages/requests/api.py", line 73, in get
    return request("get", url, params=params, **kwargs)
  File "/var/lib/juju/agents/unit-postgresql-1/charm/venv/lib/python3.10/site-packages/requests/api.py", line 59, in request
    return session.request(method=method, url=url, **kwargs)
  File "/var/lib/juju/agents/unit-postgresql-1/charm/venv/lib/python3.10/site-packages/requests/sessions.py", line 589, in request
    resp = self.send(prep, **send_kwargs)
  File "/var/lib/juju/agents/unit-postgresql-1/charm/venv/lib/python3.10/site-packages/requests/sessions.py", line 703, in send
    r = adapter.send(request, **kwargs)
  File "/var/lib/juju/agents/unit-postgresql-1/charm/venv/lib/python3.10/site-packages/requests/adapters.py", line 700, in send
    raise ConnectionError(e, request=request)
requests.exceptions.ConnectionError: HTTPConnectionPool(host='10.236.101.13', port=8008): Max retries exceeded with url: /cluster (Caused by NewConnectionError('<urllib3.connection.HTTPConnection object at 0x7f8975f542b0>: Failed to establish a new connection: [Errno 111] Connection refused'))
unit-postgresql-1: 01:37:00 ERROR unit.postgresql/1.juju-log database:4: Failed to list PostgreSQL database users: could not translate host name "None" to address: Temporary failure in name resolution

machine-0: 01:37:36 ERROR juju.worker.dependency "kvm-container-provisioner" manifold worker returned unexpected error: container types not yet available
machine-0: 01:37:36 ERROR juju.worker.dependency "lxd-container-provisioner" manifold worker returned unexpected error: container types not yet available
unit-postgresql-0: 01:37:37 ERROR juju.worker.meterstatus error running "meter-status-changed": charm missing from disk
machine-2: 01:38:44 ERROR juju.worker.dependency "lxd-container-provisioner" manifold worker returned unexpected error: container types not yet available
machine-2: 01:38:44 ERROR juju.worker.dependency "kvm-container-provisioner" manifold worker returned unexpected error: container types not yet available
unit-postgresql-2: 01:38:45 ERROR juju.worker.meterstatus error running "meter-status-changed": charm missing from disk
unit-postgresql-0: 01:50:41 ERROR unit.postgresql/0.juju-log Failed to list PostgreSQL database users: connection to server at "10.236.101.90", port 5432 failed: Connection refused
	Is the server running on that host and accepting TCP/IP connections?

unit-postgresql-2: 01:50:42 ERROR unit.postgresql/2.juju-log Failed to list PostgreSQL database users: connection to server at "10.236.101.114", port 5432 failed: Connection refused
	Is the server running on that host and accepting TCP/IP connections?

unit-postgresql-1: 01:57:32 ERROR unit.postgresql/1.juju-log database-peers:1: Unable to get the state of the cluster
Traceback (most recent call last):
  File "/var/lib/juju/agents/unit-postgresql-1/charm/venv/lib/python3.10/site-packages/urllib3/connection.py", line 198, in _new_conn
    sock = connection.create_connection(
  File "/var/lib/juju/agents/unit-postgresql-1/charm/venv/lib/python3.10/site-packages/urllib3/util/connection.py", line 85, in create_connection
    raise err
  File "/var/lib/juju/agents/unit-postgresql-1/charm/venv/lib/python3.10/site-packages/urllib3/util/connection.py", line 73, in create_connection
    sock.connect(sa)
ConnectionRefusedError: [Errno 111] Connection refused

The above exception was the direct cause of the following exception:

Traceback (most recent call last):
  File "/var/lib/juju/agents/unit-postgresql-1/charm/venv/lib/python3.10/site-packages/urllib3/connectionpool.py", line 787, in urlopen
    response = self._make_request(
  File "/var/lib/juju/agents/unit-postgresql-1/charm/venv/lib/python3.10/site-packages/urllib3/connectionpool.py", line 493, in _make_request
    conn.request(
  File "/var/lib/juju/agents/unit-postgresql-1/charm/venv/lib/python3.10/site-packages/urllib3/connection.py", line 494, in request
    self.endheaders()
  File "/usr/lib/python3.10/http/client.py", line 1278, in endheaders
    self._send_output(message_body, encode_chunked=encode_chunked)
  File "/usr/lib/python3.10/http/client.py", line 1038, in _send_output
    self.send(msg)
  File "/usr/lib/python3.10/http/client.py", line 976, in send
    self.connect()
  File "/var/lib/juju/agents/unit-postgresql-1/charm/venv/lib/python3.10/site-packages/urllib3/connection.py", line 325, in connect
    self.sock = self._new_conn()
  File "/var/lib/juju/agents/unit-postgresql-1/charm/venv/lib/python3.10/site-packages/urllib3/connection.py", line 213, in _new_conn
    raise NewConnectionError(
urllib3.exceptions.NewConnectionError: <urllib3.connection.HTTPConnection object at 0x7fbd1efb2860>: Failed to establish a new connection: [Errno 111] Connection refused

The above exception was the direct cause of the following exception:

Traceback (most recent call last):
  File "/var/lib/juju/agents/unit-postgresql-1/charm/venv/lib/python3.10/site-packages/requests/adapters.py", line 667, in send
    resp = conn.urlopen(
  File "/var/lib/juju/agents/unit-postgresql-1/charm/venv/lib/python3.10/site-packages/urllib3/connectionpool.py", line 841, in urlopen
    retries = retries.increment(
  File "/var/lib/juju/agents/unit-postgresql-1/charm/venv/lib/python3.10/site-packages/urllib3/util/retry.py", line 519, in increment
    raise MaxRetryError(_pool, url, reason) from reason  # type: ignore[arg-type]
urllib3.exceptions.MaxRetryError: HTTPConnectionPool(host='10.236.101.13', port=8008): Max retries exceeded with url: /cluster (Caused by NewConnectionError('<urllib3.connection.HTTPConnection object at 0x7fbd1efb2860>: Failed to establish a new connection: [Errno 111] Connection refused'))

During handling of the above exception, another exception occurred:

Traceback (most recent call last):
  File "/var/lib/juju/agents/unit-postgresql-1/charm/src/cluster.py", line 571, in are_replicas_up
    response = requests.get(
  File "/var/lib/juju/agents/unit-postgresql-1/charm/venv/lib/python3.10/site-packages/requests/api.py", line 73, in get
    return request("get", url, params=params, **kwargs)
  File "/var/lib/juju/agents/unit-postgresql-1/charm/venv/lib/python3.10/site-packages/requests/api.py", line 59, in request
    return session.request(method=method, url=url, **kwargs)
  File "/var/lib/juju/agents/unit-postgresql-1/charm/venv/lib/python3.10/site-packages/requests/sessions.py", line 589, in request
    resp = self.send(prep, **send_kwargs)
  File "/var/lib/juju/agents/unit-postgresql-1/charm/venv/lib/python3.10/site-packages/requests/sessions.py", line 703, in send
    r = adapter.send(request, **kwargs)
  File "/var/lib/juju/agents/unit-postgresql-1/charm/venv/lib/python3.10/site-packages/requests/adapters.py", line 700, in send
    raise ConnectionError(e, request=request)
requests.exceptions.ConnectionError: HTTPConnectionPool(host='10.236.101.13', port=8008): Max retries exceeded with url: /cluster (Caused by NewConnectionError('<urllib3.connection.HTTPConnection object at 0x7fbd1efb2860>: Failed to establish a new connection: [Errno 111] Connection refused'))
unit-postgresql-2: 02:13:37 ERROR juju.worker.dependency "uniter" manifold worker returned unexpected error: relation scope id "2eb6b0ae-6c3a-47a8-8f55-897b227c4d52:r#6#postgresql-test-app": settings 2eb6b0ae-6c3a-47a8-8f55-897b227c4d52:r#6#postgresql-test-app not found (not found)
unit-postgresql-1: 02:14:14 ERROR unit.postgresql/1.juju-log database-peers:1: Uncaught exception while in charm code:
Traceback (most recent call last):
  File "/var/lib/juju/agents/unit-postgresql-1/charm/venv/lib/python3.10/site-packages/ops/model.py", line 3637, in _run
    result = subprocess.run(args, **kwargs)  # type: ignore
  File "/usr/lib/python3.10/subprocess.py", line 526, in run
    raise CalledProcessError(retcode, process.args,
subprocess.CalledProcessError: Command '('/var/lib/juju/tools/unit-postgresql-1/goal-state', '--format=json')' returned non-zero exit status 1.

The above exception was the direct cause of the following exception:

Traceback (most recent call last):
  File "/var/lib/juju/agents/unit-postgresql-1/charm/src/charm.py", line 2391, in <module>
    main(PostgresqlOperatorCharm)
  File "/var/lib/juju/agents/unit-postgresql-1/charm/venv/lib/python3.10/site-packages/ops/__init__.py", line 356, in __call__
    return _main.main(charm_class=charm_class, use_juju_for_storage=use_juju_for_storage)
  File "/var/lib/juju/agents/unit-postgresql-1/charm/venv/lib/python3.10/site-packages/ops/_main.py", line 502, in main
    manager.run()
  File "/var/lib/juju/agents/unit-postgresql-1/charm/venv/lib/python3.10/site-packages/ops/_main.py", line 486, in run
    self._emit()
  File "/var/lib/juju/agents/unit-postgresql-1/charm/venv/lib/python3.10/site-packages/ops/_main.py", line 421, in _emit
    self._emit_charm_event(self.dispatcher.event_name)
  File "/var/lib/juju/agents/unit-postgresql-1/charm/venv/lib/python3.10/site-packages/ops/_main.py", line 465, in _emit_charm_event
    event_to_emit.emit(*args, **kwargs)
  File "/var/lib/juju/agents/unit-postgresql-1/charm/venv/lib/python3.10/site-packages/ops/framework.py", line 351, in emit
    framework._emit(event)
  File "/var/lib/juju/agents/unit-postgresql-1/charm/venv/lib/python3.10/site-packages/ops/framework.py", line 924, in _emit
    self._reemit(event_path)
  File "/var/lib/juju/agents/unit-postgresql-1/charm/venv/lib/python3.10/site-packages/ops/framework.py", line 1030, in _reemit
    custom_handler(event)
  File "/var/lib/juju/agents/unit-postgresql-1/charm/lib/charms/tempo_coordinator_k8s/v0/charm_tracing.py", line 1116, in wrapped_function
    return callable(*args, **kwargs)  # type: ignore
  File "/var/lib/juju/agents/unit-postgresql-1/charm/src/charm.py", line 680, in _on_peer_relation_changed
    if not self._peer_relation_changed_checks(event):
  File "/var/lib/juju/agents/unit-postgresql-1/charm/lib/charms/tempo_coordinator_k8s/v0/charm_tracing.py", line 1116, in wrapped_function
    return callable(*args, **kwargs)  # type: ignore
  File "/var/lib/juju/agents/unit-postgresql-1/charm/src/charm.py", line 665, in _peer_relation_changed_checks
    if self.unit.is_leader() and not self._reconfigure_cluster(event):
  File "/var/lib/juju/agents/unit-postgresql-1/charm/lib/charms/tempo_coordinator_k8s/v0/charm_tracing.py", line 1116, in wrapped_function
    return callable(*args, **kwargs)  # type: ignore
  File "/var/lib/juju/agents/unit-postgresql-1/charm/src/charm.py", line 803, in _reconfigure_cluster
    self._add_members(event)
  File "/var/lib/juju/agents/unit-postgresql-1/charm/lib/charms/tempo_coordinator_k8s/v0/charm_tracing.py", line 1116, in wrapped_function
    return callable(*args, **kwargs)  # type: ignore
  File "/var/lib/juju/agents/unit-postgresql-1/charm/src/charm.py", line 845, in _add_members
    if self._patroni.cluster_members == self._hosts:
  File "/var/lib/juju/agents/unit-postgresql-1/charm/src/charm.py", line 921, in _patroni
    self.app.planned_units(),
  File "/var/lib/juju/agents/unit-postgresql-1/charm/venv/lib/python3.10/site-packages/ops/model.py", line 486, in planned_units
    return self._backend.planned_units()
  File "/var/lib/juju/agents/unit-postgresql-1/charm/venv/lib/python3.10/site-packages/ops/model.py", line 3986, in planned_units
    app_state = self._run('goal-state', return_output=True, use_json=True)
  File "/var/lib/juju/agents/unit-postgresql-1/charm/venv/lib/python3.10/site-packages/ops/model.py", line 3639, in _run
    raise ModelError(e.stderr) from e
ops.model.ModelError: ERROR getting relation status: cannot get status: relation not found

unit-postgresql-1: 02:14:15 ERROR juju.worker.uniter.operation hook "database-peers-relation-changed" (via hook dispatching script: dispatch) failed: exit status 1

[32mINFO    [0m pytest_operator.plugin:plugin.py:1039 Forgetting model main...